2019-03-05 12:02:58,419 - util.py[DEBUG]: Cloud-init v. 18.4-0ubuntu1~18.04.1 running 'init-local' at Tue, 05 Mar 2019 12:02:58 +0000. Up 13.44 seconds.
2019-03-05 12:02:58,419 - main.py[DEBUG]: No kernel command line url found.
2019-03-05 12:02:58,419 - main.py[DEBUG]: Closing stdin.
2019-03-05 12:02:58,424 - util.py[DEBUG]: Writing to /var/log/cloud-init.log - ab: [644] 0 bytes
2019-03-05 12:02:58,425 - util.py[DEBUG]: Changing the ownership of /var/log/cloud-init.log to 102:4
2019-03-05 12:02:58,425 - util.py[DEBUG]: Attempting to remove /var/lib/cloud/instance/boot-finished
2019-03-05 12:02:58,426 - util.py[DEBUG]: Attempting to remove /var/lib/cloud/data/no-net
2019-03-05 12:02:58,426 - handlers.py[DEBUG]: start: init-local/check-cache: attempting to read from cache [check]
2019-03-05 12:02:58,426 - util.py[DEBUG]: Reading from /var/lib/cloud/instance/obj.pkl (quiet=False)
2019-03-05 12:02:58,426 - stages.py[DEBUG]: no cache found
2019-03-05 12:02:58,426 - handlers.py[DEBUG]: finish: init-local/check-cache: SUCCESS: no cache found
2019-03-05 12:02:58,426 - util.py[DEBUG]: Attempting to remove /var/lib/cloud/instance
2019-03-05 12:02:58,431 - stages.py[DEBUG]: Using distro class <class 'cloudinit.distros.ubuntu.Distro'>
2019-03-05 12:02:58,431 - __init__.py[DEBUG]: Looking for data source in: ['IBMCloud', 'None'], via packages ['', 'cloudinit.sources'] that matches dependencies ['FILESYSTEM']
2019-03-05 12:02:58,441 - __init__.py[DEBUG]: Searching for local data source in: ['DataSourceIBMCloud']
2019-03-05 12:02:58,441 - handlers.py[DEBUG]: start: init-local/search-IBMCloud: searching for local data from DataSourceIBMCloud
2019-03-05 12:02:58,441 - __init__.py[DEBUG]: Seeing if we can get any data from <class 'cloudinit.sources.DataSourceIBMCloud.DataSourceIBMCloud'>
2019-03-05 12:02:58,441 - __init__.py[DEBUG]: Update datasource metadata and network config due to events: New instance first boot
2019-03-05 12:02:58,442 - util.py[DEBUG]: Running command ['blkid', '-o', 'full'] with allowed return codes [0] (shell=False, capture=True)
2019-03-05 12:02:58,462 - util.py[DEBUG]: Reading from /sys/hypervisor/uuid (quiet=False)
2019-03-05 12:02:58,463 - util.py[DEBUG]: Read 37 bytes from /sys/hypervisor/uuid
2019-03-05 12:02:58,463 - util.py[DEBUG]: Reading from /proc/mounts (quiet=False)
2019-03-05 12:02:58,463 - util.py[DEBUG]: Read 2258 bytes from /proc/mounts
2019-03-05 12:02:58,463 - util.py[DEBUG]: Fetched {'sysfs': {'fstype': 'sysfs', 'mountpoint': '/sys', 'opts': 'rw,nosuid,nodev,noexec,relatime'}, 'proc': {'fstype': 'proc', 'mountpoint': '/proc', 'opts': 'rw,nosuid,nodev,noexec,relatime'}, 'udev': {'fstype': 'devtmpfs', 'mountpoint': '/dev', 'opts': 'rw,nosuid,relatime,size=488848k,nr_inodes=122212,mode=755'}, 'devpts': {'fstype': 'devpts', 'mountpoint': '/dev/pts', 'opts': 'rw,nosuid,noexec,relatime,gid=5,mode=620,ptmxmode=000'}, 'tmpfs': {'fstype': 'tmpfs', 'mountpoint': '/sys/fs/cgroup', 'opts': 'ro,nosuid,nodev,noexec,mode=755'}, '/dev/xvda2': {'fstype': 'ext4', 'mountpoint': '/', 'opts': 'rw,relatime,data=ordered'}, 'securityfs': {'fstype': 'securityfs', 'mountpoint': '/sys/kernel/security', 'opts': 'rw,nosuid,nodev,noexec,relatime'}, 'cgroup': {'fstype': 'cgroup', 'mountpoint': '/sys/fs/cgroup/cpuset', 'opts': 'rw,nosuid,nodev,noexec,relatime,cpuset'}, 'pstore': {'fstype': 'pstore', 'mountpoint': '/sys/fs/pstore', 'opts': 'rw,nosuid,nodev,noexec,relatime'}, 'systemd-1': {'fstype': 'autofs', 'mountpoint': '/proc/sys/fs/binfmt_misc', 'opts': 'rw,relatime,fd=27,pgrp=1,timeout=0,minproto=5,maxproto=5,direct,pipe_ino=12693'}, 'mqueue': {'fstype': 'mqueue', 'mountpoint': '/dev/mqueue', 'opts': 'rw,relatime'}, 'debugfs': {'fstype': 'debugfs', 'mountpoint': '/sys/kernel/debug', 'opts': 'rw,relatime'}, 'hugetlbfs': {'fstype': 'hugetlbfs', 'mountpoint': '/dev/hugepages', 'opts': 'rw,relatime,pagesize=2M'}, 'none': {'fstype': 'xenfs', 'mountpoint': '/proc/xen', 'opts': 'rw,relatime'}, 'configfs': {'fstype': 'configfs', 'mountpoint': '/sys/kernel/config', 'opts': 'rw,relatime'}, 'fusectl': {'fstype': 'fusectl', 'mountpoint': '/sys/fs/fuse/connections', 'opts': 'rw,relatime'}, '/dev/xvda1': {'fstype': 'ext3', 'mountpoint': '/boot', 'opts': 'rw,relatime,data=ordered'}} mounts from proc
2019-03-05 12:02:58,464 - util.py[DEBUG]: Running command ['mount', '-o', 'ro,sync', '-t', 'auto', '/dev/xvdh', '/run/cloud-init/tmp/tmpmpljf_wy'] with allowed return codes [0] (shell=False, capture=True)
2019-03-05 12:02:58,498 - util.py[DEBUG]: Reading from /run/cloud-init/tmp/tmpmpljf_wy/openstack/latest/meta_data.json (quiet=False)
2019-03-05 12:02:58,500 - util.py[DEBUG]: Read 1897 bytes from /run/cloud-init/tmp/tmpmpljf_wy/openstack/latest/meta_data.json
2019-03-05 12:02:58,501 - util.py[DEBUG]: Reading from /run/cloud-init/tmp/tmpmpljf_wy/openstack/latest/user_data (quiet=False)
2019-03-05 12:02:58,501 - util.py[DEBUG]: Read 496 bytes from /run/cloud-init/tmp/tmpmpljf_wy/openstack/latest/user_data
2019-03-05 12:02:58,501 - util.py[DEBUG]: Reading from /run/cloud-init/tmp/tmpmpljf_wy/openstack/latest/vendor_data.json (quiet=False)
2019-03-05 12:02:58,502 - util.py[DEBUG]: Read 171 bytes from /run/cloud-init/tmp/tmpmpljf_wy/openstack/latest/vendor_data.json
2019-03-05 12:02:58,502 - util.py[DEBUG]: Reading from /run/cloud-init/tmp/tmpmpljf_wy/openstack/latest/network_data.json (quiet=False)
2019-03-05 12:02:58,502 - util.py[DEBUG]: Read 886 bytes from /run/cloud-init/tmp/tmpmpljf_wy/openstack/latest/network_data.json
2019-03-05 12:02:58,502 - util.py[DEBUG]: Running command ['umount', '/run/cloud-init/tmp/tmpmpljf_wy'] with allowed return codes [0] (shell=False, capture=True)
2019-03-05 12:02:58,533 - handlers.py[DEBUG]: finish: init-local/search-IBMCloud: SUCCESS: found local data from DataSourceIBMCloud
2019-03-05 12:02:58,533 - stages.py[INFO]: Loaded datasource DataSourceIBMCloud - DataSourceIBMCloud [OS-Code/Live /dev/xvdh]
2019-03-05 12:02:58,534 - util.py[DEBUG]: Reading from /etc/cloud/cloud.cfg (quiet=False)
2019-03-05 12:02:58,534 - util.py[DEBUG]: Read 3169 bytes from /etc/cloud/cloud.cfg
2019-03-05 12:02:58,534 - util.py[DEBUG]: Attempting to load yaml from string of length 3169 with allowed root types (<class 'dict'>,)
2019-03-05 12:02:58,548 - util.py[DEBUG]: Reading from /etc/cloud/cloud.cfg.d/99_networklayer_common.cfg (quiet=False)
2019-03-05 12:02:58,548 - util.py[DEBUG]: Read 989 bytes from /etc/cloud/cloud.cfg.d/99_networklayer_common.cfg
2019-03-05 12:02:58,548 - util.py[DEBUG]: Attempting to load yaml from string of length 989 with allowed root types (<class 'dict'>,)
2019-03-05 12:02:58,553 - util.py[DEBUG]: Reading from /etc/cloud/cloud.cfg.d/90_dpkg.cfg (quiet=False)
2019-03-05 12:02:58,554 - util.py[DEBUG]: Read 257 bytes from /etc/cloud/cloud.cfg.d/90_dpkg.cfg
2019-03-05 12:02:58,554 - util.py[DEBUG]: Attempting to load yaml from string of length 257 with allowed root types (<class 'dict'>,)
2019-03-05 12:02:58,556 - util.py[DEBUG]: Reading from /etc/cloud/cloud.cfg.d/05_logging.cfg (quiet=False)
2019-03-05 12:02:58,556 - util.py[DEBUG]: Read 2057 bytes from /etc/cloud/cloud.cfg.d/05_logging.cfg
2019-03-05 12:02:58,556 - util.py[DEBUG]: Attempting to load yaml from string of length 2057 with allowed root types (<class 'dict'>,)
2019-03-05 12:02:58,560 - util.py[DEBUG]: Reading from /run/cloud-init/cloud.cfg (quiet=False)
2019-03-05 12:02:58,561 - util.py[DEBUG]: Read 36 bytes from /run/cloud-init/cloud.cfg
2019-03-05 12:02:58,561 - util.py[DEBUG]: Attempting to load yaml from string of length 36 with allowed root types (<class 'dict'>,)
2019-03-05 12:02:58,561 - util.py[DEBUG]: Attempting to load yaml from string of length 0 with allowed root types (<class 'dict'>,)
2019-03-05 12:02:58,561 - util.py[DEBUG]: loaded blob returned None, returning default.
2019-03-05 12:02:58,562 - util.py[DEBUG]: Attempting to remove /var/lib/cloud/instance
2019-03-05 12:02:58,562 - util.py[DEBUG]: Creating symbolic link from '/var/lib/cloud/instance' => '/var/lib/cloud/instances/c24eca6d-063b-4de4-ab12-dcf37e5c0601'
2019-03-05 12:02:58,564 - util.py[DEBUG]: Reading from /var/lib/cloud/instances/c24eca6d-063b-4de4-ab12-dcf37e5c0601/datasource (quiet=False)
2019-03-05 12:02:58,564 - util.py[DEBUG]: Writing to /var/lib/cloud/instances/c24eca6d-063b-4de4-ab12-dcf37e5c0601/datasource - wb: [644] 64 bytes
2019-03-05 12:02:58,564 - util.py[DEBUG]: Writing to /var/lib/cloud/data/previous-datasource - wb: [644] 64 bytes
2019-03-05 12:02:58,565 - util.py[DEBUG]: Reading from /var/lib/cloud/data/instance-id (quiet=False)
2019-03-05 12:02:58,565 - stages.py[DEBUG]: previous iid found to be NO_PREVIOUS_INSTANCE_ID
2019-03-05 12:02:58,565 - util.py[DEBUG]: Writing to /var/lib/cloud/data/instance-id - wb: [644] 37 bytes
2019-03-05 12:02:58,565 - util.py[DEBUG]: Writing to /run/cloud-init/.instance-id - wb: [644] 37 bytes
2019-03-05 12:02:58,566 - util.py[DEBUG]: Writing to /var/lib/cloud/data/previous-instance-id - wb: [644] 24 bytes
2019-03-05 12:02:58,566 - util.py[DEBUG]: Writing to /var/lib/cloud/instance/obj.pkl - wb: [400] 8231 bytes
2019-03-05 12:02:58,567 - main.py[DEBUG]: [local] init will now be targeting instance id: c24eca6d-063b-4de4-ab12-dcf37e5c0601. new=True
2019-03-05 12:02:58,567 - util.py[DEBUG]: Reading from /etc/cloud/cloud.cfg (quiet=False)
2019-03-05 12:02:58,567 - util.py[DEBUG]: Read 3169 bytes from /etc/cloud/cloud.cfg
2019-03-05 12:02:58,567 - util.py[DEBUG]: Attempting to load yaml from string of length 3169 with allowed root types (<class 'dict'>,)
2019-03-05 12:02:58,582 - util.py[DEBUG]: Reading from /etc/cloud/cloud.cfg.d/99_networklayer_common.cfg (quiet=False)
2019-03-05 12:02:58,582 - util.py[DEBUG]: Read 989 bytes from /etc/cloud/cloud.cfg.d/99_networklayer_common.cfg
2019-03-05 12:02:58,582 - util.py[DEBUG]: Attempting to load yaml from string of length 989 with allowed root types (<class 'dict'>,)
2019-03-05 12:02:58,587 - util.py[DEBUG]: Reading from /etc/cloud/cloud.cfg.d/90_dpkg.cfg (quiet=False)
2019-03-05 12:02:58,587 - util.py[DEBUG]: Read 257 bytes from /etc/cloud/cloud.cfg.d/90_dpkg.cfg
2019-03-05 12:02:58,587 - util.py[DEBUG]: Attempting to load yaml from string of length 257 with allowed root types (<class 'dict'>,)
2019-03-05 12:02:58,589 - util.py[DEBUG]: Reading from /etc/cloud/cloud.cfg.d/05_logging.cfg (quiet=False)
2019-03-05 12:02:58,589 - util.py[DEBUG]: Read 2057 bytes from /etc/cloud/cloud.cfg.d/05_logging.cfg
2019-03-05 12:02:58,589 - util.py[DEBUG]: Attempting to load yaml from string of length 2057 with allowed root types (<class 'dict'>,)
2019-03-05 12:02:58,594 - util.py[DEBUG]: Reading from /run/cloud-init/cloud.cfg (quiet=False)
2019-03-05 12:02:58,594 - util.py[DEBUG]: Read 36 bytes from /run/cloud-init/cloud.cfg
2019-03-05 12:02:58,594 - util.py[DEBUG]: Attempting to load yaml from string of length 36 with allowed root types (<class 'dict'>,)
2019-03-05 12:02:58,594 - util.py[DEBUG]: Attempting to load yaml from string of length 0 with allowed root types (<class 'dict'>,)
2019-03-05 12:02:58,595 - util.py[DEBUG]: loaded blob returned None, returning default.
2019-03-05 12:02:58,596 - stages.py[DEBUG]: Using distro class <class 'cloudinit.distros.ubuntu.Distro'>
2019-03-05 12:02:58,597 - cc_set_hostname.py[DEBUG]: Setting the hostname to csc-vm-YOURINITIALS.ibm.cloud (csc-vm-YOURINITIALS)
2019-03-05 12:02:58,597 - util.py[DEBUG]: Reading from /etc/hostname (quiet=False)
2019-03-05 12:02:58,597 - util.py[DEBUG]: Read 7 bytes from /etc/hostname
2019-03-05 12:02:58,597 - util.py[DEBUG]: Writing to /etc/hostname - wb: [644] 20 bytes
2019-03-05 12:02:58,599 - __init__.py[DEBUG]: Non-persistently setting the system hostname to csc-vm-YOURINITIALS
2019-03-05 12:02:58,599 - util.py[DEBUG]: Running command ['hostname', 'csc-vm-YOURINITIALS'] with allowed return codes [0] (shell=False, capture=True)
2019-03-05 12:02:58,604 - DataSourceIBMCloud.py[DEBUG]: network config provided via network_json
2019-03-05 12:02:58,605 - util.py[DEBUG]: Reading from /sys/class/net/eth1/addr_assign_type (quiet=False)
2019-03-05 12:02:58,605 - util.py[DEBUG]: Read 2 bytes from /sys/class/net/eth1/addr_assign_type
2019-03-05 12:02:58,605 - util.py[DEBUG]: Reading from /sys/class/net/eth1/uevent (quiet=False)
2019-03-05 12:02:58,605 - util.py[DEBUG]: Read 25 bytes from /sys/class/net/eth1/uevent
2019-03-05 12:02:58,605 - util.py[DEBUG]: Reading from /sys/class/net/eth1/address (quiet=False)
2019-03-05 12:02:58,605 - util.py[DEBUG]: Read 18 bytes from /sys/class/net/eth1/address
2019-03-05 12:02:58,605 - util.py[DEBUG]: Reading from /sys/class/net/eth1/device/device (quiet=False)
2019-03-05 12:02:58,606 - util.py[DEBUG]: Reading from /sys/class/net/lo/addr_assign_type (quiet=False)
2019-03-05 12:02:58,606 - util.py[DEBUG]: Read 2 bytes from /sys/class/net/lo/addr_assign_type
2019-03-05 12:02:58,606 - util.py[DEBUG]: Reading from /sys/class/net/lo/uevent (quiet=False)
2019-03-05 12:02:58,606 - util.py[DEBUG]: Read 23 bytes from /sys/class/net/lo/uevent
2019-03-05 12:02:58,606 - util.py[DEBUG]: Reading from /sys/class/net/lo/address (quiet=False)
2019-03-05 12:02:58,606 - util.py[DEBUG]: Read 18 bytes from /sys/class/net/lo/address
2019-03-05 12:02:58,606 - util.py[DEBUG]: Reading from /sys/class/net/lo/device/device (quiet=False)
2019-03-05 12:02:58,606 - util.py[DEBUG]: Reading from /sys/class/net/eth0/addr_assign_type (quiet=False)
2019-03-05 12:02:58,606 - util.py[DEBUG]: Read 2 bytes from /sys/class/net/eth0/addr_assign_type
2019-03-05 12:02:58,606 - util.py[DEBUG]: Reading from /sys/class/net/eth0/uevent (quiet=False)
2019-03-05 12:02:58,607 - util.py[DEBUG]: Read 25 bytes from /sys/class/net/eth0/uevent
2019-03-05 12:02:58,607 - util.py[DEBUG]: Reading from /sys/class/net/eth0/address (quiet=False)
2019-03-05 12:02:58,607 - util.py[DEBUG]: Read 18 bytes from /sys/class/net/eth0/address
2019-03-05 12:02:58,607 - util.py[DEBUG]: Reading from /sys/class/net/eth0/device/device (quiet=False)
2019-03-05 12:02:58,607 - util.py[DEBUG]: Reading from /sys/class/net/eth1/type (quiet=False)
2019-03-05 12:02:58,607 - util.py[DEBUG]: Read 2 bytes from /sys/class/net/eth1/type
2019-03-05 12:02:58,607 - util.py[DEBUG]: Reading from /sys/class/net/lo/type (quiet=False)
2019-03-05 12:02:58,607 - util.py[DEBUG]: Read 4 bytes from /sys/class/net/lo/type
2019-03-05 12:02:58,607 - util.py[DEBUG]: Reading from /sys/class/net/eth0/type (quiet=False)
2019-03-05 12:02:58,607 - util.py[DEBUG]: Read 2 bytes from /sys/class/net/eth0/type
2019-03-05 12:02:58,608 - stages.py[DEBUG]: applying net config names for {'version': 1, 'config': [{'name': 'eth0', 'mtu': None, 'type': 'physical', 'subnets': [{'type': 'static', 'netmask': '255.255.255.192', 'routes': [{'network': '10.0.0.0', 'netmask': '255.0.0.0', 'gateway': '10.142.39.1'}, {'network': '161.26.0.0', 'netmask': '255.255.0.0', 'gateway': '10.142.39.1'}, {'network': '166.8.0.0', 'netmask': '255.252.0.0', 'gateway': '10.142.39.1'}], 'address': '10.142.39.35', 'ipv4': True}], 'mac_address': '06:fc:9a:55:bf:9e'}, {'name': 'eth1', 'mtu': None, 'type': 'physical', 'subnets': [{'type': 'static', 'netmask': '255.255.255.240', 'routes': [{'network': '0.0.0.0', 'netmask': '0.0.0.0', 'gateway': '169.55.47.145'}], 'address': '169.55.47.148', 'ipv4': True}], 'mac_address': '06:99:ac:66:4b:33'}, {'type': 'nameserver', 'address': '10.0.80.11'}, {'type': 'nameserver', 'address': '10.0.80.12'}]}
2019-03-05 12:02:58,608 - util.py[DEBUG]: Reading from /sys/class/net/eth0/device/device (quiet=False)
2019-03-05 12:02:58,608 - util.py[DEBUG]: Reading from /sys/class/net/eth1/device/device (quiet=False)
2019-03-05 12:02:58,608 - util.py[DEBUG]: Reading from /sys/class/net/eth1/addr_assign_type (quiet=False)
2019-03-05 12:02:58,608 - util.py[DEBUG]: Read 2 bytes from /sys/class/net/eth1/addr_assign_type
2019-03-05 12:02:58,608 - util.py[DEBUG]: Reading from /sys/class/net/eth1/uevent (quiet=False)
2019-03-05 12:02:58,608 - util.py[DEBUG]: Read 25 bytes from /sys/class/net/eth1/uevent
2019-03-05 12:02:58,609 - util.py[DEBUG]: Reading from /sys/class/net/eth1/address (quiet=False)
2019-03-05 12:02:58,609 - util.py[DEBUG]: Read 18 bytes from /sys/class/net/eth1/address
2019-03-05 12:02:58,609 - util.py[DEBUG]: Reading from /sys/class/net/eth1/device/device (quiet=False)
2019-03-05 12:02:58,609 - util.py[DEBUG]: Reading from /sys/class/net/lo/addr_assign_type (quiet=False)
2019-03-05 12:02:58,609 - util.py[DEBUG]: Read 2 bytes from /sys/class/net/lo/addr_assign_type
2019-03-05 12:02:58,609 - util.py[DEBUG]: Reading from /sys/class/net/lo/uevent (quiet=False)
2019-03-05 12:02:58,609 - util.py[DEBUG]: Read 23 bytes from /sys/class/net/lo/uevent
2019-03-05 12:02:58,609 - util.py[DEBUG]: Reading from /sys/class/net/lo/address (quiet=False)
2019-03-05 12:02:58,609 - util.py[DEBUG]: Read 18 bytes from /sys/class/net/lo/address
2019-03-05 12:02:58,609 - util.py[DEBUG]: Reading from /sys/class/net/lo/device/device (quiet=False)
2019-03-05 12:02:58,609 - util.py[DEBUG]: Reading from /sys/class/net/eth0/addr_assign_type (quiet=False)
2019-03-05 12:02:58,610 - util.py[DEBUG]: Read 2 bytes from /sys/class/net/eth0/addr_assign_type
2019-03-05 12:02:58,610 - util.py[DEBUG]: Reading from /sys/class/net/eth0/uevent (quiet=False)
2019-03-05 12:02:58,610 - util.py[DEBUG]: Read 25 bytes from /sys/class/net/eth0/uevent
2019-03-05 12:02:58,610 - util.py[DEBUG]: Reading from /sys/class/net/eth0/address (quiet=False)
2019-03-05 12:02:58,610 - util.py[DEBUG]: Read 18 bytes from /sys/class/net/eth0/address
2019-03-05 12:02:58,610 - util.py[DEBUG]: Reading from /sys/class/net/eth0/device/device (quiet=False)
2019-03-05 12:02:58,610 - util.py[DEBUG]: Reading from /sys/class/net/eth1/operstate (quiet=False)
2019-03-05 12:02:58,610 - util.py[DEBUG]: Read 5 bytes from /sys/class/net/eth1/operstate
2019-03-05 12:02:58,610 - util.py[DEBUG]: Reading from /sys/class/net/lo/operstate (quiet=False)
2019-03-05 12:02:58,610 - util.py[DEBUG]: Read 8 bytes from /sys/class/net/lo/operstate
2019-03-05 12:02:58,610 - util.py[DEBUG]: Reading from /sys/class/net/eth0/operstate (quiet=False)
2019-03-05 12:02:58,611 - util.py[DEBUG]: Read 5 bytes from /sys/class/net/eth0/operstate
2019-03-05 12:02:58,611 - util.py[DEBUG]: Running command ['ip', '-6', 'addr', 'show', 'permanent', 'scope', 'global'] with allowed return codes [0] (shell=False, capture=True)
2019-03-05 12:02:58,614 - util.py[DEBUG]: Running command ['ip', '-4', 'addr', 'show'] with allowed return codes [0] (shell=False, capture=True)
2019-03-05 12:02:58,617 - __init__.py[DEBUG]: no work necessary for renaming of [['06:fc:9a:55:bf:9e', 'eth0', 'vif', None], ['06:99:ac:66:4b:33', 'eth1', 'vif', None]]
2019-03-05 12:02:58,618 - stages.py[INFO]: Applying network configuration from ds bringup=False: {'version': 1, 'config': [{'name': 'eth0', 'mtu': None, 'type': 'physical', 'subnets': [{'type': 'static', 'netmask': '255.255.255.192', 'routes': [{'network': '10.0.0.0', 'netmask': '255.0.0.0', 'gateway': '10.142.39.1'}, {'network': '161.26.0.0', 'netmask': '255.255.0.0', 'gateway': '10.142.39.1'}, {'network': '166.8.0.0', 'netmask': '255.252.0.0', 'gateway': '10.142.39.1'}], 'address': '10.142.39.35', 'ipv4': True}], 'mac_address': '06:fc:9a:55:bf:9e'}, {'name': 'eth1', 'mtu': None, 'type': 'physical', 'subnets': [{'type': 'static', 'netmask': '255.255.255.240', 'routes': [{'network': '0.0.0.0', 'netmask': '0.0.0.0', 'gateway': '169.55.47.145'}], 'address': '169.55.47.148', 'ipv4': True}], 'mac_address': '06:99:ac:66:4b:33'}, {'type': 'nameserver', 'address': '10.0.80.11'}, {'type': 'nameserver', 'address': '10.0.80.12'}]}
2019-03-05 12:02:58,620 - __init__.py[DEBUG]: Selected renderer 'netplan' from priority list: None
2019-03-05 12:02:58,638 - util.py[DEBUG]: Writing to /etc/netplan/50-cloud-init.yaml - wb: [644] 1140 bytes
2019-03-05 12:02:58,638 - util.py[DEBUG]: Running command ['netplan', 'generate'] with allowed return codes [0] (shell=False, capture=True)
2019-03-05 12:02:58,804 - util.py[DEBUG]: Running command ['udevadm', 'test-builtin', 'net_setup_link', '/sys/class/net/eth1'] with allowed return codes [0] (shell=False, capture=True)
2019-03-05 12:02:58,809 - util.py[DEBUG]: Running command ['udevadm', 'test-builtin', 'net_setup_link', '/sys/class/net/lo'] with allowed return codes [0] (shell=False, capture=True)
2019-03-05 12:02:58,813 - util.py[DEBUG]: Running command ['udevadm', 'test-builtin', 'net_setup_link', '/sys/class/net/eth0'] with allowed return codes [0] (shell=False, capture=True)
2019-03-05 12:02:58,818 - main.py[DEBUG]: [local] Exiting. datasource DataSourceIBMCloud [OS-Code/Live /dev/xvdh] not in local mode.
2019-03-05 12:02:58,819 - util.py[DEBUG]: Reading from /proc/uptime (quiet=False)
2019-03-05 12:02:58,819 - util.py[DEBUG]: Read 11 bytes from /proc/uptime
2019-03-05 12:02:58,819 - util.py[DEBUG]: cloud-init mode 'init' took 0.459 seconds (0.46)
2019-03-05 12:02:58,820 - handlers.py[DEBUG]: finish: init-local: SUCCESS: searching for local datasources
2019-03-05 12:03:01,095 - util.py[DEBUG]: Cloud-init v. 18.4-0ubuntu1~18.04.1 running 'init' at Tue, 05 Mar 2019 12:03:01 +0000. Up 16.11 seconds.
2019-03-05 12:03:01,095 - main.py[DEBUG]: No kernel command line url found.
2019-03-05 12:03:01,095 - main.py[DEBUG]: Closing stdin.
2019-03-05 12:03:01,097 - util.py[DEBUG]: Writing to /var/log/cloud-init.log - ab: [644] 0 bytes
2019-03-05 12:03:01,099 - util.py[DEBUG]: Changing the ownership of /var/log/cloud-init.log to 102:4
2019-03-05 12:03:01,100 - util.py[DEBUG]: Running command ['ip', 'addr', 'show'] with allowed return codes [0] (shell=False, capture=True)
2019-03-05 12:03:01,104 - util.py[DEBUG]: Running command ['ip', '-o', 'route', 'list'] with allowed return codes [0] (shell=False, capture=True)
2019-03-05 12:03:01,107 - util.py[DEBUG]: Running command ['ip', '--oneline', '-6', 'route', 'list', 'table', 'all'] with allowed return codes [0, 1] (shell=False, capture=True)
2019-03-05 12:03:01,112 - main.py[DEBUG]: Checking to see if files that we need already exist from a previous run that would allow us to stop early.
2019-03-05 12:03:01,112 - main.py[DEBUG]: Execution continuing, no previous run detected that would allow us to stop early.
2019-03-05 12:03:01,113 - handlers.py[DEBUG]: start: init-network/check-cache: attempting to read from cache [trust]
2019-03-05 12:03:01,113 - util.py[DEBUG]: Reading from /var/lib/cloud/instance/obj.pkl (quiet=False)
2019-03-05 12:03:01,113 - util.py[DEBUG]: Read 8231 bytes from /var/lib/cloud/instance/obj.pkl
2019-03-05 12:03:01,118 - util.py[DEBUG]: Reading from /run/cloud-init/.instance-id (quiet=False)
2019-03-05 12:03:01,118 - util.py[DEBUG]: Read 37 bytes from /run/cloud-init/.instance-id
2019-03-05 12:03:01,118 - stages.py[DEBUG]: restored from cache with run check: DataSourceIBMCloud [OS-Code/Live /dev/xvdh]
2019-03-05 12:03:01,118 - handlers.py[DEBUG]: finish: init-network/check-cache: SUCCESS: restored from cache with run check: DataSourceIBMCloud [OS-Code/Live /dev/xvdh]
2019-03-05 12:03:01,118 - util.py[DEBUG]: Reading from /etc/cloud/cloud.cfg (quiet=False)
2019-03-05 12:03:01,119 - util.py[DEBUG]: Read 3169 bytes from /etc/cloud/cloud.cfg
2019-03-05 12:03:01,119 - util.py[DEBUG]: Attempting to load yaml from string of length 3169 with allowed root types (<class 'dict'>,)
2019-03-05 12:03:01,146 - util.py[DEBUG]: Reading from /etc/cloud/cloud.cfg.d/99_networklayer_common.cfg (quiet=False)
2019-03-05 12:03:01,147 - util.py[DEBUG]: Read 989 bytes from /etc/cloud/cloud.cfg.d/99_networklayer_common.cfg
2019-03-05 12:03:01,147 - util.py[DEBUG]: Attempting to load yaml from string of length 989 with allowed root types (<class 'dict'>,)
2019-03-05 12:03:01,152 - util.py[DEBUG]: Reading from /etc/cloud/cloud.cfg.d/90_dpkg.cfg (quiet=False)
2019-03-05 12:03:01,152 - util.py[DEBUG]: Read 257 bytes from /etc/cloud/cloud.cfg.d/90_dpkg.cfg
2019-03-05 12:03:01,152 - util.py[DEBUG]: Attempting to load yaml from string of length 257 with allowed root types (<class 'dict'>,)
2019-03-05 12:03:01,154 - util.py[DEBUG]: Reading from /etc/cloud/cloud.cfg.d/05_logging.cfg (quiet=False)
2019-03-05 12:03:01,154 - util.py[DEBUG]: Read 2057 bytes from /etc/cloud/cloud.cfg.d/05_logging.cfg
2019-03-05 12:03:01,154 - util.py[DEBUG]: Attempting to load yaml from string of length 2057 with allowed root types (<class 'dict'>,)
2019-03-05 12:03:01,159 - util.py[DEBUG]: Reading from /run/cloud-init/cloud.cfg (quiet=False)
2019-03-05 12:03:01,159 - util.py[DEBUG]: Read 36 bytes from /run/cloud-init/cloud.cfg
2019-03-05 12:03:01,159 - util.py[DEBUG]: Attempting to load yaml from string of length 36 with allowed root types (<class 'dict'>,)
2019-03-05 12:03:01,159 - util.py[DEBUG]: Attempting to load yaml from string of length 0 with allowed root types (<class 'dict'>,)
2019-03-05 12:03:01,160 - util.py[DEBUG]: loaded blob returned None, returning default.
2019-03-05 12:03:01,160 - util.py[DEBUG]: Attempting to remove /var/lib/cloud/instance
2019-03-05 12:03:01,160 - util.py[DEBUG]: Creating symbolic link from '/var/lib/cloud/instance' => '/var/lib/cloud/instances/c24eca6d-063b-4de4-ab12-dcf37e5c0601'
2019-03-05 12:03:01,161 - util.py[DEBUG]: Reading from /var/lib/cloud/instances/c24eca6d-063b-4de4-ab12-dcf37e5c0601/datasource (quiet=False)
2019-03-05 12:03:01,161 - util.py[DEBUG]: Read 64 bytes from /var/lib/cloud/instances/c24eca6d-063b-4de4-ab12-dcf37e5c0601/datasource
2019-03-05 12:03:01,161 - util.py[DEBUG]: Writing to /var/lib/cloud/instances/c24eca6d-063b-4de4-ab12-dcf37e5c0601/datasource - wb: [644] 64 bytes
2019-03-05 12:03:01,162 - util.py[DEBUG]: Writing to /var/lib/cloud/data/previous-datasource - wb: [644] 64 bytes
2019-03-05 12:03:01,162 - util.py[DEBUG]: Reading from /var/lib/cloud/data/instance-id (quiet=False)
2019-03-05 12:03:01,162 - util.py[DEBUG]: Read 37 bytes from /var/lib/cloud/data/instance-id
2019-03-05 12:03:01,163 - stages.py[DEBUG]: previous iid found to be c24eca6d-063b-4de4-ab12-dcf37e5c0601
2019-03-05 12:03:01,163 - util.py[DEBUG]: Writing to /var/lib/cloud/data/instance-id - wb: [644] 37 bytes
2019-03-05 12:03:01,163 - util.py[DEBUG]: Writing to /run/cloud-init/.instance-id - wb: [644] 37 bytes
2019-03-05 12:03:01,164 - util.py[DEBUG]: Writing to /var/lib/cloud/data/previous-instance-id - wb: [644] 37 bytes
2019-03-05 12:03:01,164 - util.py[DEBUG]: Writing to /var/lib/cloud/instance/obj.pkl - wb: [400] 8307 bytes
2019-03-05 12:03:01,167 - main.py[DEBUG]: [net] init will now be targeting instance id: c24eca6d-063b-4de4-ab12-dcf37e5c0601. new=False
2019-03-05 12:03:01,167 - util.py[DEBUG]: Reading from /etc/cloud/cloud.cfg (quiet=False)
2019-03-05 12:03:01,167 - util.py[DEBUG]: Read 3169 bytes from /etc/cloud/cloud.cfg
2019-03-05 12:03:01,167 - util.py[DEBUG]: Attempting to load yaml from string of length 3169 with allowed root types (<class 'dict'>,)
2019-03-05 12:03:01,181 - util.py[DEBUG]: Reading from /etc/cloud/cloud.cfg.d/99_networklayer_common.cfg (quiet=False)
2019-03-05 12:03:01,181 - util.py[DEBUG]: Read 989 bytes from /etc/cloud/cloud.cfg.d/99_networklayer_common.cfg
2019-03-05 12:03:01,181 - util.py[DEBUG]: Attempting to load yaml from string of length 989 with allowed root types (<class 'dict'>,)
2019-03-05 12:03:01,186 - util.py[DEBUG]: Reading from /etc/cloud/cloud.cfg.d/90_dpkg.cfg (quiet=False)
2019-03-05 12:03:01,187 - util.py[DEBUG]: Read 257 bytes from /etc/cloud/cloud.cfg.d/90_dpkg.cfg
2019-03-05 12:03:01,187 - util.py[DEBUG]: Attempting to load yaml from string of length 257 with allowed root types (<class 'dict'>,)
2019-03-05 12:03:01,189 - util.py[DEBUG]: Reading from /etc/cloud/cloud.cfg.d/05_logging.cfg (quiet=False)
2019-03-05 12:03:01,189 - util.py[DEBUG]: Read 2057 bytes from /etc/cloud/cloud.cfg.d/05_logging.cfg
2019-03-05 12:03:01,189 - util.py[DEBUG]: Attempting to load yaml from string of length 2057 with allowed root types (<class 'dict'>,)
2019-03-05 12:03:01,193 - util.py[DEBUG]: Reading from /run/cloud-init/cloud.cfg (quiet=False)
2019-03-05 12:03:01,193 - util.py[DEBUG]: Read 36 bytes from /run/cloud-init/cloud.cfg
2019-03-05 12:03:01,193 - util.py[DEBUG]: Attempting to load yaml from string of length 36 with allowed root types (<class 'dict'>,)
2019-03-05 12:03:01,194 - util.py[DEBUG]: Attempting to load yaml from string of length 0 with allowed root types (<class 'dict'>,)
2019-03-05 12:03:01,194 - util.py[DEBUG]: loaded blob returned None, returning default.
2019-03-05 12:03:01,195 - DataSourceIBMCloud.py[DEBUG]: network config provided via network_json
2019-03-05 12:03:01,196 - util.py[DEBUG]: Reading from /sys/class/net/eth1/addr_assign_type (quiet=False)
2019-03-05 12:03:01,196 - util.py[DEBUG]: Read 2 bytes from /sys/class/net/eth1/addr_assign_type
2019-03-05 12:03:01,196 - util.py[DEBUG]: Reading from /sys/class/net/eth1/uevent (quiet=False)
2019-03-05 12:03:01,196 - util.py[DEBUG]: Read 25 bytes from /sys/class/net/eth1/uevent
2019-03-05 12:03:01,196 - util.py[DEBUG]: Reading from /sys/class/net/eth1/address (quiet=False)
2019-03-05 12:03:01,196 - util.py[DEBUG]: Read 18 bytes from /sys/class/net/eth1/address
2019-03-05 12:03:01,196 - util.py[DEBUG]: Reading from /sys/class/net/eth1/device/device (quiet=False)
2019-03-05 12:03:01,196 - util.py[DEBUG]: Reading from /sys/class/net/lo/addr_assign_type (quiet=False)
2019-03-05 12:03:01,196 - util.py[DEBUG]: Read 2 bytes from /sys/class/net/lo/addr_assign_type
2019-03-05 12:03:01,197 - util.py[DEBUG]: Reading from /sys/class/net/lo/uevent (quiet=False)
2019-03-05 12:03:01,197 - util.py[DEBUG]: Read 23 bytes from /sys/class/net/lo/uevent
2019-03-05 12:03:01,197 - util.py[DEBUG]: Reading from /sys/class/net/lo/address (quiet=False)
2019-03-05 12:03:01,197 - util.py[DEBUG]: Read 18 bytes from /sys/class/net/lo/address
2019-03-05 12:03:01,197 - util.py[DEBUG]: Reading from /sys/class/net/lo/device/device (quiet=False)
2019-03-05 12:03:01,197 - util.py[DEBUG]: Reading from /sys/class/net/eth0/addr_assign_type (quiet=False)
2019-03-05 12:03:01,197 - util.py[DEBUG]: Read 2 bytes from /sys/class/net/eth0/addr_assign_type
2019-03-05 12:03:01,197 - util.py[DEBUG]: Reading from /sys/class/net/eth0/uevent (quiet=False)
2019-03-05 12:03:01,197 - util.py[DEBUG]: Read 25 bytes from /sys/class/net/eth0/uevent
2019-03-05 12:03:01,197 - util.py[DEBUG]: Reading from /sys/class/net/eth0/address (quiet=False)
2019-03-05 12:03:01,197 - util.py[DEBUG]: Read 18 bytes from /sys/class/net/eth0/address
2019-03-05 12:03:01,197 - util.py[DEBUG]: Reading from /sys/class/net/eth0/device/device (quiet=False)
2019-03-05 12:03:01,198 - util.py[DEBUG]: Reading from /sys/class/net/eth1/type (quiet=False)
2019-03-05 12:03:01,198 - util.py[DEBUG]: Read 2 bytes from /sys/class/net/eth1/type
2019-03-05 12:03:01,198 - util.py[DEBUG]: Reading from /sys/class/net/lo/type (quiet=False)
2019-03-05 12:03:01,198 - util.py[DEBUG]: Read 4 bytes from /sys/class/net/lo/type
2019-03-05 12:03:01,198 - util.py[DEBUG]: Reading from /sys/class/net/eth0/type (quiet=False)
2019-03-05 12:03:01,198 - util.py[DEBUG]: Read 2 bytes from /sys/class/net/eth0/type
2019-03-05 12:03:01,198 - stages.py[DEBUG]: applying net config names for {'version': 1, 'config': [{'name': 'eth0', 'mtu': None, 'type': 'physical', 'subnets': [{'type': 'static', 'netmask': '255.255.255.192', 'routes': [{'network': '10.0.0.0', 'netmask': '255.0.0.0', 'gateway': '10.142.39.1'}, {'network': '161.26.0.0', 'netmask': '255.255.0.0', 'gateway': '10.142.39.1'}, {'network': '166.8.0.0', 'netmask': '255.252.0.0', 'gateway': '10.142.39.1'}], 'address': '10.142.39.35', 'ipv4': True}], 'mac_address': '06:fc:9a:55:bf:9e'}, {'name': 'eth1', 'mtu': None, 'type': 'physical', 'subnets': [{'type': 'static', 'netmask': '255.255.255.240', 'routes': [{'network': '0.0.0.0', 'netmask': '0.0.0.0', 'gateway': '169.55.47.145'}], 'address': '169.55.47.148', 'ipv4': True}], 'mac_address': '06:99:ac:66:4b:33'}, {'type': 'nameserver', 'address': '10.0.80.11'}, {'type': 'nameserver', 'address': '10.0.80.12'}]}
2019-03-05 12:03:01,199 - stages.py[DEBUG]: Using distro class <class 'cloudinit.distros.ubuntu.Distro'>
2019-03-05 12:03:01,199 - util.py[DEBUG]: Reading from /sys/class/net/eth0/device/device (quiet=False)
2019-03-05 12:03:01,200 - util.py[DEBUG]: Reading from /sys/class/net/eth1/device/device (quiet=False)
2019-03-05 12:03:01,200 - util.py[DEBUG]: Reading from /sys/class/net/eth1/addr_assign_type (quiet=False)
2019-03-05 12:03:01,200 - util.py[DEBUG]: Read 2 bytes from /sys/class/net/eth1/addr_assign_type
2019-03-05 12:03:01,200 - util.py[DEBUG]: Reading from /sys/class/net/eth1/uevent (quiet=False)
2019-03-05 12:03:01,200 - util.py[DEBUG]: Read 25 bytes from /sys/class/net/eth1/uevent
2019-03-05 12:03:01,200 - util.py[DEBUG]: Reading from /sys/class/net/eth1/address (quiet=False)
2019-03-05 12:03:01,200 - util.py[DEBUG]: Read 18 bytes from /sys/class/net/eth1/address
2019-03-05 12:03:01,200 - util.py[DEBUG]: Reading from /sys/class/net/eth1/device/device (quiet=False)
2019-03-05 12:03:01,200 - util.py[DEBUG]: Reading from /sys/class/net/lo/addr_assign_type (quiet=False)
2019-03-05 12:03:01,200 - util.py[DEBUG]: Read 2 bytes from /sys/class/net/lo/addr_assign_type
2019-03-05 12:03:01,201 - util.py[DEBUG]: Reading from /sys/class/net/lo/uevent (quiet=False)
2019-03-05 12:03:01,201 - util.py[DEBUG]: Read 23 bytes from /sys/class/net/lo/uevent
2019-03-05 12:03:01,201 - util.py[DEBUG]: Reading from /sys/class/net/lo/address (quiet=False)
2019-03-05 12:03:01,201 - util.py[DEBUG]: Read 18 bytes from /sys/class/net/lo/address
2019-03-05 12:03:01,201 - util.py[DEBUG]: Reading from /sys/class/net/lo/device/device (quiet=False)
2019-03-05 12:03:01,201 - util.py[DEBUG]: Reading from /sys/class/net/eth0/addr_assign_type (quiet=False)
2019-03-05 12:03:01,201 - util.py[DEBUG]: Read 2 bytes from /sys/class/net/eth0/addr_assign_type
2019-03-05 12:03:01,201 - util.py[DEBUG]: Reading from /sys/class/net/eth0/uevent (quiet=False)
2019-03-05 12:03:01,201 - util.py[DEBUG]: Read 25 bytes from /sys/class/net/eth0/uevent
2019-03-05 12:03:01,201 - util.py[DEBUG]: Reading from /sys/class/net/eth0/address (quiet=False)
2019-03-05 12:03:01,201 - util.py[DEBUG]: Read 18 bytes from /sys/class/net/eth0/address
2019-03-05 12:03:01,202 - util.py[DEBUG]: Reading from /sys/class/net/eth0/device/device (quiet=False)
2019-03-05 12:03:01,202 - util.py[DEBUG]: Reading from /sys/class/net/eth1/operstate (quiet=False)
2019-03-05 12:03:01,202 - util.py[DEBUG]: Read 3 bytes from /sys/class/net/eth1/operstate
2019-03-05 12:03:01,202 - util.py[DEBUG]: Reading from /sys/class/net/lo/operstate (quiet=False)
2019-03-05 12:03:01,202 - util.py[DEBUG]: Read 8 bytes from /sys/class/net/lo/operstate
2019-03-05 12:03:01,202 - util.py[DEBUG]: Reading from /sys/class/net/eth0/operstate (quiet=False)
2019-03-05 12:03:01,202 - util.py[DEBUG]: Read 3 bytes from /sys/class/net/eth0/operstate
2019-03-05 12:03:01,202 - util.py[DEBUG]: Running command ['ip', '-6', 'addr', 'show', 'permanent', 'scope', 'global'] with allowed return codes [0] (shell=False, capture=True)
2019-03-05 12:03:01,205 - util.py[DEBUG]: Running command ['ip', '-4', 'addr', 'show'] with allowed return codes [0] (shell=False, capture=True)
2019-03-05 12:03:01,208 - __init__.py[DEBUG]: no work necessary for renaming of [['06:fc:9a:55:bf:9e', 'eth0', 'vif', None], ['06:99:ac:66:4b:33', 'eth1', 'vif', None]]
2019-03-05 12:03:01,209 - __init__.py[DEBUG]: Datasource DataSourceIBMCloud [OS-Code/Live /dev/xvdh] not updated for events: System boot
2019-03-05 12:03:01,209 - stages.py[DEBUG]: No network config applied. Neither a new instance nor datasource network update on 'System boot' event
2019-03-05 12:03:01,209 - handlers.py[DEBUG]: start: init-network/setup-datasource: setting up datasource
2019-03-05 12:03:01,209 - handlers.py[DEBUG]: finish: init-network/setup-datasource: SUCCESS: setting up datasource
2019-03-05 12:03:01,210 - util.py[DEBUG]: Writing to /var/lib/cloud/instances/c24eca6d-063b-4de4-ab12-dcf37e5c0601/user-data.txt - wb: [600] 496 bytes
2019-03-05 12:03:01,212 - util.py[DEBUG]: Attempting to load yaml from string of length 304 with allowed root types (<class 'dict'>,)
2019-03-05 12:03:01,217 - util.py[DEBUG]: Writing to /var/lib/cloud/instances/c24eca6d-063b-4de4-ab12-dcf37e5c0601/user-data.txt.i - wb: [600] 641 bytes
2019-03-05 12:03:01,218 - util.py[DEBUG]: Writing to /var/lib/cloud/instances/c24eca6d-063b-4de4-ab12-dcf37e5c0601/vendor-data.txt - wb: [600] 153 bytes
2019-03-05 12:03:01,220 - util.py[DEBUG]: Writing to /var/lib/cloud/instances/c24eca6d-063b-4de4-ab12-dcf37e5c0601/vendor-data.txt.i - wb: [600] 459 bytes
2019-03-05 12:03:01,221 - util.py[DEBUG]: Reading from /var/lib/cloud/data/set-hostname (quiet=False)
2019-03-05 12:03:01,221 - util.py[DEBUG]: Read 81 bytes from /var/lib/cloud/data/set-hostname
2019-03-05 12:03:01,221 - cc_set_hostname.py[DEBUG]: No hostname changes. Skipping set-hostname
2019-03-05 12:03:01,221 - util.py[DEBUG]: Writing to /var/lib/cloud/instances/c24eca6d-063b-4de4-ab12-dcf37e5c0601/sem/consume_data - wb: [644] 24 bytes
2019-03-05 12:03:01,222 - helpers.py[DEBUG]: Running consume_data using lock (<FileLock using file '/var/lib/cloud/instances/c24eca6d-063b-4de4-ab12-dcf37e5c0601/sem/consume_data'>)
2019-03-05 12:03:01,222 - handlers.py[DEBUG]: start: init-network/consume-user-data: reading and applying user-data
2019-03-05 12:03:01,223 - stages.py[DEBUG]: Added default handler for {'text/cloud-config-jsonp', 'text/cloud-config'} from CloudConfigPartHandler: [['text/cloud-config', 'text/cloud-config-jsonp']]
2019-03-05 12:03:01,223 - stages.py[DEBUG]: Added default handler for {'text/x-shellscript'} from ShellScriptPartHandler: [['text/x-shellscript']]
2019-03-05 12:03:01,223 - stages.py[DEBUG]: Added default handler for {'text/cloud-boothook'} from BootHookPartHandler: [['text/cloud-boothook']]
2019-03-05 12:03:01,223 - stages.py[DEBUG]: Added default handler for {'text/upstart-job'} from UpstartJobPartHandler: [['text/upstart-job']]
2019-03-05 12:03:01,223 - stages.py[DEBUG]: Added default handler for {'text/jinja2'} from JinjaTemplatePartHandler: [['text/jinja2']]
2019-03-05 12:03:01,223 - __init__.py[DEBUG]: Calling handler CloudConfigPartHandler: [['text/cloud-config', 'text/cloud-config-jsonp']] (__begin__, None, 3) with frequency once-per-instance
2019-03-05 12:03:01,223 - __init__.py[DEBUG]: Calling handler ShellScriptPartHandler: [['text/x-shellscript']] (__begin__, None, 2) with frequency once-per-instance
2019-03-05 12:03:01,223 - __init__.py[DEBUG]: Calling handler BootHookPartHandler: [['text/cloud-boothook']] (__begin__, None, 2) with frequency once-per-instance
2019-03-05 12:03:01,223 - __init__.py[DEBUG]: Calling handler UpstartJobPartHandler: [['text/upstart-job']] (__begin__, None, 2) with frequency once-per-instance
2019-03-05 12:03:01,223 - __init__.py[DEBUG]: Calling handler JinjaTemplatePartHandler: [['text/jinja2']] (__begin__, None, 3) with frequency once-per-instance
2019-03-05 12:03:01,224 - __init__.py[DEBUG]: {'Content-Transfer-Encoding': '7bit', 'Mime-Version': '1.0', 'Content-Type': 'text/cloud-config', 'Content-Disposition': 'attachment; filename="part-001"'}
2019-03-05 12:03:01,224 - __init__.py[DEBUG]: Calling handler CloudConfigPartHandler: [['text/cloud-config', 'text/cloud-config-jsonp']] (text/cloud-config, part-001, 3) with frequency once-per-instance
2019-03-05 12:03:01,224 - util.py[DEBUG]: Attempting to load yaml from string of length 304 with allowed root types (<class 'dict'>,)
2019-03-05 12:03:01,226 - cloud_config.py[DEBUG]: Merging by applying [('dict', ['replace']), ('list', []), ('str', [])]
2019-03-05 12:03:01,227 - __init__.py[DEBUG]: Calling handler CloudConfigPartHandler: [['text/cloud-config', 'text/cloud-config-jsonp']] (__end__, None, 3) with frequency once-per-instance
2019-03-05 12:03:01,228 - util.py[DEBUG]: Writing to /var/lib/cloud/instances/c24eca6d-063b-4de4-ab12-dcf37e5c0601/cloud-config.txt - wb: [600] 363 bytes
2019-03-05 12:03:01,229 - __init__.py[DEBUG]: Calling handler ShellScriptPartHandler: [['text/x-shellscript']] (__end__, None, 2) with frequency once-per-instance
2019-03-05 12:03:01,229 - __init__.py[DEBUG]: Calling handler BootHookPartHandler: [['text/cloud-boothook']] (__end__, None, 2) with frequency once-per-instance
2019-03-05 12:03:01,229 - __init__.py[DEBUG]: Calling handler UpstartJobPartHandler: [['text/upstart-job']] (__end__, None, 2) with frequency once-per-instance
2019-03-05 12:03:01,229 - __init__.py[DEBUG]: Calling handler JinjaTemplatePartHandler: [['text/jinja2']] (__end__, None, 3) with frequency once-per-instance
2019-03-05 12:03:01,229 - handlers.py[DEBUG]: finish: init-network/consume-user-data: SUCCESS: reading and applying user-data
2019-03-05 12:03:01,229 - handlers.py[DEBUG]: start: init-network/consume-vendor-data: reading and applying vendor-data
2019-03-05 12:03:01,230 - util.py[DEBUG]: Reading from /var/lib/cloud/instance/cloud-config.txt (quiet=False)
2019-03-05 12:03:01,230 - util.py[DEBUG]: Read 363 bytes from /var/lib/cloud/instance/cloud-config.txt
2019-03-05 12:03:01,230 - util.py[DEBUG]: Attempting to load yaml from string of length 363 with allowed root types (<class 'dict'>,)
2019-03-05 12:03:01,233 - stages.py[DEBUG]: vendor data will be consumed. disabled_handlers=None
2019-03-05 12:03:01,233 - stages.py[DEBUG]: Added default handler for {'text/cloud-config-jsonp', 'text/cloud-config'} from CloudConfigPartHandler: [['text/cloud-config', 'text/cloud-config-jsonp']]
2019-03-05 12:03:01,233 - stages.py[DEBUG]: Added default handler for {'text/x-shellscript'} from ShellScriptPartHandler: [['text/x-shellscript']]
2019-03-05 12:03:01,233 - stages.py[DEBUG]: Added default handler for {'text/cloud-boothook'} from BootHookPartHandler: [['text/cloud-boothook']]
2019-03-05 12:03:01,234 - stages.py[DEBUG]: Added default handler for {'text/upstart-job'} from UpstartJobPartHandler: [['text/upstart-job']]
2019-03-05 12:03:01,234 - stages.py[DEBUG]: Added default handler for {'text/jinja2'} from JinjaTemplatePartHandler: [['text/jinja2']]
2019-03-05 12:03:01,234 - __init__.py[DEBUG]: Calling handler CloudConfigPartHandler: [['text/cloud-config', 'text/cloud-config-jsonp']] (__begin__, None, 3) with frequency once-per-instance
2019-03-05 12:03:01,234 - __init__.py[DEBUG]: Calling handler ShellScriptPartHandler: [['text/x-shellscript']] (__begin__, None, 2) with frequency once-per-instance
2019-03-05 12:03:01,234 - __init__.py[DEBUG]: Calling handler BootHookPartHandler: [['text/cloud-boothook']] (__begin__, None, 2) with frequency once-per-instance
2019-03-05 12:03:01,234 - __init__.py[DEBUG]: Calling handler UpstartJobPartHandler: [['text/upstart-job']] (__begin__, None, 2) with frequency once-per-instance
2019-03-05 12:03:01,234 - __init__.py[DEBUG]: Calling handler JinjaTemplatePartHandler: [['text/jinja2']] (__begin__, None, 3) with frequency once-per-instance
2019-03-05 12:03:01,234 - __init__.py[DEBUG]: {'MIME-Version': '1.0', 'Content-Type': 'text/x-shellscript', 'Content-Disposition': 'attachment; filename="part-001"'}
2019-03-05 12:03:01,234 - __init__.py[DEBUG]: Calling handler ShellScriptPartHandler: [['text/x-shellscript']] (text/x-shellscript, part-001, 2) with frequency once-per-instance
2019-03-05 12:03:01,235 - util.py[DEBUG]: Writing to /var/lib/cloud/instance/scripts/vendor/part-001 - wb: [700] 153 bytes
2019-03-05 12:03:01,235 - __init__.py[DEBUG]: Calling handler CloudConfigPartHandler: [['text/cloud-config', 'text/cloud-config-jsonp']] (__end__, None, 3) with frequency once-per-instance
2019-03-05 12:03:01,235 - util.py[DEBUG]: Writing to /var/lib/cloud/instances/c24eca6d-063b-4de4-ab12-dcf37e5c0601/vendor-cloud-config.txt - wb: [600] 0 bytes
2019-03-05 12:03:01,236 - __init__.py[DEBUG]: Calling handler ShellScriptPartHandler: [['text/x-shellscript']] (__end__, None, 2) with frequency once-per-instance
2019-03-05 12:03:01,236 - __init__.py[DEBUG]: Calling handler BootHookPartHandler: [['text/cloud-boothook']] (__end__, None, 2) with frequency once-per-instance
2019-03-05 12:03:01,236 - __init__.py[DEBUG]: Calling handler UpstartJobPartHandler: [['text/upstart-job']] (__end__, None, 2) with frequency once-per-instance
2019-03-05 12:03:01,236 - __init__.py[DEBUG]: Calling handler JinjaTemplatePartHandler: [['text/jinja2']] (__end__, None, 3) with frequency once-per-instance
2019-03-05 12:03:01,236 - handlers.py[DEBUG]: finish: init-network/consume-vendor-data: SUCCESS: reading and applying vendor-data
2019-03-05 12:03:01,236 - util.py[DEBUG]: Reading from /etc/cloud/cloud.cfg (quiet=False)
2019-03-05 12:03:01,237 - util.py[DEBUG]: Read 3169 bytes from /etc/cloud/cloud.cfg
2019-03-05 12:03:01,237 - util.py[DEBUG]: Attempting to load yaml from string of length 3169 with allowed root types (<class 'dict'>,)
2019-03-05 12:03:01,251 - util.py[DEBUG]: Reading from /etc/cloud/cloud.cfg.d/99_networklayer_common.cfg (quiet=False)
2019-03-05 12:03:01,251 - util.py[DEBUG]: Read 989 bytes from /etc/cloud/cloud.cfg.d/99_networklayer_common.cfg
2019-03-05 12:03:01,251 - util.py[DEBUG]: Attempting to load yaml from string of length 989 with allowed root types (<class 'dict'>,)
2019-03-05 12:03:01,256 - util.py[DEBUG]: Reading from /etc/cloud/cloud.cfg.d/90_dpkg.cfg (quiet=False)
2019-03-05 12:03:01,256 - util.py[DEBUG]: Read 257 bytes from /etc/cloud/cloud.cfg.d/90_dpkg.cfg
2019-03-05 12:03:01,256 - util.py[DEBUG]: Attempting to load yaml from string of length 257 with allowed root types (<class 'dict'>,)
2019-03-05 12:03:01,258 - util.py[DEBUG]: Reading from /etc/cloud/cloud.cfg.d/05_logging.cfg (quiet=False)
2019-03-05 12:03:01,258 - util.py[DEBUG]: Read 2057 bytes from /etc/cloud/cloud.cfg.d/05_logging.cfg
2019-03-05 12:03:01,258 - util.py[DEBUG]: Attempting to load yaml from string of length 2057 with allowed root types (<class 'dict'>,)
2019-03-05 12:03:01,263 - util.py[DEBUG]: Reading from /run/cloud-init/cloud.cfg (quiet=False)
2019-03-05 12:03:01,263 - util.py[DEBUG]: Read 36 bytes from /run/cloud-init/cloud.cfg
2019-03-05 12:03:01,263 - util.py[DEBUG]: Attempting to load yaml from string of length 36 with allowed root types (<class 'dict'>,)
2019-03-05 12:03:01,264 - util.py[DEBUG]: Attempting to load yaml from string of length 0 with allowed root types (<class 'dict'>,)
2019-03-05 12:03:01,264 - util.py[DEBUG]: loaded blob returned None, returning default.
2019-03-05 12:03:01,264 - util.py[DEBUG]: Reading from /var/lib/cloud/instance/cloud-config.txt (quiet=False)
2019-03-05 12:03:01,264 - util.py[DEBUG]: Read 363 bytes from /var/lib/cloud/instance/cloud-config.txt
2019-03-05 12:03:01,264 - util.py[DEBUG]: Attempting to load yaml from string of length 363 with allowed root types (<class 'dict'>,)
2019-03-05 12:03:01,267 - util.py[DEBUG]: Reading from /var/lib/cloud/instance/vendor-cloud-config.txt (quiet=False)
2019-03-05 12:03:01,267 - util.py[DEBUG]: Read 0 bytes from /var/lib/cloud/instance/vendor-cloud-config.txt
2019-03-05 12:03:01,267 - util.py[DEBUG]: Attempting to load yaml from string of length 0 with allowed root types (<class 'dict'>,)
2019-03-05 12:03:01,267 - util.py[DEBUG]: loaded blob returned None, returning default.
2019-03-05 12:03:01,268 - util.py[DEBUG]: Reading from /var/lib/cloud/instance/cloud-config.txt (quiet=False)
2019-03-05 12:03:01,268 - util.py[DEBUG]: Read 363 bytes from /var/lib/cloud/instance/cloud-config.txt
2019-03-05 12:03:01,268 - util.py[DEBUG]: Attempting to load yaml from string of length 363 with allowed root types (<class 'dict'>,)
2019-03-05 12:03:01,271 - util.py[DEBUG]: Reading from /var/lib/cloud/instance/vendor-cloud-config.txt (quiet=False)
2019-03-05 12:03:01,271 - util.py[DEBUG]: Read 0 bytes from /var/lib/cloud/instance/vendor-cloud-config.txt
2019-03-05 12:03:01,271 - util.py[DEBUG]: Attempting to load yaml from string of length 0 with allowed root types (<class 'dict'>,)
2019-03-05 12:03:01,271 - util.py[DEBUG]: loaded blob returned None, returning default.
2019-03-05 12:03:01,281 - handlers.py[DEBUG]: start: init-network/activate-datasource: activating datasource
2019-03-05 12:03:01,281 - util.py[DEBUG]: Writing to /var/lib/cloud/instance/obj.pkl - wb: [400] 11360 bytes
2019-03-05 12:03:01,289 - handlers.py[DEBUG]: finish: init-network/activate-datasource: SUCCESS: activating datasource
2019-03-05 12:03:01,290 - main.py[DEBUG]: no di_report found in config.
2019-03-05 12:03:01,358 - stages.py[DEBUG]: Using distro class <class 'cloudinit.distros.ubuntu.Distro'>
2019-03-05 12:03:01,359 - stages.py[DEBUG]: Running module migrator (<module 'cloudinit.config.cc_migrator' from '/usr/lib/python3/dist-packages/cloudinit/config/cc_migrator.py'>) with frequency always
2019-03-05 12:03:01,359 - handlers.py[DEBUG]: start: init-network/config-migrator: running config-migrator with frequency always
2019-03-05 12:03:01,359 - helpers.py[DEBUG]: Running config-migrator using lock (<cloudinit.helpers.DummyLock object at 0x7f4ba463cfd0>)
2019-03-05 12:03:01,359 - cc_migrator.py[DEBUG]: Migrated 0 semaphore files to there canonicalized names
2019-03-05 12:03:01,360 - handlers.py[DEBUG]: finish: init-network/config-migrator: SUCCESS: config-migrator ran successfully
2019-03-05 12:03:01,360 - stages.py[DEBUG]: Running module seed_random (<module 'cloudinit.config.cc_seed_random' from '/usr/lib/python3/dist-packages/cloudinit/config/cc_seed_random.py'>) with frequency once-per-instance
2019-03-05 12:03:01,360 - handlers.py[DEBUG]: start: init-network/config-seed_random: running config-seed_random with frequency once-per-instance
2019-03-05 12:03:01,361 - util.py[DEBUG]: Writing to /var/lib/cloud/instances/c24eca6d-063b-4de4-ab12-dcf37e5c0601/sem/config_seed_random - wb: [644] 24 bytes
2019-03-05 12:03:01,361 - helpers.py[DEBUG]: Running config-seed_random using lock (<FileLock using file '/var/lib/cloud/instances/c24eca6d-063b-4de4-ab12-dcf37e5c0601/sem/config_seed_random'>)
2019-03-05 12:03:01,361 - cc_seed_random.py[DEBUG]: seed_random: adding 512 bytes of random seed entropy to /dev/urandom
2019-03-05 12:03:01,361 - util.py[DEBUG]: Writing to /dev/urandom - ab: [None] 512 bytes
2019-03-05 12:03:01,362 - cc_seed_random.py[DEBUG]: no command provided
2019-03-05 12:03:01,362 - handlers.py[DEBUG]: finish: init-network/config-seed_random: SUCCESS: config-seed_random ran successfully
2019-03-05 12:03:01,362 - stages.py[DEBUG]: Running module bootcmd (<module 'cloudinit.config.cc_bootcmd' from '/usr/lib/python3/dist-packages/cloudinit/config/cc_bootcmd.py'>) with frequency always
2019-03-05 12:03:01,370 - handlers.py[DEBUG]: start: init-network/config-bootcmd: running config-bootcmd with frequency always
2019-03-05 12:03:01,370 - helpers.py[DEBUG]: Running config-bootcmd using lock (<cloudinit.helpers.DummyLock object at 0x7f4ba463cfd0>)
2019-03-05 12:03:01,370 - cc_bootcmd.py[DEBUG]: Skipping module named bootcmd, no 'bootcmd' key in configuration
2019-03-05 12:03:01,370 - handlers.py[DEBUG]: finish: init-network/config-bootcmd: SUCCESS: config-bootcmd ran successfully
2019-03-05 12:03:01,370 - stages.py[DEBUG]: Running module write-files (<module 'cloudinit.config.cc_write_files' from '/usr/lib/python3/dist-packages/cloudinit/config/cc_write_files.py'>) with frequency once-per-instance
2019-03-05 12:03:01,370 - handlers.py[DEBUG]: start: init-network/config-write-files: running config-write-files with frequency once-per-instance
2019-03-05 12:03:01,371 - util.py[DEBUG]: Writing to /var/lib/cloud/instances/c24eca6d-063b-4de4-ab12-dcf37e5c0601/sem/config_write_files - wb: [644] 24 bytes
2019-03-05 12:03:01,371 - helpers.py[DEBUG]: Running config-write-files using lock (<FileLock using file '/var/lib/cloud/instances/c24eca6d-063b-4de4-ab12-dcf37e5c0601/sem/config_write_files'>)
2019-03-05 12:03:01,371 - cc_write_files.py[DEBUG]: Skipping module named write-files, no/empty 'write_files' key in configuration
2019-03-05 12:03:01,371 - handlers.py[DEBUG]: finish: init-network/config-write-files: SUCCESS: config-write-files ran successfully
2019-03-05 12:03:01,371 - stages.py[DEBUG]: Running module growpart (<module 'cloudinit.config.cc_growpart' from '/usr/lib/python3/dist-packages/cloudinit/config/cc_growpart.py'>) with frequency always
2019-03-05 12:03:01,372 - handlers.py[DEBUG]: start: init-network/config-growpart: running config-growpart with frequency always
2019-03-05 12:03:01,372 - helpers.py[DEBUG]: Running config-growpart using lock (<cloudinit.helpers.DummyLock object at 0x7f4ba46010f0>)
2019-03-05 12:03:01,372 - cc_growpart.py[DEBUG]: No 'growpart' entry in cfg.  Using default: {'mode': 'auto', 'devices': ['/'], 'ignore_growroot_disabled': False}
2019-03-05 12:03:01,372 - util.py[DEBUG]: Running command ['growpart', '--help'] with allowed return codes [0] (shell=False, capture=True)
2019-03-05 12:03:01,391 - util.py[DEBUG]: Reading from /proc/729/mountinfo (quiet=False)
2019-03-05 12:03:01,391 - util.py[DEBUG]: Read 3014 bytes from /proc/729/mountinfo
2019-03-05 12:03:01,392 - util.py[DEBUG]: Running command ['systemd-detect-virt', '--quiet', '--container'] with allowed return codes [0] (shell=False, capture=True)
2019-03-05 12:03:01,397 - util.py[DEBUG]: Running command ['running-in-container'] with allowed return codes [0] (shell=False, capture=True)
2019-03-05 12:03:01,400 - util.py[DEBUG]: Running command ['lxc-is-container'] with allowed return codes [0] (shell=False, capture=True)
2019-03-05 12:03:01,414 - util.py[DEBUG]: Reading from /proc/1/environ (quiet=False)
2019-03-05 12:03:01,414 - util.py[DEBUG]: Read 182 bytes from /proc/1/environ
2019-03-05 12:03:01,414 - util.py[DEBUG]: Reading from /proc/self/status (quiet=False)
2019-03-05 12:03:01,414 - util.py[DEBUG]: Read 1296 bytes from /proc/self/status
2019-03-05 12:03:01,415 - util.py[DEBUG]: Reading from /etc/os-release (quiet=False)
2019-03-05 12:03:01,416 - util.py[DEBUG]: Read 386 bytes from /etc/os-release
2019-03-05 12:03:01,416 - util.py[DEBUG]: Reading from /sys/class/block/xvda2/partition (quiet=False)
2019-03-05 12:03:01,416 - util.py[DEBUG]: Read 2 bytes from /sys/class/block/xvda2/partition
2019-03-05 12:03:01,417 - util.py[DEBUG]: Reading from /sys/devices/vbd-768/block/xvda/dev (quiet=False)
2019-03-05 12:03:01,417 - util.py[DEBUG]: Read 6 bytes from /sys/devices/vbd-768/block/xvda/dev
2019-03-05 12:03:01,417 - util.py[DEBUG]: Running command ['growpart', '--dry-run', '/dev/xvda', '2'] with allowed return codes [0] (shell=False, capture=True)
2019-03-05 12:03:01,500 - util.py[DEBUG]: resize_devices took 0.109 seconds
2019-03-05 12:03:01,500 - cc_growpart.py[DEBUG]: '/' NOCHANGE: no change necessary (/dev/xvda, 2)
2019-03-05 12:03:01,500 - handlers.py[DEBUG]: finish: init-network/config-growpart: SUCCESS: config-growpart ran successfully
2019-03-05 12:03:01,500 - stages.py[DEBUG]: Running module resizefs (<module 'cloudinit.config.cc_resizefs' from '/usr/lib/python3/dist-packages/cloudinit/config/cc_resizefs.py'>) with frequency always
2019-03-05 12:03:01,501 - handlers.py[DEBUG]: start: init-network/config-resizefs: running config-resizefs with frequency always
2019-03-05 12:03:01,501 - helpers.py[DEBUG]: Running config-resizefs using lock (<cloudinit.helpers.DummyLock object at 0x7f4ba4601278>)
2019-03-05 12:03:01,547 - util.py[DEBUG]: Reading from /proc/729/mountinfo (quiet=False)
2019-03-05 12:03:01,547 - util.py[DEBUG]: Read 3014 bytes from /proc/729/mountinfo
2019-03-05 12:03:01,547 - cc_resizefs.py[DEBUG]: resize_info: dev=/dev/xvda2 mnt_point=/ path=/
2019-03-05 12:03:01,547 - util.py[DEBUG]: Running command ['systemd-detect-virt', '--quiet', '--container'] with allowed return codes [0] (shell=False, capture=True)
2019-03-05 12:03:01,558 - util.py[DEBUG]: Running command ['running-in-container'] with allowed return codes [0] (shell=False, capture=True)
2019-03-05 12:03:01,560 - util.py[DEBUG]: Running command ['lxc-is-container'] with allowed return codes [0] (shell=False, capture=True)
2019-03-05 12:03:01,574 - util.py[DEBUG]: Reading from /proc/1/environ (quiet=False)
2019-03-05 12:03:01,575 - util.py[DEBUG]: Read 182 bytes from /proc/1/environ
2019-03-05 12:03:01,575 - util.py[DEBUG]: Reading from /proc/self/status (quiet=False)
2019-03-05 12:03:01,575 - util.py[DEBUG]: Read 1296 bytes from /proc/self/status
2019-03-05 12:03:01,575 - cc_resizefs.py[DEBUG]: Resizing / (ext4) using resize2fs /dev/xvda2
2019-03-05 12:03:01,575 - util.py[DEBUG]: Running command ('resize2fs', '/dev/xvda2') with allowed return codes [0] (shell=False, capture=True)
2019-03-05 12:03:01,621 - util.py[DEBUG]: Resizing took 0.045 seconds
2019-03-05 12:03:01,621 - cc_resizefs.py[DEBUG]: Resized root filesystem (type=ext4, val=True)
2019-03-05 12:03:01,622 - handlers.py[DEBUG]: finish: init-network/config-resizefs: SUCCESS: config-resizefs ran successfully
2019-03-05 12:03:01,622 - stages.py[DEBUG]: Running module disk_setup (<module 'cloudinit.config.cc_disk_setup' from '/usr/lib/python3/dist-packages/cloudinit/config/cc_disk_setup.py'>) with frequency once-per-instance
2019-03-05 12:03:01,626 - handlers.py[DEBUG]: start: init-network/config-disk_setup: running config-disk_setup with frequency once-per-instance
2019-03-05 12:03:01,627 - util.py[DEBUG]: Writing to /var/lib/cloud/instances/c24eca6d-063b-4de4-ab12-dcf37e5c0601/sem/config_disk_setup - wb: [644] 24 bytes
2019-03-05 12:03:01,627 - helpers.py[DEBUG]: Running config-disk_setup using lock (<FileLock using file '/var/lib/cloud/instances/c24eca6d-063b-4de4-ab12-dcf37e5c0601/sem/config_disk_setup'>)
2019-03-05 12:03:01,628 - handlers.py[DEBUG]: finish: init-network/config-disk_setup: SUCCESS: config-disk_setup ran successfully
2019-03-05 12:03:01,628 - stages.py[DEBUG]: Running module mounts (<module 'cloudinit.config.cc_mounts' from '/usr/lib/python3/dist-packages/cloudinit/config/cc_mounts.py'>) with frequency once-per-instance
2019-03-05 12:03:01,628 - handlers.py[DEBUG]: start: init-network/config-mounts: running config-mounts with frequency once-per-instance
2019-03-05 12:03:01,628 - util.py[DEBUG]: Writing to /var/lib/cloud/instances/c24eca6d-063b-4de4-ab12-dcf37e5c0601/sem/config_mounts - wb: [644] 24 bytes
2019-03-05 12:03:01,629 - helpers.py[DEBUG]: Running config-mounts using lock (<FileLock using file '/var/lib/cloud/instances/c24eca6d-063b-4de4-ab12-dcf37e5c0601/sem/config_mounts'>)
2019-03-05 12:03:01,629 - cc_mounts.py[DEBUG]: mounts configuration is [['/dev/xvdc', '/mnt/newvar', 'ext4', 'defaults,noexec,nofail', '0', '2']]
2019-03-05 12:03:01,629 - util.py[DEBUG]: Reading from /etc/fstab (quiet=False)
2019-03-05 12:03:01,629 - util.py[DEBUG]: Read 194 bytes from /etc/fstab
2019-03-05 12:03:01,629 - cc_mounts.py[DEBUG]: Attempting to determine the real name of /dev/xvdc
2019-03-05 12:03:01,629 - cc_mounts.py[DEBUG]: Attempting to determine the real name of ephemeral0
2019-03-05 12:03:01,629 - cc_mounts.py[DEBUG]: changed default device ephemeral0 => None
2019-03-05 12:03:01,630 - cc_mounts.py[DEBUG]: Ignoring nonexistent default named mount ephemeral0
2019-03-05 12:03:01,630 - cc_mounts.py[DEBUG]: Attempting to determine the real name of swap
2019-03-05 12:03:01,630 - cc_mounts.py[DEBUG]: changed default device swap => None
2019-03-05 12:03:01,630 - cc_mounts.py[DEBUG]: Ignoring nonexistent default named mount swap
2019-03-05 12:03:01,630 - cc_mounts.py[DEBUG]: no need to setup swap
2019-03-05 12:03:01,643 - util.py[DEBUG]: Writing to /etc/fstab - wb: [644] 268 bytes
2019-03-05 12:03:01,643 - cc_mounts.py[DEBUG]: Changes to fstab: ['+ /dev/xvdc /mnt/newvar ext4 defaults,noexec,nofail,comment=cloudconfig 0 2']
2019-03-05 12:03:01,643 - util.py[DEBUG]: Running command ['mount', '-a'] with allowed return codes [0] (shell=False, capture=True)
2019-03-05 12:03:01,671 - cc_mounts.py[WARNING]: Activate mounts: FAIL:mount -a
2019-03-05 12:03:01,671 - util.py[WARNING]: Activate mounts: FAIL:mount -a
2019-03-05 12:03:01,672 - util.py[DEBUG]: Activate mounts: FAIL:mount -a
Traceback (most recent call last):
  File "/usr/lib/python3/dist-packages/cloudinit/config/cc_mounts.py", line 484, in handle
    util.subp(cmd)
  File "/usr/lib/python3/dist-packages/cloudinit/util.py", line 2067, in subp
    cmd=args)
cloudinit.util.ProcessExecutionError: Unexpected error while running command.
Command: ['mount', '-a']
Exit code: 32
Reason: -
Stdout: 
Stderr: mount: /mnt/newvar: wrong fs type, bad option, bad superblock on /dev/xvdc, missing codepage or helper program, or other error.
2019-03-05 12:03:01,686 - util.py[DEBUG]: Running command ['systemctl', 'daemon-reload'] with allowed return codes [0] (shell=False, capture=True)
2019-03-05 12:03:01,946 - cc_mounts.py[DEBUG]: Activate mounts: PASS:systemctl daemon-reload
2019-03-05 12:03:01,947 - handlers.py[DEBUG]: finish: init-network/config-mounts: SUCCESS: config-mounts ran successfully
2019-03-05 12:03:01,947 - stages.py[DEBUG]: Running module set_hostname (<module 'cloudinit.config.cc_set_hostname' from '/usr/lib/python3/dist-packages/cloudinit/config/cc_set_hostname.py'>) with frequency once-per-instance
2019-03-05 12:03:01,947 - handlers.py[DEBUG]: start: init-network/config-set_hostname: running config-set_hostname with frequency once-per-instance
2019-03-05 12:03:01,947 - util.py[DEBUG]: Writing to /var/lib/cloud/instances/c24eca6d-063b-4de4-ab12-dcf37e5c0601/sem/config_set_hostname - wb: [644] 24 bytes
2019-03-05 12:03:01,948 - helpers.py[DEBUG]: Running config-set_hostname using lock (<FileLock using file '/var/lib/cloud/instances/c24eca6d-063b-4de4-ab12-dcf37e5c0601/sem/config_set_hostname'>)
2019-03-05 12:03:01,948 - util.py[DEBUG]: Reading from /var/lib/cloud/data/set-hostname (quiet=False)
2019-03-05 12:03:01,949 - util.py[DEBUG]: Read 81 bytes from /var/lib/cloud/data/set-hostname
2019-03-05 12:03:01,949 - cc_set_hostname.py[DEBUG]: No hostname changes. Skipping set-hostname
2019-03-05 12:03:01,949 - handlers.py[DEBUG]: finish: init-network/config-set_hostname: SUCCESS: config-set_hostname ran successfully
2019-03-05 12:03:01,949 - stages.py[DEBUG]: Running module update_hostname (<module 'cloudinit.config.cc_update_hostname' from '/usr/lib/python3/dist-packages/cloudinit/config/cc_update_hostname.py'>) with frequency always
2019-03-05 12:03:01,949 - handlers.py[DEBUG]: start: init-network/config-update_hostname: running config-update_hostname with frequency always
2019-03-05 12:03:01,949 - helpers.py[DEBUG]: Running config-update_hostname using lock (<cloudinit.helpers.DummyLock object at 0x7f4ba458cef0>)
2019-03-05 12:03:01,949 - cc_update_hostname.py[DEBUG]: Updating hostname to csc-vm-YOURINITIALS.ibm.cloud (csc-vm-YOURINITIALS)
2019-03-05 12:03:01,949 - util.py[DEBUG]: Reading from /etc/hostname (quiet=False)
2019-03-05 12:03:01,950 - util.py[DEBUG]: Read 20 bytes from /etc/hostname
2019-03-05 12:03:01,950 - __init__.py[DEBUG]: Attempting to update hostname to csc-vm-YOURINITIALS in 1 files
2019-03-05 12:03:01,950 - util.py[DEBUG]: Reading from /var/lib/cloud/data/previous-hostname (quiet=False)
2019-03-05 12:03:01,950 - util.py[DEBUG]: Writing to /var/lib/cloud/data/previous-hostname - wb: [644] 20 bytes
2019-03-05 12:03:01,952 - handlers.py[DEBUG]: finish: init-network/config-update_hostname: SUCCESS: config-update_hostname ran successfully
2019-03-05 12:03:01,952 - stages.py[DEBUG]: Running module update_etc_hosts (<module 'cloudinit.config.cc_update_etc_hosts' from '/usr/lib/python3/dist-packages/cloudinit/config/cc_update_etc_hosts.py'>) with frequency always
2019-03-05 12:03:01,952 - handlers.py[DEBUG]: start: init-network/config-update_etc_hosts: running config-update_etc_hosts with frequency always
2019-03-05 12:03:01,952 - helpers.py[DEBUG]: Running config-update_etc_hosts using lock (<cloudinit.helpers.DummyLock object at 0x7f4ba451b080>)
2019-03-05 12:03:01,952 - cc_update_etc_hosts.py[DEBUG]: Managing localhost in /etc/hosts
2019-03-05 12:03:01,952 - util.py[DEBUG]: Reading from /etc/hosts (quiet=False)
2019-03-05 12:03:01,952 - util.py[DEBUG]: Read 221 bytes from /etc/hosts
2019-03-05 12:03:01,953 - util.py[DEBUG]: Writing to /etc/hosts - wb: [644] 282 bytes
2019-03-05 12:03:01,953 - handlers.py[DEBUG]: finish: init-network/config-update_etc_hosts: SUCCESS: config-update_etc_hosts ran successfully
2019-03-05 12:03:01,953 - stages.py[DEBUG]: Running module ca-certs (<module 'cloudinit.config.cc_ca_certs' from '/usr/lib/python3/dist-packages/cloudinit/config/cc_ca_certs.py'>) with frequency once-per-instance
2019-03-05 12:03:01,954 - handlers.py[DEBUG]: start: init-network/config-ca-certs: running config-ca-certs with frequency once-per-instance
2019-03-05 12:03:01,954 - util.py[DEBUG]: Writing to /var/lib/cloud/instances/c24eca6d-063b-4de4-ab12-dcf37e5c0601/sem/config_ca_certs - wb: [644] 24 bytes
2019-03-05 12:03:01,954 - helpers.py[DEBUG]: Running config-ca-certs using lock (<FileLock using file '/var/lib/cloud/instances/c24eca6d-063b-4de4-ab12-dcf37e5c0601/sem/config_ca_certs'>)
2019-03-05 12:03:01,954 - cc_ca_certs.py[DEBUG]: Skipping module named ca-certs, no 'ca-certs' key in configuration
2019-03-05 12:03:01,954 - handlers.py[DEBUG]: finish: init-network/config-ca-certs: SUCCESS: config-ca-certs ran successfully
2019-03-05 12:03:01,955 - stages.py[DEBUG]: Running module rsyslog (<module 'cloudinit.config.cc_rsyslog' from '/usr/lib/python3/dist-packages/cloudinit/config/cc_rsyslog.py'>) with frequency once-per-instance
2019-03-05 12:03:01,955 - handlers.py[DEBUG]: start: init-network/config-rsyslog: running config-rsyslog with frequency once-per-instance
2019-03-05 12:03:01,955 - util.py[DEBUG]: Writing to /var/lib/cloud/instances/c24eca6d-063b-4de4-ab12-dcf37e5c0601/sem/config_rsyslog - wb: [644] 23 bytes
2019-03-05 12:03:01,956 - helpers.py[DEBUG]: Running config-rsyslog using lock (<FileLock using file '/var/lib/cloud/instances/c24eca6d-063b-4de4-ab12-dcf37e5c0601/sem/config_rsyslog'>)
2019-03-05 12:03:01,956 - cc_rsyslog.py[DEBUG]: Skipping module named rsyslog, no 'rsyslog' key in configuration
2019-03-05 12:03:01,956 - handlers.py[DEBUG]: finish: init-network/config-rsyslog: SUCCESS: config-rsyslog ran successfully
2019-03-05 12:03:01,956 - stages.py[DEBUG]: Running module users-groups (<module 'cloudinit.config.cc_users_groups' from '/usr/lib/python3/dist-packages/cloudinit/config/cc_users_groups.py'>) with frequency once-per-instance
2019-03-05 12:03:01,956 - handlers.py[DEBUG]: start: init-network/config-users-groups: running config-users-groups with frequency once-per-instance
2019-03-05 12:03:01,956 - util.py[DEBUG]: Writing to /var/lib/cloud/instances/c24eca6d-063b-4de4-ab12-dcf37e5c0601/sem/config_users_groups - wb: [644] 24 bytes
2019-03-05 12:03:01,957 - helpers.py[DEBUG]: Running config-users-groups using lock (<FileLock using file '/var/lib/cloud/instances/c24eca6d-063b-4de4-ab12-dcf37e5c0601/sem/config_users_groups'>)
2019-03-05 12:03:01,958 - util.py[DEBUG]: Reading from /etc/os-release (quiet=True)
2019-03-05 12:03:01,958 - util.py[DEBUG]: Read 386 bytes from /etc/os-release
2019-03-05 12:03:01,958 - util.py[DEBUG]: Reading from /etc/system-image/channel.ini (quiet=True)
2019-03-05 12:03:01,959 - util.py[DEBUG]: Read 0 bytes from /etc/system-image/channel.ini
2019-03-05 12:03:01,959 - __init__.py[DEBUG]: Adding user ubuntu
2019-03-05 12:03:01,959 - util.py[DEBUG]: Running hidden command to protect sensitive input/output logstring: ['useradd', 'ubuntu', '--comment', 'Ubuntu', '--groups', 'adm,audio,cdrom,dialout,dip,floppy,lxd,netdev,plugdev,sudo,video', '--shell', '/bin/bash', '-m']
2019-03-05 12:03:02,032 - util.py[DEBUG]: Running command ['passwd', '-l', 'ubuntu'] with allowed return codes [0] (shell=False, capture=True)
2019-03-05 12:03:02,045 - util.py[DEBUG]: Reading from /etc/sudoers (quiet=False)
2019-03-05 12:03:02,046 - util.py[DEBUG]: Read 755 bytes from /etc/sudoers
2019-03-05 12:03:02,048 - util.py[DEBUG]: Writing to /etc/sudoers.d/90-cloud-init-users - wb: [440] 139 bytes
2019-03-05 12:03:02,049 - handlers.py[DEBUG]: finish: init-network/config-users-groups: SUCCESS: config-users-groups ran successfully
2019-03-05 12:03:02,049 - stages.py[DEBUG]: Running module ssh (<module 'cloudinit.config.cc_ssh' from '/usr/lib/python3/dist-packages/cloudinit/config/cc_ssh.py'>) with frequency once-per-instance
2019-03-05 12:03:02,049 - handlers.py[DEBUG]: start: init-network/config-ssh: running config-ssh with frequency once-per-instance
2019-03-05 12:03:02,050 - util.py[DEBUG]: Writing to /var/lib/cloud/instances/c24eca6d-063b-4de4-ab12-dcf37e5c0601/sem/config_ssh - wb: [644] 24 bytes
2019-03-05 12:03:02,050 - helpers.py[DEBUG]: Running config-ssh using lock (<FileLock using file '/var/lib/cloud/instances/c24eca6d-063b-4de4-ab12-dcf37e5c0601/sem/config_ssh'>)
2019-03-05 12:03:02,051 - util.py[DEBUG]: Running command ['ssh-keygen', '-t', 'rsa', '-N', '', '-f', '/etc/ssh/ssh_host_rsa_key'] with allowed return codes [0] (shell=False, capture=True)
2019-03-05 12:03:02,197 - util.py[DEBUG]: Running command ['ssh-keygen', '-t', 'dsa', '-N', '', '-f', '/etc/ssh/ssh_host_dsa_key'] with allowed return codes [0] (shell=False, capture=True)
2019-03-05 12:03:02,656 - util.py[DEBUG]: Running command ['ssh-keygen', '-t', 'ecdsa', '-N', '', '-f', '/etc/ssh/ssh_host_ecdsa_key'] with allowed return codes [0] (shell=False, capture=True)
2019-03-05 12:03:02,665 - util.py[DEBUG]: Running command ['ssh-keygen', '-t', 'ed25519', '-N', '', '-f', '/etc/ssh/ssh_host_ed25519_key'] with allowed return codes [0] (shell=False, capture=True)
2019-03-05 12:03:02,673 - util.py[DEBUG]: Changing the ownership of /home/ubuntu/.ssh to 1000:1000
2019-03-05 12:03:02,673 - util.py[DEBUG]: Reading from /etc/ssh/sshd_config (quiet=False)
2019-03-05 12:03:02,676 - util.py[DEBUG]: Read 3248 bytes from /etc/ssh/sshd_config
2019-03-05 12:03:02,677 - util.py[DEBUG]: Writing to /home/ubuntu/.ssh/authorized_keys - wb: [600] 394 bytes
2019-03-05 12:03:02,678 - util.py[DEBUG]: Changing the ownership of /home/ubuntu/.ssh/authorized_keys to 1000:1000
2019-03-05 12:03:02,680 - util.py[DEBUG]: Changing the ownership of /root/.ssh to 0:0
2019-03-05 12:03:02,681 - util.py[DEBUG]: Reading from /etc/ssh/sshd_config (quiet=False)
2019-03-05 12:03:02,681 - util.py[DEBUG]: Read 3248 bytes from /etc/ssh/sshd_config
2019-03-05 12:03:02,681 - util.py[DEBUG]: Writing to /root/.ssh/authorized_keys - wb: [600] 394 bytes
2019-03-05 12:03:02,682 - util.py[DEBUG]: Changing the ownership of /root/.ssh/authorized_keys to 0:0
2019-03-05 12:03:02,682 - handlers.py[DEBUG]: finish: init-network/config-ssh: SUCCESS: config-ssh ran successfully
2019-03-05 12:03:02,682 - main.py[DEBUG]: Ran 15 modules with 0 failures
2019-03-05 12:03:02,683 - util.py[DEBUG]: Reading from /proc/uptime (quiet=False)
2019-03-05 12:03:02,683 - util.py[DEBUG]: Read 11 bytes from /proc/uptime
2019-03-05 12:03:02,683 - util.py[DEBUG]: cloud-init mode 'init' took 1.636 seconds (1.64)
2019-03-05 12:03:02,684 - handlers.py[DEBUG]: finish: init-network: SUCCESS: searching for network datasources
2019-03-05 12:03:09,371 - util.py[DEBUG]: Cloud-init v. 18.4-0ubuntu1~18.04.1 running 'modules:config' at Tue, 05 Mar 2019 12:03:09 +0000. Up 24.33 seconds.
2019-03-05 12:03:09,402 - stages.py[DEBUG]: Using distro class <class 'cloudinit.distros.ubuntu.Distro'>
2019-03-05 12:03:09,403 - stages.py[DEBUG]: Running module emit_upstart (<module 'cloudinit.config.cc_emit_upstart' from '/usr/lib/python3/dist-packages/cloudinit/config/cc_emit_upstart.py'>) with frequency always
2019-03-05 12:03:09,404 - handlers.py[DEBUG]: start: modules-config/config-emit_upstart: running config-emit_upstart with frequency always
2019-03-05 12:03:09,404 - helpers.py[DEBUG]: Running config-emit_upstart using lock (<cloudinit.helpers.DummyLock object at 0x7f1770e0a748>)
2019-03-05 12:03:09,404 - cc_emit_upstart.py[DEBUG]: no /sbin/initctl located
2019-03-05 12:03:09,404 - cc_emit_upstart.py[DEBUG]: not upstart system, 'emit_upstart' disabled
2019-03-05 12:03:09,404 - handlers.py[DEBUG]: finish: modules-config/config-emit_upstart: SUCCESS: config-emit_upstart ran successfully
2019-03-05 12:03:09,404 - stages.py[DEBUG]: Running module snap (<module 'cloudinit.config.cc_snap' from '/usr/lib/python3/dist-packages/cloudinit/config/cc_snap.py'>) with frequency once-per-instance
2019-03-05 12:03:09,404 - handlers.py[DEBUG]: start: modules-config/config-snap: running config-snap with frequency once-per-instance
2019-03-05 12:03:09,405 - util.py[DEBUG]: Writing to /var/lib/cloud/instances/c24eca6d-063b-4de4-ab12-dcf37e5c0601/sem/config_snap - wb: [644] 25 bytes
2019-03-05 12:03:09,405 - helpers.py[DEBUG]: Running config-snap using lock (<FileLock using file '/var/lib/cloud/instances/c24eca6d-063b-4de4-ab12-dcf37e5c0601/sem/config_snap'>)
2019-03-05 12:03:09,405 - cc_snap.py[DEBUG]: Skipping module named snap, no 'snap' key in configuration
2019-03-05 12:03:09,405 - handlers.py[DEBUG]: finish: modules-config/config-snap: SUCCESS: config-snap ran successfully
2019-03-05 12:03:09,405 - stages.py[DEBUG]: Running module snap_config (<module 'cloudinit.config.cc_snap_config' from '/usr/lib/python3/dist-packages/cloudinit/config/cc_snap_config.py'>) with frequency once-per-instance
2019-03-05 12:03:09,406 - handlers.py[DEBUG]: start: modules-config/config-snap_config: running config-snap_config with frequency once-per-instance
2019-03-05 12:03:09,406 - util.py[DEBUG]: Writing to /var/lib/cloud/instances/c24eca6d-063b-4de4-ab12-dcf37e5c0601/sem/config_snap_config - wb: [644] 24 bytes
2019-03-05 12:03:09,406 - helpers.py[DEBUG]: Running config-snap_config using lock (<FileLock using file '/var/lib/cloud/instances/c24eca6d-063b-4de4-ab12-dcf37e5c0601/sem/config_snap_config'>)
2019-03-05 12:03:09,406 - cc_snap_config.py[DEBUG]: No snappy config provided, skipping
2019-03-05 12:03:09,406 - handlers.py[DEBUG]: finish: modules-config/config-snap_config: SUCCESS: config-snap_config ran successfully
2019-03-05 12:03:09,406 - stages.py[DEBUG]: Running module ssh-import-id (<module 'cloudinit.config.cc_ssh_import_id' from '/usr/lib/python3/dist-packages/cloudinit/config/cc_ssh_import_id.py'>) with frequency once-per-instance
2019-03-05 12:03:09,407 - handlers.py[DEBUG]: start: modules-config/config-ssh-import-id: running config-ssh-import-id with frequency once-per-instance
2019-03-05 12:03:09,407 - util.py[DEBUG]: Writing to /var/lib/cloud/instances/c24eca6d-063b-4de4-ab12-dcf37e5c0601/sem/config_ssh_import_id - wb: [644] 25 bytes
2019-03-05 12:03:09,407 - helpers.py[DEBUG]: Running config-ssh-import-id using lock (<FileLock using file '/var/lib/cloud/instances/c24eca6d-063b-4de4-ab12-dcf37e5c0601/sem/config_ssh_import_id'>)
2019-03-05 12:03:09,408 - handlers.py[DEBUG]: finish: modules-config/config-ssh-import-id: SUCCESS: config-ssh-import-id ran successfully
2019-03-05 12:03:09,408 - stages.py[DEBUG]: Running module locale (<module 'cloudinit.config.cc_locale' from '/usr/lib/python3/dist-packages/cloudinit/config/cc_locale.py'>) with frequency once-per-instance
2019-03-05 12:03:09,408 - handlers.py[DEBUG]: start: modules-config/config-locale: running config-locale with frequency once-per-instance
2019-03-05 12:03:09,408 - util.py[DEBUG]: Writing to /var/lib/cloud/instances/c24eca6d-063b-4de4-ab12-dcf37e5c0601/sem/config_locale - wb: [644] 25 bytes
2019-03-05 12:03:09,409 - helpers.py[DEBUG]: Running config-locale using lock (<FileLock using file '/var/lib/cloud/instances/c24eca6d-063b-4de4-ab12-dcf37e5c0601/sem/config_locale'>)
2019-03-05 12:03:09,409 - util.py[DEBUG]: Reading from /etc/default/locale (quiet=False)
2019-03-05 12:03:09,409 - util.py[DEBUG]: Read 13 bytes from /etc/default/locale
2019-03-05 12:03:09,409 - cc_locale.py[DEBUG]: Setting locale to C.UTF-8
2019-03-05 12:03:09,409 - debian.py[DEBUG]: System has 'LANG=C.UTF-8' requested 'C.UTF-8', skipping regeneration.
2019-03-05 12:03:09,409 - handlers.py[DEBUG]: finish: modules-config/config-locale: SUCCESS: config-locale ran successfully
2019-03-05 12:03:09,409 - stages.py[DEBUG]: Running module set-passwords (<module 'cloudinit.config.cc_set_passwords' from '/usr/lib/python3/dist-packages/cloudinit/config/cc_set_passwords.py'>) with frequency once-per-instance
2019-03-05 12:03:09,410 - handlers.py[DEBUG]: start: modules-config/config-set-passwords: running config-set-passwords with frequency once-per-instance
2019-03-05 12:03:09,410 - util.py[DEBUG]: Writing to /var/lib/cloud/instances/c24eca6d-063b-4de4-ab12-dcf37e5c0601/sem/config_set_passwords - wb: [644] 25 bytes
2019-03-05 12:03:09,410 - helpers.py[DEBUG]: Running config-set-passwords using lock (<FileLock using file '/var/lib/cloud/instances/c24eca6d-063b-4de4-ab12-dcf37e5c0601/sem/config_set_passwords'>)
2019-03-05 12:03:09,410 - util.py[DEBUG]: Reading from /etc/ssh/sshd_config (quiet=False)
2019-03-05 12:03:09,410 - util.py[DEBUG]: Read 3248 bytes from /etc/ssh/sshd_config
2019-03-05 12:03:09,411 - ssh_util.py[DEBUG]: line 56: option PasswordAuthentication already set to yes
2019-03-05 12:03:09,411 - cc_set_passwords.py[DEBUG]: No need to restart ssh service, PasswordAuthentication not updated.
2019-03-05 12:03:09,411 - handlers.py[DEBUG]: finish: modules-config/config-set-passwords: SUCCESS: config-set-passwords ran successfully
2019-03-05 12:03:09,411 - stages.py[DEBUG]: Running module grub-dpkg (<module 'cloudinit.config.cc_grub_dpkg' from '/usr/lib/python3/dist-packages/cloudinit/config/cc_grub_dpkg.py'>) with frequency once-per-instance
2019-03-05 12:03:09,411 - handlers.py[DEBUG]: start: modules-config/config-grub-dpkg: running config-grub-dpkg with frequency once-per-instance
2019-03-05 12:03:09,412 - util.py[DEBUG]: Writing to /var/lib/cloud/instances/c24eca6d-063b-4de4-ab12-dcf37e5c0601/sem/config_grub_dpkg - wb: [644] 25 bytes
2019-03-05 12:03:09,412 - helpers.py[DEBUG]: Running config-grub-dpkg using lock (<FileLock using file '/var/lib/cloud/instances/c24eca6d-063b-4de4-ab12-dcf37e5c0601/sem/config_grub_dpkg'>)
2019-03-05 12:03:09,412 - cc_grub_dpkg.py[DEBUG]: Setting grub debconf-set-selections with '/dev/xvda','false'
2019-03-05 12:03:09,412 - util.py[DEBUG]: Running command ['debconf-set-selections'] with allowed return codes [0] (shell=False, capture=True)
2019-03-05 12:03:09,675 - handlers.py[DEBUG]: finish: modules-config/config-grub-dpkg: SUCCESS: config-grub-dpkg ran successfully
2019-03-05 12:03:09,675 - stages.py[DEBUG]: Running module apt-pipelining (<module 'cloudinit.config.cc_apt_pipelining' from '/usr/lib/python3/dist-packages/cloudinit/config/cc_apt_pipelining.py'>) with frequency once-per-instance
2019-03-05 12:03:09,676 - handlers.py[DEBUG]: start: modules-config/config-apt-pipelining: running config-apt-pipelining with frequency once-per-instance
2019-03-05 12:03:09,676 - util.py[DEBUG]: Writing to /var/lib/cloud/instances/c24eca6d-063b-4de4-ab12-dcf37e5c0601/sem/config_apt_pipelining - wb: [644] 25 bytes
2019-03-05 12:03:09,677 - helpers.py[DEBUG]: Running config-apt-pipelining using lock (<FileLock using file '/var/lib/cloud/instances/c24eca6d-063b-4de4-ab12-dcf37e5c0601/sem/config_apt_pipelining'>)
2019-03-05 12:03:09,677 - util.py[DEBUG]: Writing to /etc/apt/apt.conf.d/90cloud-init-pipelining - wb: [644] 80 bytes
2019-03-05 12:03:09,677 - cc_apt_pipelining.py[DEBUG]: Wrote /etc/apt/apt.conf.d/90cloud-init-pipelining with apt pipeline depth setting 0
2019-03-05 12:03:09,678 - handlers.py[DEBUG]: finish: modules-config/config-apt-pipelining: SUCCESS: config-apt-pipelining ran successfully
2019-03-05 12:03:09,678 - stages.py[DEBUG]: Running module apt-configure (<module 'cloudinit.config.cc_apt_configure' from '/usr/lib/python3/dist-packages/cloudinit/config/cc_apt_configure.py'>) with frequency once-per-instance
2019-03-05 12:03:09,678 - handlers.py[DEBUG]: start: modules-config/config-apt-configure: running config-apt-configure with frequency once-per-instance
2019-03-05 12:03:09,678 - util.py[DEBUG]: Writing to /var/lib/cloud/instances/c24eca6d-063b-4de4-ab12-dcf37e5c0601/sem/config_apt_configure - wb: [644] 25 bytes
2019-03-05 12:03:09,679 - helpers.py[DEBUG]: Running config-apt-configure using lock (<FileLock using file '/var/lib/cloud/instances/c24eca6d-063b-4de4-ab12-dcf37e5c0601/sem/config_apt_configure'>)
2019-03-05 12:03:09,679 - cc_apt_configure.py[DEBUG]: debconf_selections was not set in config
2019-03-05 12:03:09,679 - util.py[DEBUG]: Reading from /etc/os-release (quiet=True)
2019-03-05 12:03:09,679 - util.py[DEBUG]: Read 386 bytes from /etc/os-release
2019-03-05 12:03:09,679 - util.py[DEBUG]: Reading from /etc/system-image/channel.ini (quiet=True)
2019-03-05 12:03:09,680 - util.py[DEBUG]: Read 0 bytes from /etc/system-image/channel.ini
2019-03-05 12:03:09,680 - cc_apt_configure.py[DEBUG]: handling apt config: {}
2019-03-05 12:03:09,680 - util.py[DEBUG]: Running command ['lsb_release', '--all'] with allowed return codes [0] (shell=False, capture=True)
2019-03-05 12:03:09,769 - util.py[DEBUG]: Running command ['dpkg', '--print-architecture'] with allowed return codes [0] (shell=False, capture=True)
2019-03-05 12:03:09,777 - cc_apt_configure.py[DEBUG]: got primary mirror: None
2019-03-05 12:03:09,778 - cc_apt_configure.py[DEBUG]: got security mirror: None
2019-03-05 12:03:09,778 - util.py[DEBUG]: Running command ['dpkg', '--print-architecture'] with allowed return codes [0] (shell=False, capture=True)
2019-03-05 12:03:09,858 - util.py[DEBUG]: Resolving URL: http://mirrors.service.networklayer.com/ubuntu took 0.076 seconds
2019-03-05 12:03:09,859 - util.py[DEBUG]: Resolving URL: http://mirrors.service.networklayer.com/ubuntu took 0.001 seconds
2019-03-05 12:03:09,859 - __init__.py[DEBUG]: filtered distro mirror info: {'primary': 'http://mirrors.service.networklayer.com/ubuntu', 'security': 'http://mirrors.service.networklayer.com/ubuntu'}
2019-03-05 12:03:09,859 - cc_apt_configure.py[DEBUG]: Apt Mirror info: {'primary': 'http://mirrors.service.networklayer.com/ubuntu', 'security': 'http://mirrors.service.networklayer.com/ubuntu', 'PRIMARY': 'http://mirrors.service.networklayer.com/ubuntu', 'SECURITY': 'http://mirrors.service.networklayer.com/ubuntu', 'MIRROR': 'http://mirrors.service.networklayer.com/ubuntu'}
2019-03-05 12:03:09,860 - cc_apt_configure.py[INFO]: No custom template provided, fall back to builtin
2019-03-05 12:03:09,861 - util.py[DEBUG]: Reading from /etc/cloud/templates/sources.list.ubuntu.tmpl (quiet=False)
2019-03-05 12:03:09,862 - util.py[DEBUG]: Read 2841 bytes from /etc/cloud/templates/sources.list.ubuntu.tmpl
2019-03-05 12:03:09,873 - util.py[DEBUG]: Writing to /etc/apt/sources.list - wb: [644] 3399 bytes
2019-03-05 12:03:09,874 - util.py[DEBUG]: Running command ['dpkg', '--print-architecture'] with allowed return codes [0] (shell=False, capture=True)
2019-03-05 12:03:09,880 - handlers.py[DEBUG]: finish: modules-config/config-apt-configure: SUCCESS: config-apt-configure ran successfully
2019-03-05 12:03:09,880 - stages.py[DEBUG]: Running module ubuntu-advantage (<module 'cloudinit.config.cc_ubuntu_advantage' from '/usr/lib/python3/dist-packages/cloudinit/config/cc_ubuntu_advantage.py'>) with frequency once-per-instance
2019-03-05 12:03:09,881 - handlers.py[DEBUG]: start: modules-config/config-ubuntu-advantage: running config-ubuntu-advantage with frequency once-per-instance
2019-03-05 12:03:09,881 - util.py[DEBUG]: Writing to /var/lib/cloud/instances/c24eca6d-063b-4de4-ab12-dcf37e5c0601/sem/config_ubuntu_advantage - wb: [644] 25 bytes
2019-03-05 12:03:09,881 - helpers.py[DEBUG]: Running config-ubuntu-advantage using lock (<FileLock using file '/var/lib/cloud/instances/c24eca6d-063b-4de4-ab12-dcf37e5c0601/sem/config_ubuntu_advantage'>)
2019-03-05 12:03:09,882 - cc_ubuntu_advantage.py[DEBUG]: Skipping module named ubuntu-advantage, no 'ubuntu-advantage' key in configuration
2019-03-05 12:03:09,882 - handlers.py[DEBUG]: finish: modules-config/config-ubuntu-advantage: SUCCESS: config-ubuntu-advantage ran successfully
2019-03-05 12:03:09,882 - stages.py[DEBUG]: Running module ntp (<module 'cloudinit.config.cc_ntp' from '/usr/lib/python3/dist-packages/cloudinit/config/cc_ntp.py'>) with frequency once-per-instance
2019-03-05 12:03:09,882 - handlers.py[DEBUG]: start: modules-config/config-ntp: running config-ntp with frequency once-per-instance
2019-03-05 12:03:09,882 - util.py[DEBUG]: Writing to /var/lib/cloud/instances/c24eca6d-063b-4de4-ab12-dcf37e5c0601/sem/config_ntp - wb: [644] 25 bytes
2019-03-05 12:03:09,883 - helpers.py[DEBUG]: Running config-ntp using lock (<FileLock using file '/var/lib/cloud/instances/c24eca6d-063b-4de4-ab12-dcf37e5c0601/sem/config_ntp'>)
2019-03-05 12:03:09,883 - cc_ntp.py[DEBUG]: Skipping module named ntp, not present or disabled by cfg
2019-03-05 12:03:09,883 - handlers.py[DEBUG]: finish: modules-config/config-ntp: SUCCESS: config-ntp ran successfully
2019-03-05 12:03:09,883 - stages.py[DEBUG]: Running module timezone (<module 'cloudinit.config.cc_timezone' from '/usr/lib/python3/dist-packages/cloudinit/config/cc_timezone.py'>) with frequency once-per-instance
2019-03-05 12:03:09,883 - handlers.py[DEBUG]: start: modules-config/config-timezone: running config-timezone with frequency once-per-instance
2019-03-05 12:03:09,884 - util.py[DEBUG]: Writing to /var/lib/cloud/instances/c24eca6d-063b-4de4-ab12-dcf37e5c0601/sem/config_timezone - wb: [644] 25 bytes
2019-03-05 12:03:09,884 - helpers.py[DEBUG]: Running config-timezone using lock (<FileLock using file '/var/lib/cloud/instances/c24eca6d-063b-4de4-ab12-dcf37e5c0601/sem/config_timezone'>)
2019-03-05 12:03:09,884 - cc_timezone.py[DEBUG]: Skipping module named timezone, no 'timezone' specified
2019-03-05 12:03:09,884 - handlers.py[DEBUG]: finish: modules-config/config-timezone: SUCCESS: config-timezone ran successfully
2019-03-05 12:03:09,884 - stages.py[DEBUG]: Running module disable-ec2-metadata (<module 'cloudinit.config.cc_disable_ec2_metadata' from '/usr/lib/python3/dist-packages/cloudinit/config/cc_disable_ec2_metadata.py'>) with frequency always
2019-03-05 12:03:09,885 - handlers.py[DEBUG]: start: modules-config/config-disable-ec2-metadata: running config-disable-ec2-metadata with frequency always
2019-03-05 12:03:09,885 - helpers.py[DEBUG]: Running config-disable-ec2-metadata using lock (<cloudinit.helpers.DummyLock object at 0x7f1770dda208>)
2019-03-05 12:03:09,885 - cc_disable_ec2_metadata.py[DEBUG]: Skipping module named disable-ec2-metadata, disabling the ec2 route not enabled
2019-03-05 12:03:09,885 - handlers.py[DEBUG]: finish: modules-config/config-disable-ec2-metadata: SUCCESS: config-disable-ec2-metadata ran successfully
2019-03-05 12:03:09,885 - stages.py[DEBUG]: Running module runcmd (<module 'cloudinit.config.cc_runcmd' from '/usr/lib/python3/dist-packages/cloudinit/config/cc_runcmd.py'>) with frequency once-per-instance
2019-03-05 12:03:09,885 - handlers.py[DEBUG]: start: modules-config/config-runcmd: running config-runcmd with frequency once-per-instance
2019-03-05 12:03:09,885 - util.py[DEBUG]: Writing to /var/lib/cloud/instances/c24eca6d-063b-4de4-ab12-dcf37e5c0601/sem/config_runcmd - wb: [644] 25 bytes
2019-03-05 12:03:09,886 - helpers.py[DEBUG]: Running config-runcmd using lock (<FileLock using file '/var/lib/cloud/instances/c24eca6d-063b-4de4-ab12-dcf37e5c0601/sem/config_runcmd'>)
2019-03-05 12:03:09,892 - util.py[DEBUG]: Shellified 2 commands.
2019-03-05 12:03:09,892 - util.py[DEBUG]: Writing to /var/lib/cloud/instances/c24eca6d-063b-4de4-ab12-dcf37e5c0601/scripts/runcmd - wb: [700] 48 bytes
2019-03-05 12:03:09,893 - handlers.py[DEBUG]: finish: modules-config/config-runcmd: SUCCESS: config-runcmd ran successfully
2019-03-05 12:03:09,893 - stages.py[DEBUG]: Running module byobu (<module 'cloudinit.config.cc_byobu' from '/usr/lib/python3/dist-packages/cloudinit/config/cc_byobu.py'>) with frequency once-per-instance
2019-03-05 12:03:09,893 - handlers.py[DEBUG]: start: modules-config/config-byobu: running config-byobu with frequency once-per-instance
2019-03-05 12:03:09,893 - util.py[DEBUG]: Writing to /var/lib/cloud/instances/c24eca6d-063b-4de4-ab12-dcf37e5c0601/sem/config_byobu - wb: [644] 25 bytes
2019-03-05 12:03:09,894 - helpers.py[DEBUG]: Running config-byobu using lock (<FileLock using file '/var/lib/cloud/instances/c24eca6d-063b-4de4-ab12-dcf37e5c0601/sem/config_byobu'>)
2019-03-05 12:03:09,894 - cc_byobu.py[DEBUG]: Skipping module named byobu, no 'byobu' values found
2019-03-05 12:03:09,894 - handlers.py[DEBUG]: finish: modules-config/config-byobu: SUCCESS: config-byobu ran successfully
2019-03-05 12:03:09,894 - main.py[DEBUG]: Ran 15 modules with 0 failures
2019-03-05 12:03:09,895 - util.py[DEBUG]: Reading from /proc/uptime (quiet=False)
2019-03-05 12:03:09,895 - util.py[DEBUG]: Read 11 bytes from /proc/uptime
2019-03-05 12:03:09,895 - util.py[DEBUG]: cloud-init mode 'modules' took 0.625 seconds (0.63)
2019-03-05 12:03:09,895 - handlers.py[DEBUG]: finish: modules-config: SUCCESS: running modules for config
2019-03-05 12:03:10,580 - util.py[DEBUG]: Cloud-init v. 18.4-0ubuntu1~18.04.1 running 'modules:final' at Tue, 05 Mar 2019 12:03:10 +0000. Up 25.54 seconds.
2019-03-05 12:03:10,612 - stages.py[DEBUG]: Using distro class <class 'cloudinit.distros.ubuntu.Distro'>
2019-03-05 12:03:10,613 - stages.py[DEBUG]: Running module snappy (<module 'cloudinit.config.cc_snappy' from '/usr/lib/python3/dist-packages/cloudinit/config/cc_snappy.py'>) with frequency once-per-instance
2019-03-05 12:03:10,613 - handlers.py[DEBUG]: start: modules-final/config-snappy: running config-snappy with frequency once-per-instance
2019-03-05 12:03:10,614 - util.py[DEBUG]: Writing to /var/lib/cloud/instances/c24eca6d-063b-4de4-ab12-dcf37e5c0601/sem/config_snappy - wb: [644] 25 bytes
2019-03-05 12:03:10,614 - helpers.py[DEBUG]: Running config-snappy using lock (<FileLock using file '/var/lib/cloud/instances/c24eca6d-063b-4de4-ab12-dcf37e5c0601/sem/config_snappy'>)
2019-03-05 12:03:10,614 - util.py[DEBUG]: Reading from /etc/os-release (quiet=True)
2019-03-05 12:03:10,614 - util.py[DEBUG]: Read 386 bytes from /etc/os-release
2019-03-05 12:03:10,615 - util.py[DEBUG]: Reading from /etc/system-image/channel.ini (quiet=True)
2019-03-05 12:03:10,615 - util.py[DEBUG]: Read 0 bytes from /etc/system-image/channel.ini
2019-03-05 12:03:10,615 - cc_snappy.py[DEBUG]: snappy: 'auto' mode, and system not snappy
2019-03-05 12:03:10,615 - handlers.py[DEBUG]: finish: modules-final/config-snappy: SUCCESS: config-snappy ran successfully
2019-03-05 12:03:10,615 - stages.py[DEBUG]: Running module package-update-upgrade-install (<module 'cloudinit.config.cc_package_update_upgrade_install' from '/usr/lib/python3/dist-packages/cloudinit/config/cc_package_update_upgrade_install.py'>) with frequency once-per-instance
2019-03-05 12:03:10,616 - handlers.py[DEBUG]: start: modules-final/config-package-update-upgrade-install: running config-package-update-upgrade-install with frequency once-per-instance
2019-03-05 12:03:10,616 - util.py[DEBUG]: Writing to /var/lib/cloud/instances/c24eca6d-063b-4de4-ab12-dcf37e5c0601/sem/config_package_update_upgrade_install - wb: [644] 25 bytes
2019-03-05 12:03:10,616 - helpers.py[DEBUG]: Running config-package-update-upgrade-install using lock (<FileLock using file '/var/lib/cloud/instances/c24eca6d-063b-4de4-ab12-dcf37e5c0601/sem/config_package_update_upgrade_install'>)
2019-03-05 12:03:10,617 - util.py[DEBUG]: Writing to /var/lib/cloud/instances/c24eca6d-063b-4de4-ab12-dcf37e5c0601/sem/update_sources - wb: [644] 25 bytes
2019-03-05 12:03:10,617 - helpers.py[DEBUG]: Running update-sources using lock (<FileLock using file '/var/lib/cloud/instances/c24eca6d-063b-4de4-ab12-dcf37e5c0601/sem/update_sources'>)
2019-03-05 12:03:10,617 - util.py[DEBUG]: Running command ['eatmydata', 'apt-get', '--option=Dpkg::Options::=--force-confold', '--option=Dpkg::options::=--force-unsafe-io', '--assume-yes', '--quiet', 'update'] with allowed return codes [0] (shell=False, capture=False)
2019-03-05 12:03:22,861 - util.py[DEBUG]: apt-update [eatmydata apt-get --option=Dpkg::Options::=--force-confold --option=Dpkg::options::=--force-unsafe-io --assume-yes --quiet update] took 12.244 seconds
2019-03-05 12:03:22,862 - util.py[DEBUG]: Running command ['eatmydata', 'apt-get', '--option=Dpkg::Options::=--force-confold', '--option=Dpkg::options::=--force-unsafe-io', '--assume-yes', '--quiet', 'dist-upgrade'] with allowed return codes [0] (shell=False, capture=False)
2019-03-05 12:04:39,026 - util.py[DEBUG]: apt-upgrade [eatmydata apt-get --option=Dpkg::Options::=--force-confold --option=Dpkg::options::=--force-unsafe-io --assume-yes --quiet dist-upgrade] took 76.164 seconds
2019-03-05 12:04:39,028 - util.py[WARNING]: Package upgrade failed
2019-03-05 12:04:39,028 - util.py[DEBUG]: Package upgrade failed
Traceback (most recent call last):
  File "/usr/lib/python3/dist-packages/cloudinit/config/cc_package_update_upgrade_install.py", line 92, in handle
    cloud.distro.package_command("upgrade")
  File "/usr/lib/python3/dist-packages/cloudinit/distros/debian.py", line 200, in package_command
    args=(cmd,), kwargs={'env': e, 'capture': False})
  File "/usr/lib/python3/dist-packages/cloudinit/util.py", line 2514, in log_time
    ret = func(*args, **kwargs)
  File "/usr/lib/python3/dist-packages/cloudinit/util.py", line 2067, in subp
    cmd=args)
cloudinit.util.ProcessExecutionError: Unexpected error while running command.
Command: ['eatmydata', 'apt-get', '--option=Dpkg::Options::=--force-confold', '--option=Dpkg::options::=--force-unsafe-io', '--assume-yes', '--quiet', 'dist-upgrade']
Exit code: 100
Reason: -
Stdout: -
Stderr: -
2019-03-05 12:04:39,055 - helpers.py[DEBUG]: update-sources already ran (freq=once-per-instance)
2019-03-05 12:04:39,055 - util.py[DEBUG]: Running command ['eatmydata', 'apt-get', '--option=Dpkg::Options::=--force-confold', '--option=Dpkg::options::=--force-unsafe-io', '--assume-yes', '--quiet', 'install', 'mc', 'htop', 'python'] with allowed return codes [0] (shell=False, capture=False)
2019-03-05 12:04:58,143 - util.py[DEBUG]: apt-install [eatmydata apt-get --option=Dpkg::Options::=--force-confold --option=Dpkg::options::=--force-unsafe-io --assume-yes --quiet install mc htop python] took 19.087 seconds
2019-03-05 12:04:58,143 - util.py[WARNING]: Failed to install packages: ['mc', 'htop', 'python']
2019-03-05 12:04:58,144 - util.py[DEBUG]: Failed to install packages: ['mc', 'htop', 'python']
Traceback (most recent call last):
  File "/usr/lib/python3/dist-packages/cloudinit/config/cc_package_update_upgrade_install.py", line 99, in handle
    cloud.distro.install_packages(pkglist)
  File "/usr/lib/python3/dist-packages/cloudinit/distros/debian.py", line 110, in install_packages
    self.package_command('install', pkgs=pkglist)
  File "/usr/lib/python3/dist-packages/cloudinit/distros/debian.py", line 200, in package_command
    args=(cmd,), kwargs={'env': e, 'capture': False})
  File "/usr/lib/python3/dist-packages/cloudinit/util.py", line 2514, in log_time
    ret = func(*args, **kwargs)
  File "/usr/lib/python3/dist-packages/cloudinit/util.py", line 2067, in subp
    cmd=args)
cloudinit.util.ProcessExecutionError: Unexpected error while running command.
Command: ['eatmydata', 'apt-get', '--option=Dpkg::Options::=--force-confold', '--option=Dpkg::options::=--force-unsafe-io', '--assume-yes', '--quiet', 'install', 'mc', 'htop', 'python']
Exit code: 100
Reason: -
Stdout: -
Stderr: -
2019-03-05 12:04:58,144 - cc_package_update_upgrade_install.py[WARNING]: 2 failed with exceptions, re-raising the last one
2019-03-05 12:04:58,144 - handlers.py[DEBUG]: finish: modules-final/config-package-update-upgrade-install: FAIL: running config-package-update-upgrade-install with frequency once-per-instance
2019-03-05 12:04:58,144 - util.py[WARNING]: Running module package-update-upgrade-install (<module 'cloudinit.config.cc_package_update_upgrade_install' from '/usr/lib/python3/dist-packages/cloudinit/config/cc_package_update_upgrade_install.py'>) failed
2019-03-05 12:04:58,145 - util.py[DEBUG]: Running module package-update-upgrade-install (<module 'cloudinit.config.cc_package_update_upgrade_install' from '/usr/lib/python3/dist-packages/cloudinit/config/cc_package_update_upgrade_install.py'>) failed
Traceback (most recent call last):
  File "/usr/lib/python3/dist-packages/cloudinit/stages.py", line 812, in _run_modules
    freq=freq)
  File "/usr/lib/python3/dist-packages/cloudinit/cloud.py", line 54, in run
    return self._runners.run(name, functor, args, freq, clear_on_fail)
  File "/usr/lib/python3/dist-packages/cloudinit/helpers.py", line 187, in run
    results = functor(*args)
  File "/usr/lib/python3/dist-packages/cloudinit/config/cc_package_update_upgrade_install.py", line 122, in handle
    raise errors[-1]
  File "/usr/lib/python3/dist-packages/cloudinit/config/cc_package_update_upgrade_install.py", line 99, in handle
    cloud.distro.install_packages(pkglist)
  File "/usr/lib/python3/dist-packages/cloudinit/distros/debian.py", line 110, in install_packages
    self.package_command('install', pkgs=pkglist)
  File "/usr/lib/python3/dist-packages/cloudinit/distros/debian.py", line 200, in package_command
    args=(cmd,), kwargs={'env': e, 'capture': False})
  File "/usr/lib/python3/dist-packages/cloudinit/util.py", line 2514, in log_time
    ret = func(*args, **kwargs)
  File "/usr/lib/python3/dist-packages/cloudinit/util.py", line 2067, in subp
    cmd=args)
cloudinit.util.ProcessExecutionError: Unexpected error while running command.
Command: ['eatmydata', 'apt-get', '--option=Dpkg::Options::=--force-confold', '--option=Dpkg::options::=--force-unsafe-io', '--assume-yes', '--quiet', 'install', 'mc', 'htop', 'python']
Exit code: 100
Reason: -
Stdout: -
Stderr: -
2019-03-05 12:04:58,161 - stages.py[DEBUG]: Running module fan (<module 'cloudinit.config.cc_fan' from '/usr/lib/python3/dist-packages/cloudinit/config/cc_fan.py'>) with frequency once-per-instance
2019-03-05 12:04:58,161 - handlers.py[DEBUG]: start: modules-final/config-fan: running config-fan with frequency once-per-instance
2019-03-05 12:04:58,161 - util.py[DEBUG]: Writing to /var/lib/cloud/instances/c24eca6d-063b-4de4-ab12-dcf37e5c0601/sem/config_fan - wb: [644] 25 bytes
2019-03-05 12:04:58,163 - helpers.py[DEBUG]: Running config-fan using lock (<FileLock using file '/var/lib/cloud/instances/c24eca6d-063b-4de4-ab12-dcf37e5c0601/sem/config_fan'>)
2019-03-05 12:04:58,163 - cc_fan.py[DEBUG]: fan: no 'fan' config entry. disabling
2019-03-05 12:04:58,164 - handlers.py[DEBUG]: finish: modules-final/config-fan: SUCCESS: config-fan ran successfully
2019-03-05 12:04:58,164 - stages.py[DEBUG]: Running module landscape (<module 'cloudinit.config.cc_landscape' from '/usr/lib/python3/dist-packages/cloudinit/config/cc_landscape.py'>) with frequency once-per-instance
2019-03-05 12:04:58,164 - handlers.py[DEBUG]: start: modules-final/config-landscape: running config-landscape with frequency once-per-instance
2019-03-05 12:04:58,164 - util.py[DEBUG]: Writing to /var/lib/cloud/instances/c24eca6d-063b-4de4-ab12-dcf37e5c0601/sem/config_landscape - wb: [644] 25 bytes
2019-03-05 12:04:58,165 - helpers.py[DEBUG]: Running config-landscape using lock (<FileLock using file '/var/lib/cloud/instances/c24eca6d-063b-4de4-ab12-dcf37e5c0601/sem/config_landscape'>)
2019-03-05 12:04:58,165 - handlers.py[DEBUG]: finish: modules-final/config-landscape: SUCCESS: config-landscape ran successfully
2019-03-05 12:04:58,165 - stages.py[DEBUG]: Running module lxd (<module 'cloudinit.config.cc_lxd' from '/usr/lib/python3/dist-packages/cloudinit/config/cc_lxd.py'>) with frequency once-per-instance
2019-03-05 12:04:58,165 - handlers.py[DEBUG]: start: modules-final/config-lxd: running config-lxd with frequency once-per-instance
2019-03-05 12:04:58,165 - util.py[DEBUG]: Writing to /var/lib/cloud/instances/c24eca6d-063b-4de4-ab12-dcf37e5c0601/sem/config_lxd - wb: [644] 24 bytes
2019-03-05 12:04:58,166 - helpers.py[DEBUG]: Running config-lxd using lock (<FileLock using file '/var/lib/cloud/instances/c24eca6d-063b-4de4-ab12-dcf37e5c0601/sem/config_lxd'>)
2019-03-05 12:04:58,166 - cc_lxd.py[DEBUG]: Skipping module named lxd, not present or disabled by cfg
2019-03-05 12:04:58,175 - handlers.py[DEBUG]: finish: modules-final/config-lxd: SUCCESS: config-lxd ran successfully
2019-03-05 12:04:58,175 - stages.py[DEBUG]: Running module puppet (<module 'cloudinit.config.cc_puppet' from '/usr/lib/python3/dist-packages/cloudinit/config/cc_puppet.py'>) with frequency once-per-instance
2019-03-05 12:04:58,175 - handlers.py[DEBUG]: start: modules-final/config-puppet: running config-puppet with frequency once-per-instance
2019-03-05 12:04:58,175 - util.py[DEBUG]: Writing to /var/lib/cloud/instances/c24eca6d-063b-4de4-ab12-dcf37e5c0601/sem/config_puppet - wb: [644] 25 bytes
2019-03-05 12:04:58,176 - helpers.py[DEBUG]: Running config-puppet using lock (<FileLock using file '/var/lib/cloud/instances/c24eca6d-063b-4de4-ab12-dcf37e5c0601/sem/config_puppet'>)
2019-03-05 12:04:58,176 - cc_puppet.py[DEBUG]: Skipping module named puppet, no 'puppet' configuration found
2019-03-05 12:04:58,176 - handlers.py[DEBUG]: finish: modules-final/config-puppet: SUCCESS: config-puppet ran successfully
2019-03-05 12:04:58,176 - stages.py[DEBUG]: Running module chef (<module 'cloudinit.config.cc_chef' from '/usr/lib/python3/dist-packages/cloudinit/config/cc_chef.py'>) with frequency once-per-instance
2019-03-05 12:04:58,177 - handlers.py[DEBUG]: start: modules-final/config-chef: running config-chef with frequency once-per-instance
2019-03-05 12:04:58,177 - util.py[DEBUG]: Writing to /var/lib/cloud/instances/c24eca6d-063b-4de4-ab12-dcf37e5c0601/sem/config_chef - wb: [644] 24 bytes
2019-03-05 12:04:58,177 - helpers.py[DEBUG]: Running config-chef using lock (<FileLock using file '/var/lib/cloud/instances/c24eca6d-063b-4de4-ab12-dcf37e5c0601/sem/config_chef'>)
2019-03-05 12:04:58,177 - cc_chef.py[DEBUG]: Skipping module named chef, no 'chef' key in configuration
2019-03-05 12:04:58,177 - handlers.py[DEBUG]: finish: modules-final/config-chef: SUCCESS: config-chef ran successfully
2019-03-05 12:04:58,177 - stages.py[DEBUG]: Running module mcollective (<module 'cloudinit.config.cc_mcollective' from '/usr/lib/python3/dist-packages/cloudinit/config/cc_mcollective.py'>) with frequency once-per-instance
2019-03-05 12:04:58,178 - handlers.py[DEBUG]: start: modules-final/config-mcollective: running config-mcollective with frequency once-per-instance
2019-03-05 12:04:58,178 - util.py[DEBUG]: Writing to /var/lib/cloud/instances/c24eca6d-063b-4de4-ab12-dcf37e5c0601/sem/config_mcollective - wb: [644] 25 bytes
2019-03-05 12:04:58,178 - helpers.py[DEBUG]: Running config-mcollective using lock (<FileLock using file '/var/lib/cloud/instances/c24eca6d-063b-4de4-ab12-dcf37e5c0601/sem/config_mcollective'>)
2019-03-05 12:04:58,179 - cc_mcollective.py[DEBUG]: Skipping module named mcollective, no 'mcollective' key in configuration
2019-03-05 12:04:58,179 - handlers.py[DEBUG]: finish: modules-final/config-mcollective: SUCCESS: config-mcollective ran successfully
2019-03-05 12:04:58,179 - stages.py[DEBUG]: Running module salt-minion (<module 'cloudinit.config.cc_salt_minion' from '/usr/lib/python3/dist-packages/cloudinit/config/cc_salt_minion.py'>) with frequency once-per-instance
2019-03-05 12:04:58,179 - handlers.py[DEBUG]: start: modules-final/config-salt-minion: running config-salt-minion with frequency once-per-instance
2019-03-05 12:04:58,179 - util.py[DEBUG]: Writing to /var/lib/cloud/instances/c24eca6d-063b-4de4-ab12-dcf37e5c0601/sem/config_salt_minion - wb: [644] 25 bytes
2019-03-05 12:04:58,180 - helpers.py[DEBUG]: Running config-salt-minion using lock (<FileLock using file '/var/lib/cloud/instances/c24eca6d-063b-4de4-ab12-dcf37e5c0601/sem/config_salt_minion'>)
2019-03-05 12:04:58,180 - cc_salt_minion.py[DEBUG]: Skipping module named salt-minion, no 'salt_minion' key in configuration
2019-03-05 12:04:58,180 - handlers.py[DEBUG]: finish: modules-final/config-salt-minion: SUCCESS: config-salt-minion ran successfully
2019-03-05 12:04:58,180 - stages.py[DEBUG]: Running module rightscale_userdata (<module 'cloudinit.config.cc_rightscale_userdata' from '/usr/lib/python3/dist-packages/cloudinit/config/cc_rightscale_userdata.py'>) with frequency once-per-instance
2019-03-05 12:04:58,180 - handlers.py[DEBUG]: start: modules-final/config-rightscale_userdata: running config-rightscale_userdata with frequency once-per-instance
2019-03-05 12:04:58,180 - util.py[DEBUG]: Writing to /var/lib/cloud/instances/c24eca6d-063b-4de4-ab12-dcf37e5c0601/sem/config_rightscale_userdata - wb: [644] 25 bytes
2019-03-05 12:04:58,181 - helpers.py[DEBUG]: Running config-rightscale_userdata using lock (<FileLock using file '/var/lib/cloud/instances/c24eca6d-063b-4de4-ab12-dcf37e5c0601/sem/config_rightscale_userdata'>)
2019-03-05 12:04:58,181 - cc_rightscale_userdata.py[DEBUG]: Failed to get raw userdata in module rightscale_userdata
2019-03-05 12:04:58,181 - handlers.py[DEBUG]: finish: modules-final/config-rightscale_userdata: SUCCESS: config-rightscale_userdata ran successfully
2019-03-05 12:04:58,181 - stages.py[DEBUG]: Running module scripts-vendor (<module 'cloudinit.config.cc_scripts_vendor' from '/usr/lib/python3/dist-packages/cloudinit/config/cc_scripts_vendor.py'>) with frequency once-per-instance
2019-03-05 12:04:58,182 - handlers.py[DEBUG]: start: modules-final/config-scripts-vendor: running config-scripts-vendor with frequency once-per-instance
2019-03-05 12:04:58,182 - util.py[DEBUG]: Writing to /var/lib/cloud/instances/c24eca6d-063b-4de4-ab12-dcf37e5c0601/sem/config_scripts_vendor - wb: [644] 24 bytes
2019-03-05 12:04:58,187 - helpers.py[DEBUG]: Running config-scripts-vendor using lock (<FileLock using file '/var/lib/cloud/instances/c24eca6d-063b-4de4-ab12-dcf37e5c0601/sem/config_scripts_vendor'>)
2019-03-05 12:04:58,204 - util.py[DEBUG]: Running command ['/var/lib/cloud/instance/scripts/vendor/part-001'] with allowed return codes [0] (shell=False, capture=False)
2019-03-05 12:04:58,224 - handlers.py[DEBUG]: finish: modules-final/config-scripts-vendor: SUCCESS: config-scripts-vendor ran successfully
2019-03-05 12:04:58,224 - stages.py[DEBUG]: Running module scripts-per-once (<module 'cloudinit.config.cc_scripts_per_once' from '/usr/lib/python3/dist-packages/cloudinit/config/cc_scripts_per_once.py'>) with frequency once
2019-03-05 12:04:58,225 - handlers.py[DEBUG]: start: modules-final/config-scripts-per-once: running config-scripts-per-once with frequency once
2019-03-05 12:04:58,226 - util.py[DEBUG]: Writing to /var/lib/cloud/sem/config_scripts_per_once.once - wb: [644] 23 bytes
2019-03-05 12:04:58,226 - helpers.py[DEBUG]: Running config-scripts-per-once using lock (<FileLock using file '/var/lib/cloud/sem/config_scripts_per_once.once'>)
2019-03-05 12:04:58,228 - handlers.py[DEBUG]: finish: modules-final/config-scripts-per-once: SUCCESS: config-scripts-per-once ran successfully
2019-03-05 12:04:58,228 - stages.py[DEBUG]: Running module scripts-per-boot (<module 'cloudinit.config.cc_scripts_per_boot' from '/usr/lib/python3/dist-packages/cloudinit/config/cc_scripts_per_boot.py'>) with frequency always
2019-03-05 12:04:58,228 - handlers.py[DEBUG]: start: modules-final/config-scripts-per-boot: running config-scripts-per-boot with frequency always
2019-03-05 12:04:58,228 - helpers.py[DEBUG]: Running config-scripts-per-boot using lock (<cloudinit.helpers.DummyLock object at 0x7fa467029f60>)
2019-03-05 12:04:58,229 - handlers.py[DEBUG]: finish: modules-final/config-scripts-per-boot: SUCCESS: config-scripts-per-boot ran successfully
2019-03-05 12:04:58,229 - stages.py[DEBUG]: Running module scripts-per-instance (<module 'cloudinit.config.cc_scripts_per_instance' from '/usr/lib/python3/dist-packages/cloudinit/config/cc_scripts_per_instance.py'>) with frequency once-per-instance
2019-03-05 12:04:58,229 - handlers.py[DEBUG]: start: modules-final/config-scripts-per-instance: running config-scripts-per-instance with frequency once-per-instance
2019-03-05 12:04:58,230 - util.py[DEBUG]: Writing to /var/lib/cloud/instances/c24eca6d-063b-4de4-ab12-dcf37e5c0601/sem/config_scripts_per_instance - wb: [644] 25 bytes
2019-03-05 12:04:58,230 - helpers.py[DEBUG]: Running config-scripts-per-instance using lock (<FileLock using file '/var/lib/cloud/instances/c24eca6d-063b-4de4-ab12-dcf37e5c0601/sem/config_scripts_per_instance'>)
2019-03-05 12:04:58,231 - handlers.py[DEBUG]: finish: modules-final/config-scripts-per-instance: SUCCESS: config-scripts-per-instance ran successfully
2019-03-05 12:04:58,231 - stages.py[DEBUG]: Running module scripts-user (<module 'cloudinit.config.cc_scripts_user' from '/usr/lib/python3/dist-packages/cloudinit/config/cc_scripts_user.py'>) with frequency once-per-instance
2019-03-05 12:04:58,231 - handlers.py[DEBUG]: start: modules-final/config-scripts-user: running config-scripts-user with frequency once-per-instance
2019-03-05 12:04:58,232 - util.py[DEBUG]: Writing to /var/lib/cloud/instances/c24eca6d-063b-4de4-ab12-dcf37e5c0601/sem/config_scripts_user - wb: [644] 25 bytes
2019-03-05 12:04:58,232 - helpers.py[DEBUG]: Running config-scripts-user using lock (<FileLock using file '/var/lib/cloud/instances/c24eca6d-063b-4de4-ab12-dcf37e5c0601/sem/config_scripts_user'>)
2019-03-05 12:04:58,232 - util.py[DEBUG]: Running command ['/var/lib/cloud/instance/scripts/runcmd'] with allowed return codes [0] (shell=False, capture=False)
2019-03-05 12:04:59,663 - handlers.py[DEBUG]: finish: modules-final/config-scripts-user: SUCCESS: config-scripts-user ran successfully
2019-03-05 12:04:59,663 - stages.py[DEBUG]: Running module ssh-authkey-fingerprints (<module 'cloudinit.config.cc_ssh_authkey_fingerprints' from '/usr/lib/python3/dist-packages/cloudinit/config/cc_ssh_authkey_fingerprints.py'>) with frequency once-per-instance
2019-03-05 12:04:59,664 - handlers.py[DEBUG]: start: modules-final/config-ssh-authkey-fingerprints: running config-ssh-authkey-fingerprints with frequency once-per-instance
2019-03-05 12:04:59,664 - util.py[DEBUG]: Writing to /var/lib/cloud/instances/c24eca6d-063b-4de4-ab12-dcf37e5c0601/sem/config_ssh_authkey_fingerprints - wb: [644] 24 bytes
2019-03-05 12:04:59,665 - helpers.py[DEBUG]: Running config-ssh-authkey-fingerprints using lock (<FileLock using file '/var/lib/cloud/instances/c24eca6d-063b-4de4-ab12-dcf37e5c0601/sem/config_ssh_authkey_fingerprints'>)
2019-03-05 12:04:59,666 - util.py[DEBUG]: Reading from /etc/ssh/sshd_config (quiet=False)
2019-03-05 12:04:59,666 - util.py[DEBUG]: Read 3248 bytes from /etc/ssh/sshd_config
2019-03-05 12:04:59,678 - util.py[DEBUG]: Reading from /home/ubuntu/.ssh/authorized_keys (quiet=False)
2019-03-05 12:04:59,680 - util.py[DEBUG]: Read 394 bytes from /home/ubuntu/.ssh/authorized_keys
2019-03-05 12:04:59,719 - handlers.py[DEBUG]: finish: modules-final/config-ssh-authkey-fingerprints: SUCCESS: config-ssh-authkey-fingerprints ran successfully
2019-03-05 12:04:59,719 - stages.py[DEBUG]: Running module keys-to-console (<module 'cloudinit.config.cc_keys_to_console' from '/usr/lib/python3/dist-packages/cloudinit/config/cc_keys_to_console.py'>) with frequency once-per-instance
2019-03-05 12:04:59,719 - handlers.py[DEBUG]: start: modules-final/config-keys-to-console: running config-keys-to-console with frequency once-per-instance
2019-03-05 12:04:59,719 - util.py[DEBUG]: Writing to /var/lib/cloud/instances/c24eca6d-063b-4de4-ab12-dcf37e5c0601/sem/config_keys_to_console - wb: [644] 25 bytes
2019-03-05 12:04:59,720 - helpers.py[DEBUG]: Running config-keys-to-console using lock (<FileLock using file '/var/lib/cloud/instances/c24eca6d-063b-4de4-ab12-dcf37e5c0601/sem/config_keys_to_console'>)
2019-03-05 12:04:59,721 - util.py[DEBUG]: Running command ['/usr/lib/cloud-init/write-ssh-key-fingerprints', '', 'ssh-dss'] with allowed return codes [0] (shell=False, capture=True)
2019-03-05 12:04:59,890 - handlers.py[DEBUG]: finish: modules-final/config-keys-to-console: SUCCESS: config-keys-to-console ran successfully
2019-03-05 12:04:59,890 - stages.py[DEBUG]: Running module phone-home (<module 'cloudinit.config.cc_phone_home' from '/usr/lib/python3/dist-packages/cloudinit/config/cc_phone_home.py'>) with frequency once-per-instance
2019-03-05 12:04:59,891 - handlers.py[DEBUG]: start: modules-final/config-phone-home: running config-phone-home with frequency once-per-instance
2019-03-05 12:04:59,891 - util.py[DEBUG]: Writing to /var/lib/cloud/instances/c24eca6d-063b-4de4-ab12-dcf37e5c0601/sem/config_phone_home - wb: [644] 25 bytes
2019-03-05 12:04:59,892 - helpers.py[DEBUG]: Running config-phone-home using lock (<FileLock using file '/var/lib/cloud/instances/c24eca6d-063b-4de4-ab12-dcf37e5c0601/sem/config_phone_home'>)
2019-03-05 12:04:59,892 - cc_phone_home.py[DEBUG]: Skipping module named phone-home, no 'phone_home' configuration found
2019-03-05 12:04:59,892 - handlers.py[DEBUG]: finish: modules-final/config-phone-home: SUCCESS: config-phone-home ran successfully
2019-03-05 12:04:59,892 - stages.py[DEBUG]: Running module final-message (<module 'cloudinit.config.cc_final_message' from '/usr/lib/python3/dist-packages/cloudinit/config/cc_final_message.py'>) with frequency always
2019-03-05 12:04:59,892 - handlers.py[DEBUG]: start: modules-final/config-final-message: running config-final-message with frequency always
2019-03-05 12:04:59,892 - helpers.py[DEBUG]: Running config-final-message using lock (<cloudinit.helpers.DummyLock object at 0x7fa462a455c0>)
2019-03-05 12:04:59,893 - util.py[DEBUG]: Reading from /proc/uptime (quiet=False)
2019-03-05 12:04:59,893 - util.py[DEBUG]: Read 13 bytes from /proc/uptime
2019-03-05 12:04:59,893 - util.py[DEBUG]: The system is finally up, after 134.95 seconds
2019-03-05 12:04:59,893 - util.py[DEBUG]: Writing to /var/lib/cloud/instance/boot-finished - wb: [644] 68 bytes
2019-03-05 12:04:59,893 - handlers.py[DEBUG]: finish: modules-final/config-final-message: SUCCESS: config-final-message ran successfully
2019-03-05 12:04:59,894 - stages.py[DEBUG]: Running module power-state-change (<module 'cloudinit.config.cc_power_state_change' from '/usr/lib/python3/dist-packages/cloudinit/config/cc_power_state_change.py'>) with frequency once-per-instance
2019-03-05 12:04:59,894 - handlers.py[DEBUG]: start: modules-final/config-power-state-change: running config-power-state-change with frequency once-per-instance
2019-03-05 12:04:59,894 - util.py[DEBUG]: Writing to /var/lib/cloud/instances/c24eca6d-063b-4de4-ab12-dcf37e5c0601/sem/config_power_state_change - wb: [644] 25 bytes
2019-03-05 12:04:59,895 - helpers.py[DEBUG]: Running config-power-state-change using lock (<FileLock using file '/var/lib/cloud/instances/c24eca6d-063b-4de4-ab12-dcf37e5c0601/sem/config_power_state_change'>)
2019-03-05 12:04:59,896 - util.py[DEBUG]: Reading from /etc/os-release (quiet=False)
2019-03-05 12:04:59,896 - util.py[DEBUG]: Read 386 bytes from /etc/os-release
2019-03-05 12:04:59,897 - util.py[DEBUG]: Reading from /proc/1096/cmdline (quiet=False)
2019-03-05 12:04:59,897 - util.py[DEBUG]: Read 58 bytes from /proc/1096/cmdline
2019-03-05 12:04:59,897 - cc_power_state_change.py[DEBUG]: After pid 1096 ends, will execute: shutdown -r now
2019-03-05 12:04:59,898 - util.py[DEBUG]: Forked child 21404 who will run callback run_after_pid_gone
2019-03-05 12:04:59,899 - handlers.py[DEBUG]: finish: modules-final/config-power-state-change: SUCCESS: config-power-state-change ran successfully
2019-03-05 12:04:59,899 - main.py[DEBUG]: Ran 20 modules with 1 failures
2019-03-05 12:04:59,902 - util.py[DEBUG]: Creating symbolic link from '/run/cloud-init/result.json' => '../../var/lib/cloud/data/result.json'
2019-03-05 12:04:59,902 - util.py[DEBUG]: Reading from /proc/uptime (quiet=False)
2019-03-05 12:04:59,902 - util.py[DEBUG]: Read 13 bytes from /proc/uptime
2019-03-05 12:04:59,902 - util.py[DEBUG]: Reading from /etc/os-release (quiet=False)
2019-03-05 12:04:59,903 - util.py[DEBUG]: Read 386 bytes from /etc/os-release
2019-03-05 12:04:59,903 - util.py[DEBUG]: Reading from /proc/1096/cmdline (quiet=False)
2019-03-05 12:04:59,904 - util.py[DEBUG]: Read 58 bytes from /proc/1096/cmdline
2019-03-05 12:04:59,902 - util.py[DEBUG]: cloud-init mode 'modules' took 109.423 seconds (109.42)
2019-03-05 12:04:59,904 - handlers.py[DEBUG]: finish: modules-final: FAIL: running modules for final
2019-03-05 12:05:00,154 - util.py[DEBUG]: Reading from /etc/os-release (quiet=False)
2019-03-05 12:05:00,155 - util.py[DEBUG]: Read 386 bytes from /etc/os-release
2019-03-05 12:05:00,155 - util.py[DEBUG]: Reading from /proc/1096/cmdline (quiet=False)
2019-03-05 12:05:00,155 - cc_power_state_change.py[DEBUG]: cmdline changed for 1096 [now: None]
2019-03-05 12:05:00,155 - cc_power_state_change.py[DEBUG]: Static Condition: True
2019-03-05 12:05:36,076 - util.py[DEBUG]: Cloud-init v. 18.4-0ubuntu1~18.04.1 running 'init-local' at Tue, 05 Mar 2019 12:05:36 +0000. Up 10.68 seconds.
2019-03-05 12:05:36,078 - main.py[DEBUG]: No kernel command line url found.
2019-03-05 12:05:36,078 - main.py[DEBUG]: Closing stdin.
2019-03-05 12:05:36,081 - util.py[DEBUG]: Writing to /var/log/cloud-init.log - ab: [644] 0 bytes
2019-03-05 12:05:36,083 - util.py[DEBUG]: Changing the ownership of /var/log/cloud-init.log to 102:4
2019-03-05 12:05:36,083 - util.py[DEBUG]: Attempting to remove /var/lib/cloud/instance/boot-finished
2019-03-05 12:05:36,083 - util.py[DEBUG]: Attempting to remove /var/lib/cloud/data/no-net
2019-03-05 12:05:36,083 - handlers.py[DEBUG]: start: init-local/check-cache: attempting to read from cache [check]
2019-03-05 12:05:36,083 - util.py[DEBUG]: Reading from /var/lib/cloud/instance/obj.pkl (quiet=False)
2019-03-05 12:05:36,085 - util.py[DEBUG]: Read 11360 bytes from /var/lib/cloud/instance/obj.pkl
2019-03-05 12:05:36,095 - util.py[DEBUG]: Reading from /sys/hypervisor/uuid (quiet=False)
2019-03-05 12:05:36,095 - util.py[DEBUG]: Read 37 bytes from /sys/hypervisor/uuid
2019-03-05 12:05:36,095 - stages.py[DEBUG]: restored from checked cache: DataSourceIBMCloud [OS-Code/Live /dev/xvdh]
2019-03-05 12:05:36,095 - handlers.py[DEBUG]: finish: init-local/check-cache: SUCCESS: restored from checked cache: DataSourceIBMCloud [OS-Code/Live /dev/xvdh]
2019-03-05 12:05:36,095 - util.py[DEBUG]: Reading from /etc/cloud/cloud.cfg (quiet=False)
2019-03-05 12:05:36,095 - util.py[DEBUG]: Read 3169 bytes from /etc/cloud/cloud.cfg
2019-03-05 12:05:36,095 - util.py[DEBUG]: Attempting to load yaml from string of length 3169 with allowed root types (<class 'dict'>,)
2019-03-05 12:05:36,128 - util.py[DEBUG]: Reading from /etc/cloud/cloud.cfg.d/99_networklayer_common.cfg (quiet=False)
2019-03-05 12:05:36,129 - util.py[DEBUG]: Read 989 bytes from /etc/cloud/cloud.cfg.d/99_networklayer_common.cfg
2019-03-05 12:05:36,129 - util.py[DEBUG]: Attempting to load yaml from string of length 989 with allowed root types (<class 'dict'>,)
2019-03-05 12:05:36,134 - util.py[DEBUG]: Reading from /etc/cloud/cloud.cfg.d/90_dpkg.cfg (quiet=False)
2019-03-05 12:05:36,135 - util.py[DEBUG]: Read 257 bytes from /etc/cloud/cloud.cfg.d/90_dpkg.cfg
2019-03-05 12:05:36,135 - util.py[DEBUG]: Attempting to load yaml from string of length 257 with allowed root types (<class 'dict'>,)
2019-03-05 12:05:36,137 - util.py[DEBUG]: Reading from /etc/cloud/cloud.cfg.d/05_logging.cfg (quiet=False)
2019-03-05 12:05:36,137 - util.py[DEBUG]: Read 2057 bytes from /etc/cloud/cloud.cfg.d/05_logging.cfg
2019-03-05 12:05:36,137 - util.py[DEBUG]: Attempting to load yaml from string of length 2057 with allowed root types (<class 'dict'>,)
2019-03-05 12:05:36,142 - util.py[DEBUG]: Reading from /run/cloud-init/cloud.cfg (quiet=False)
2019-03-05 12:05:36,142 - util.py[DEBUG]: Read 36 bytes from /run/cloud-init/cloud.cfg
2019-03-05 12:05:36,142 - util.py[DEBUG]: Attempting to load yaml from string of length 36 with allowed root types (<class 'dict'>,)
2019-03-05 12:05:36,143 - util.py[DEBUG]: Attempting to load yaml from string of length 0 with allowed root types (<class 'dict'>,)
2019-03-05 12:05:36,143 - util.py[DEBUG]: loaded blob returned None, returning default.
2019-03-05 12:05:36,144 - util.py[DEBUG]: Reading from /var/lib/cloud/instance/cloud-config.txt (quiet=False)
2019-03-05 12:05:36,144 - util.py[DEBUG]: Read 363 bytes from /var/lib/cloud/instance/cloud-config.txt
2019-03-05 12:05:36,144 - util.py[DEBUG]: Attempting to load yaml from string of length 363 with allowed root types (<class 'dict'>,)
2019-03-05 12:05:36,147 - util.py[DEBUG]: Reading from /var/lib/cloud/instance/vendor-cloud-config.txt (quiet=False)
2019-03-05 12:05:36,147 - util.py[DEBUG]: Read 0 bytes from /var/lib/cloud/instance/vendor-cloud-config.txt
2019-03-05 12:05:36,147 - util.py[DEBUG]: Attempting to load yaml from string of length 0 with allowed root types (<class 'dict'>,)
2019-03-05 12:05:36,147 - util.py[DEBUG]: loaded blob returned None, returning default.
2019-03-05 12:05:36,150 - util.py[DEBUG]: Attempting to remove /var/lib/cloud/instance
2019-03-05 12:05:36,150 - util.py[DEBUG]: Creating symbolic link from '/var/lib/cloud/instance' => '/var/lib/cloud/instances/c24eca6d-063b-4de4-ab12-dcf37e5c0601'
2019-03-05 12:05:36,151 - util.py[DEBUG]: Reading from /var/lib/cloud/instances/c24eca6d-063b-4de4-ab12-dcf37e5c0601/datasource (quiet=False)
2019-03-05 12:05:36,152 - util.py[DEBUG]: Read 64 bytes from /var/lib/cloud/instances/c24eca6d-063b-4de4-ab12-dcf37e5c0601/datasource
2019-03-05 12:05:36,152 - util.py[DEBUG]: Writing to /var/lib/cloud/instances/c24eca6d-063b-4de4-ab12-dcf37e5c0601/datasource - wb: [644] 64 bytes
2019-03-05 12:05:36,152 - util.py[DEBUG]: Writing to /var/lib/cloud/data/previous-datasource - wb: [644] 64 bytes
2019-03-05 12:05:36,153 - util.py[DEBUG]: Reading from /var/lib/cloud/data/instance-id (quiet=False)
2019-03-05 12:05:36,154 - util.py[DEBUG]: Read 37 bytes from /var/lib/cloud/data/instance-id
2019-03-05 12:05:36,154 - stages.py[DEBUG]: previous iid found to be c24eca6d-063b-4de4-ab12-dcf37e5c0601
2019-03-05 12:05:36,154 - util.py[DEBUG]: Writing to /var/lib/cloud/data/instance-id - wb: [644] 37 bytes
2019-03-05 12:05:36,155 - util.py[DEBUG]: Writing to /run/cloud-init/.instance-id - wb: [644] 37 bytes
2019-03-05 12:05:36,155 - util.py[DEBUG]: Writing to /var/lib/cloud/data/previous-instance-id - wb: [644] 37 bytes
2019-03-05 12:05:36,156 - util.py[DEBUG]: Writing to /var/lib/cloud/instance/obj.pkl - wb: [400] 11430 bytes
2019-03-05 12:05:36,157 - main.py[DEBUG]: [local] init will now be targeting instance id: c24eca6d-063b-4de4-ab12-dcf37e5c0601. new=False
2019-03-05 12:05:36,157 - util.py[DEBUG]: Reading from /etc/cloud/cloud.cfg (quiet=False)
2019-03-05 12:05:36,157 - util.py[DEBUG]: Read 3169 bytes from /etc/cloud/cloud.cfg
2019-03-05 12:05:36,157 - util.py[DEBUG]: Attempting to load yaml from string of length 3169 with allowed root types (<class 'dict'>,)
2019-03-05 12:05:36,172 - util.py[DEBUG]: Reading from /etc/cloud/cloud.cfg.d/99_networklayer_common.cfg (quiet=False)
2019-03-05 12:05:36,172 - util.py[DEBUG]: Read 989 bytes from /etc/cloud/cloud.cfg.d/99_networklayer_common.cfg
2019-03-05 12:05:36,172 - util.py[DEBUG]: Attempting to load yaml from string of length 989 with allowed root types (<class 'dict'>,)
2019-03-05 12:05:36,178 - util.py[DEBUG]: Reading from /etc/cloud/cloud.cfg.d/90_dpkg.cfg (quiet=False)
2019-03-05 12:05:36,178 - util.py[DEBUG]: Read 257 bytes from /etc/cloud/cloud.cfg.d/90_dpkg.cfg
2019-03-05 12:05:36,178 - util.py[DEBUG]: Attempting to load yaml from string of length 257 with allowed root types (<class 'dict'>,)
2019-03-05 12:05:36,180 - util.py[DEBUG]: Reading from /etc/cloud/cloud.cfg.d/05_logging.cfg (quiet=False)
2019-03-05 12:05:36,180 - util.py[DEBUG]: Read 2057 bytes from /etc/cloud/cloud.cfg.d/05_logging.cfg
2019-03-05 12:05:36,180 - util.py[DEBUG]: Attempting to load yaml from string of length 2057 with allowed root types (<class 'dict'>,)
2019-03-05 12:05:36,185 - util.py[DEBUG]: Reading from /run/cloud-init/cloud.cfg (quiet=False)
2019-03-05 12:05:36,185 - util.py[DEBUG]: Read 36 bytes from /run/cloud-init/cloud.cfg
2019-03-05 12:05:36,185 - util.py[DEBUG]: Attempting to load yaml from string of length 36 with allowed root types (<class 'dict'>,)
2019-03-05 12:05:36,186 - util.py[DEBUG]: Attempting to load yaml from string of length 0 with allowed root types (<class 'dict'>,)
2019-03-05 12:05:36,186 - util.py[DEBUG]: loaded blob returned None, returning default.
2019-03-05 12:05:36,186 - util.py[DEBUG]: Reading from /var/lib/cloud/instance/cloud-config.txt (quiet=False)
2019-03-05 12:05:36,186 - util.py[DEBUG]: Read 363 bytes from /var/lib/cloud/instance/cloud-config.txt
2019-03-05 12:05:36,187 - util.py[DEBUG]: Attempting to load yaml from string of length 363 with allowed root types (<class 'dict'>,)
2019-03-05 12:05:36,189 - util.py[DEBUG]: Reading from /var/lib/cloud/instance/vendor-cloud-config.txt (quiet=False)
2019-03-05 12:05:36,189 - util.py[DEBUG]: Read 0 bytes from /var/lib/cloud/instance/vendor-cloud-config.txt
2019-03-05 12:05:36,189 - util.py[DEBUG]: Attempting to load yaml from string of length 0 with allowed root types (<class 'dict'>,)
2019-03-05 12:05:36,190 - util.py[DEBUG]: loaded blob returned None, returning default.
2019-03-05 12:05:36,191 - stages.py[DEBUG]: Using distro class <class 'cloudinit.distros.ubuntu.Distro'>
2019-03-05 12:05:36,192 - util.py[DEBUG]: Reading from /var/lib/cloud/data/set-hostname (quiet=False)
2019-03-05 12:05:36,193 - util.py[DEBUG]: Read 81 bytes from /var/lib/cloud/data/set-hostname
2019-03-05 12:05:36,193 - cc_set_hostname.py[DEBUG]: No hostname changes. Skipping set-hostname
2019-03-05 12:05:36,194 - stages.py[DEBUG]: applying net config names for {'version': 1, 'config': [{'name': 'eth0', 'mtu': None, 'type': 'physical', 'subnets': [{'type': 'static', 'netmask': '255.255.255.192', 'routes': [{'network': '10.0.0.0', 'netmask': '255.0.0.0', 'gateway': '10.142.39.1'}, {'network': '161.26.0.0', 'netmask': '255.255.0.0', 'gateway': '10.142.39.1'}, {'network': '166.8.0.0', 'netmask': '255.252.0.0', 'gateway': '10.142.39.1'}], 'address': '10.142.39.35', 'ipv4': True}], 'mac_address': '06:fc:9a:55:bf:9e'}, {'name': 'eth1', 'mtu': None, 'type': 'physical', 'subnets': [{'type': 'static', 'netmask': '255.255.255.240', 'routes': [{'network': '0.0.0.0', 'netmask': '0.0.0.0', 'gateway': '169.55.47.145'}], 'address': '169.55.47.148', 'ipv4': True}], 'mac_address': '06:99:ac:66:4b:33'}, {'type': 'nameserver', 'address': '10.0.80.11'}, {'type': 'nameserver', 'address': '10.0.80.12'}]}
2019-03-05 12:05:36,194 - util.py[DEBUG]: Reading from /sys/class/net/eth0/device/device (quiet=False)
2019-03-05 12:05:36,194 - util.py[DEBUG]: Reading from /sys/class/net/eth1/device/device (quiet=False)
2019-03-05 12:05:36,194 - util.py[DEBUG]: Reading from /sys/class/net/eth1/addr_assign_type (quiet=False)
2019-03-05 12:05:36,195 - util.py[DEBUG]: Read 2 bytes from /sys/class/net/eth1/addr_assign_type
2019-03-05 12:05:36,195 - util.py[DEBUG]: Reading from /sys/class/net/eth1/uevent (quiet=False)
2019-03-05 12:05:36,195 - util.py[DEBUG]: Read 25 bytes from /sys/class/net/eth1/uevent
2019-03-05 12:05:36,195 - util.py[DEBUG]: Reading from /sys/class/net/eth1/address (quiet=False)
2019-03-05 12:05:36,195 - util.py[DEBUG]: Read 18 bytes from /sys/class/net/eth1/address
2019-03-05 12:05:36,195 - util.py[DEBUG]: Reading from /sys/class/net/eth1/device/device (quiet=False)
2019-03-05 12:05:36,195 - util.py[DEBUG]: Reading from /sys/class/net/lo/addr_assign_type (quiet=False)
2019-03-05 12:05:36,195 - util.py[DEBUG]: Read 2 bytes from /sys/class/net/lo/addr_assign_type
2019-03-05 12:05:36,195 - util.py[DEBUG]: Reading from /sys/class/net/lo/uevent (quiet=False)
2019-03-05 12:05:36,195 - util.py[DEBUG]: Read 23 bytes from /sys/class/net/lo/uevent
2019-03-05 12:05:36,196 - util.py[DEBUG]: Reading from /sys/class/net/lo/address (quiet=False)
2019-03-05 12:05:36,196 - util.py[DEBUG]: Read 18 bytes from /sys/class/net/lo/address
2019-03-05 12:05:36,196 - util.py[DEBUG]: Reading from /sys/class/net/lo/device/device (quiet=False)
2019-03-05 12:05:36,196 - util.py[DEBUG]: Reading from /sys/class/net/eth0/addr_assign_type (quiet=False)
2019-03-05 12:05:36,196 - util.py[DEBUG]: Read 2 bytes from /sys/class/net/eth0/addr_assign_type
2019-03-05 12:05:36,196 - util.py[DEBUG]: Reading from /sys/class/net/eth0/uevent (quiet=False)
2019-03-05 12:05:36,196 - util.py[DEBUG]: Read 25 bytes from /sys/class/net/eth0/uevent
2019-03-05 12:05:36,196 - util.py[DEBUG]: Reading from /sys/class/net/eth0/address (quiet=False)
2019-03-05 12:05:36,196 - util.py[DEBUG]: Read 18 bytes from /sys/class/net/eth0/address
2019-03-05 12:05:36,196 - util.py[DEBUG]: Reading from /sys/class/net/eth0/device/device (quiet=False)
2019-03-05 12:05:36,196 - util.py[DEBUG]: Reading from /sys/class/net/eth1/operstate (quiet=False)
2019-03-05 12:05:36,197 - util.py[DEBUG]: Read 5 bytes from /sys/class/net/eth1/operstate
2019-03-05 12:05:36,197 - util.py[DEBUG]: Reading from /sys/class/net/lo/operstate (quiet=False)
2019-03-05 12:05:36,197 - util.py[DEBUG]: Read 8 bytes from /sys/class/net/lo/operstate
2019-03-05 12:05:36,197 - util.py[DEBUG]: Reading from /sys/class/net/eth0/operstate (quiet=False)
2019-03-05 12:05:36,197 - util.py[DEBUG]: Read 5 bytes from /sys/class/net/eth0/operstate
2019-03-05 12:05:36,197 - util.py[DEBUG]: Running command ['ip', '-6', 'addr', 'show', 'permanent', 'scope', 'global'] with allowed return codes [0] (shell=False, capture=True)
2019-03-05 12:05:36,201 - util.py[DEBUG]: Running command ['ip', '-4', 'addr', 'show'] with allowed return codes [0] (shell=False, capture=True)
2019-03-05 12:05:36,204 - __init__.py[DEBUG]: no work necessary for renaming of [['06:fc:9a:55:bf:9e', 'eth0', 'vif', None], ['06:99:ac:66:4b:33', 'eth1', 'vif', None]]
2019-03-05 12:05:36,205 - __init__.py[DEBUG]: Datasource DataSourceIBMCloud [OS-Code/Live /dev/xvdh] not updated for events: System boot
2019-03-05 12:05:36,205 - stages.py[DEBUG]: No network config applied. Neither a new instance nor datasource network update on 'System boot' event
2019-03-05 12:05:36,205 - main.py[DEBUG]: [local] Exiting. datasource DataSourceIBMCloud [OS-Code/Live /dev/xvdh] not in local mode.
2019-03-05 12:05:36,206 - util.py[DEBUG]: Reading from /proc/uptime (quiet=False)
2019-03-05 12:05:36,206 - util.py[DEBUG]: Read 11 bytes from /proc/uptime
2019-03-05 12:05:36,206 - util.py[DEBUG]: cloud-init mode 'init' took 0.215 seconds (0.22)
2019-03-05 12:05:36,206 - handlers.py[DEBUG]: finish: init-local: SUCCESS: searching for local datasources
2019-03-05 12:05:38,858 - util.py[DEBUG]: Cloud-init v. 18.4-0ubuntu1~18.04.1 running 'init' at Tue, 05 Mar 2019 12:05:38 +0000. Up 13.46 seconds.
2019-03-05 12:05:38,859 - main.py[DEBUG]: No kernel command line url found.
2019-03-05 12:05:38,859 - main.py[DEBUG]: Closing stdin.
2019-03-05 12:05:38,861 - util.py[DEBUG]: Writing to /var/log/cloud-init.log - ab: [644] 0 bytes
2019-03-05 12:05:38,862 - util.py[DEBUG]: Changing the ownership of /var/log/cloud-init.log to 102:4
2019-03-05 12:05:38,863 - util.py[DEBUG]: Running command ['ip', 'addr', 'show'] with allowed return codes [0] (shell=False, capture=True)
2019-03-05 12:05:38,868 - util.py[DEBUG]: Running command ['ip', '-o', 'route', 'list'] with allowed return codes [0] (shell=False, capture=True)
2019-03-05 12:05:38,871 - util.py[DEBUG]: Running command ['ip', '--oneline', '-6', 'route', 'list', 'table', 'all'] with allowed return codes [0, 1] (shell=False, capture=True)
2019-03-05 12:05:38,875 - main.py[DEBUG]: Checking to see if files that we need already exist from a previous run that would allow us to stop early.
2019-03-05 12:05:38,875 - main.py[DEBUG]: Execution continuing, no previous run detected that would allow us to stop early.
2019-03-05 12:05:38,876 - handlers.py[DEBUG]: start: init-network/check-cache: attempting to read from cache [trust]
2019-03-05 12:05:38,876 - util.py[DEBUG]: Reading from /var/lib/cloud/instance/obj.pkl (quiet=False)
2019-03-05 12:05:38,876 - util.py[DEBUG]: Read 11430 bytes from /var/lib/cloud/instance/obj.pkl
2019-03-05 12:05:38,881 - util.py[DEBUG]: Reading from /run/cloud-init/.instance-id (quiet=False)
2019-03-05 12:05:38,881 - util.py[DEBUG]: Read 37 bytes from /run/cloud-init/.instance-id
2019-03-05 12:05:38,881 - stages.py[DEBUG]: restored from cache with run check: DataSourceIBMCloud [OS-Code/Live /dev/xvdh]
2019-03-05 12:05:38,881 - handlers.py[DEBUG]: finish: init-network/check-cache: SUCCESS: restored from cache with run check: DataSourceIBMCloud [OS-Code/Live /dev/xvdh]
2019-03-05 12:05:38,882 - util.py[DEBUG]: Reading from /etc/cloud/cloud.cfg (quiet=False)
2019-03-05 12:05:38,882 - util.py[DEBUG]: Read 3169 bytes from /etc/cloud/cloud.cfg
2019-03-05 12:05:38,882 - util.py[DEBUG]: Attempting to load yaml from string of length 3169 with allowed root types (<class 'dict'>,)
2019-03-05 12:05:38,911 - util.py[DEBUG]: Reading from /etc/cloud/cloud.cfg.d/99_networklayer_common.cfg (quiet=False)
2019-03-05 12:05:38,911 - util.py[DEBUG]: Read 989 bytes from /etc/cloud/cloud.cfg.d/99_networklayer_common.cfg
2019-03-05 12:05:38,911 - util.py[DEBUG]: Attempting to load yaml from string of length 989 with allowed root types (<class 'dict'>,)
2019-03-05 12:05:38,916 - util.py[DEBUG]: Reading from /etc/cloud/cloud.cfg.d/90_dpkg.cfg (quiet=False)
2019-03-05 12:05:38,916 - util.py[DEBUG]: Read 257 bytes from /etc/cloud/cloud.cfg.d/90_dpkg.cfg
2019-03-05 12:05:38,916 - util.py[DEBUG]: Attempting to load yaml from string of length 257 with allowed root types (<class 'dict'>,)
2019-03-05 12:05:38,918 - util.py[DEBUG]: Reading from /etc/cloud/cloud.cfg.d/05_logging.cfg (quiet=False)
2019-03-05 12:05:38,918 - util.py[DEBUG]: Read 2057 bytes from /etc/cloud/cloud.cfg.d/05_logging.cfg
2019-03-05 12:05:38,918 - util.py[DEBUG]: Attempting to load yaml from string of length 2057 with allowed root types (<class 'dict'>,)
2019-03-05 12:05:38,923 - util.py[DEBUG]: Reading from /run/cloud-init/cloud.cfg (quiet=False)
2019-03-05 12:05:38,923 - util.py[DEBUG]: Read 36 bytes from /run/cloud-init/cloud.cfg
2019-03-05 12:05:38,923 - util.py[DEBUG]: Attempting to load yaml from string of length 36 with allowed root types (<class 'dict'>,)
2019-03-05 12:05:38,924 - util.py[DEBUG]: Attempting to load yaml from string of length 0 with allowed root types (<class 'dict'>,)
2019-03-05 12:05:38,924 - util.py[DEBUG]: loaded blob returned None, returning default.
2019-03-05 12:05:38,924 - util.py[DEBUG]: Reading from /var/lib/cloud/instance/cloud-config.txt (quiet=False)
2019-03-05 12:05:38,924 - util.py[DEBUG]: Read 363 bytes from /var/lib/cloud/instance/cloud-config.txt
2019-03-05 12:05:38,924 - util.py[DEBUG]: Attempting to load yaml from string of length 363 with allowed root types (<class 'dict'>,)
2019-03-05 12:05:38,927 - util.py[DEBUG]: Reading from /var/lib/cloud/instance/vendor-cloud-config.txt (quiet=False)
2019-03-05 12:05:38,927 - util.py[DEBUG]: Read 0 bytes from /var/lib/cloud/instance/vendor-cloud-config.txt
2019-03-05 12:05:38,927 - util.py[DEBUG]: Attempting to load yaml from string of length 0 with allowed root types (<class 'dict'>,)
2019-03-05 12:05:38,927 - util.py[DEBUG]: loaded blob returned None, returning default.
2019-03-05 12:05:38,928 - util.py[DEBUG]: Attempting to remove /var/lib/cloud/instance
2019-03-05 12:05:38,928 - util.py[DEBUG]: Creating symbolic link from '/var/lib/cloud/instance' => '/var/lib/cloud/instances/c24eca6d-063b-4de4-ab12-dcf37e5c0601'
2019-03-05 12:05:38,929 - util.py[DEBUG]: Reading from /var/lib/cloud/instances/c24eca6d-063b-4de4-ab12-dcf37e5c0601/datasource (quiet=False)
2019-03-05 12:05:38,929 - util.py[DEBUG]: Read 64 bytes from /var/lib/cloud/instances/c24eca6d-063b-4de4-ab12-dcf37e5c0601/datasource
2019-03-05 12:05:38,929 - util.py[DEBUG]: Writing to /var/lib/cloud/instances/c24eca6d-063b-4de4-ab12-dcf37e5c0601/datasource - wb: [644] 64 bytes
2019-03-05 12:05:38,930 - util.py[DEBUG]: Writing to /var/lib/cloud/data/previous-datasource - wb: [644] 64 bytes
2019-03-05 12:05:38,930 - util.py[DEBUG]: Reading from /var/lib/cloud/data/instance-id (quiet=False)
2019-03-05 12:05:38,930 - util.py[DEBUG]: Read 37 bytes from /var/lib/cloud/data/instance-id
2019-03-05 12:05:38,930 - stages.py[DEBUG]: previous iid found to be c24eca6d-063b-4de4-ab12-dcf37e5c0601
2019-03-05 12:05:38,930 - util.py[DEBUG]: Writing to /var/lib/cloud/data/instance-id - wb: [644] 37 bytes
2019-03-05 12:05:38,931 - util.py[DEBUG]: Writing to /run/cloud-init/.instance-id - wb: [644] 37 bytes
2019-03-05 12:05:38,931 - util.py[DEBUG]: Writing to /var/lib/cloud/data/previous-instance-id - wb: [644] 37 bytes
2019-03-05 12:05:38,932 - util.py[DEBUG]: Writing to /var/lib/cloud/instance/obj.pkl - wb: [400] 11430 bytes
2019-03-05 12:05:38,935 - main.py[DEBUG]: [net] init will now be targeting instance id: c24eca6d-063b-4de4-ab12-dcf37e5c0601. new=False
2019-03-05 12:05:38,935 - util.py[DEBUG]: Reading from /etc/cloud/cloud.cfg (quiet=False)
2019-03-05 12:05:38,935 - util.py[DEBUG]: Read 3169 bytes from /etc/cloud/cloud.cfg
2019-03-05 12:05:38,935 - util.py[DEBUG]: Attempting to load yaml from string of length 3169 with allowed root types (<class 'dict'>,)
2019-03-05 12:05:38,949 - util.py[DEBUG]: Reading from /etc/cloud/cloud.cfg.d/99_networklayer_common.cfg (quiet=False)
2019-03-05 12:05:38,949 - util.py[DEBUG]: Read 989 bytes from /etc/cloud/cloud.cfg.d/99_networklayer_common.cfg
2019-03-05 12:05:38,950 - util.py[DEBUG]: Attempting to load yaml from string of length 989 with allowed root types (<class 'dict'>,)
2019-03-05 12:05:38,955 - util.py[DEBUG]: Reading from /etc/cloud/cloud.cfg.d/90_dpkg.cfg (quiet=False)
2019-03-05 12:05:38,955 - util.py[DEBUG]: Read 257 bytes from /etc/cloud/cloud.cfg.d/90_dpkg.cfg
2019-03-05 12:05:38,955 - util.py[DEBUG]: Attempting to load yaml from string of length 257 with allowed root types (<class 'dict'>,)
2019-03-05 12:05:38,957 - util.py[DEBUG]: Reading from /etc/cloud/cloud.cfg.d/05_logging.cfg (quiet=False)
2019-03-05 12:05:38,957 - util.py[DEBUG]: Read 2057 bytes from /etc/cloud/cloud.cfg.d/05_logging.cfg
2019-03-05 12:05:38,957 - util.py[DEBUG]: Attempting to load yaml from string of length 2057 with allowed root types (<class 'dict'>,)
2019-03-05 12:05:38,961 - util.py[DEBUG]: Reading from /run/cloud-init/cloud.cfg (quiet=False)
2019-03-05 12:05:38,962 - util.py[DEBUG]: Read 36 bytes from /run/cloud-init/cloud.cfg
2019-03-05 12:05:38,962 - util.py[DEBUG]: Attempting to load yaml from string of length 36 with allowed root types (<class 'dict'>,)
2019-03-05 12:05:38,962 - util.py[DEBUG]: Attempting to load yaml from string of length 0 with allowed root types (<class 'dict'>,)
2019-03-05 12:05:38,962 - util.py[DEBUG]: loaded blob returned None, returning default.
2019-03-05 12:05:38,963 - util.py[DEBUG]: Reading from /var/lib/cloud/instance/cloud-config.txt (quiet=False)
2019-03-05 12:05:38,963 - util.py[DEBUG]: Read 363 bytes from /var/lib/cloud/instance/cloud-config.txt
2019-03-05 12:05:38,963 - util.py[DEBUG]: Attempting to load yaml from string of length 363 with allowed root types (<class 'dict'>,)
2019-03-05 12:05:38,966 - util.py[DEBUG]: Reading from /var/lib/cloud/instance/vendor-cloud-config.txt (quiet=False)
2019-03-05 12:05:38,966 - util.py[DEBUG]: Read 0 bytes from /var/lib/cloud/instance/vendor-cloud-config.txt
2019-03-05 12:05:38,966 - util.py[DEBUG]: Attempting to load yaml from string of length 0 with allowed root types (<class 'dict'>,)
2019-03-05 12:05:38,966 - util.py[DEBUG]: loaded blob returned None, returning default.
2019-03-05 12:05:38,967 - stages.py[DEBUG]: applying net config names for {'version': 1, 'config': [{'name': 'eth0', 'mtu': None, 'type': 'physical', 'subnets': [{'type': 'static', 'netmask': '255.255.255.192', 'routes': [{'network': '10.0.0.0', 'netmask': '255.0.0.0', 'gateway': '10.142.39.1'}, {'network': '161.26.0.0', 'netmask': '255.255.0.0', 'gateway': '10.142.39.1'}, {'network': '166.8.0.0', 'netmask': '255.252.0.0', 'gateway': '10.142.39.1'}], 'address': '10.142.39.35', 'ipv4': True}], 'mac_address': '06:fc:9a:55:bf:9e'}, {'name': 'eth1', 'mtu': None, 'type': 'physical', 'subnets': [{'type': 'static', 'netmask': '255.255.255.240', 'routes': [{'network': '0.0.0.0', 'netmask': '0.0.0.0', 'gateway': '169.55.47.145'}], 'address': '169.55.47.148', 'ipv4': True}], 'mac_address': '06:99:ac:66:4b:33'}, {'type': 'nameserver', 'address': '10.0.80.11'}, {'type': 'nameserver', 'address': '10.0.80.12'}]}
2019-03-05 12:05:38,968 - stages.py[DEBUG]: Using distro class <class 'cloudinit.distros.ubuntu.Distro'>
2019-03-05 12:05:38,969 - util.py[DEBUG]: Reading from /sys/class/net/eth0/device/device (quiet=False)
2019-03-05 12:05:38,969 - util.py[DEBUG]: Reading from /sys/class/net/eth1/device/device (quiet=False)
2019-03-05 12:05:38,969 - util.py[DEBUG]: Reading from /sys/class/net/eth1/addr_assign_type (quiet=False)
2019-03-05 12:05:38,969 - util.py[DEBUG]: Read 2 bytes from /sys/class/net/eth1/addr_assign_type
2019-03-05 12:05:38,969 - util.py[DEBUG]: Reading from /sys/class/net/eth1/uevent (quiet=False)
2019-03-05 12:05:38,969 - util.py[DEBUG]: Read 25 bytes from /sys/class/net/eth1/uevent
2019-03-05 12:05:38,969 - util.py[DEBUG]: Reading from /sys/class/net/eth1/address (quiet=False)
2019-03-05 12:05:38,969 - util.py[DEBUG]: Read 18 bytes from /sys/class/net/eth1/address
2019-03-05 12:05:38,970 - util.py[DEBUG]: Reading from /sys/class/net/eth1/device/device (quiet=False)
2019-03-05 12:05:38,970 - util.py[DEBUG]: Reading from /sys/class/net/lo/addr_assign_type (quiet=False)
2019-03-05 12:05:38,970 - util.py[DEBUG]: Read 2 bytes from /sys/class/net/lo/addr_assign_type
2019-03-05 12:05:38,970 - util.py[DEBUG]: Reading from /sys/class/net/lo/uevent (quiet=False)
2019-03-05 12:05:38,970 - util.py[DEBUG]: Read 23 bytes from /sys/class/net/lo/uevent
2019-03-05 12:05:38,970 - util.py[DEBUG]: Reading from /sys/class/net/lo/address (quiet=False)
2019-03-05 12:05:38,970 - util.py[DEBUG]: Read 18 bytes from /sys/class/net/lo/address
2019-03-05 12:05:38,970 - util.py[DEBUG]: Reading from /sys/class/net/lo/device/device (quiet=False)
2019-03-05 12:05:38,970 - util.py[DEBUG]: Reading from /sys/class/net/eth0/addr_assign_type (quiet=False)
2019-03-05 12:05:38,970 - util.py[DEBUG]: Read 2 bytes from /sys/class/net/eth0/addr_assign_type
2019-03-05 12:05:38,970 - util.py[DEBUG]: Reading from /sys/class/net/eth0/uevent (quiet=False)
2019-03-05 12:05:38,971 - util.py[DEBUG]: Read 25 bytes from /sys/class/net/eth0/uevent
2019-03-05 12:05:38,971 - util.py[DEBUG]: Reading from /sys/class/net/eth0/address (quiet=False)
2019-03-05 12:05:38,971 - util.py[DEBUG]: Read 18 bytes from /sys/class/net/eth0/address
2019-03-05 12:05:38,971 - util.py[DEBUG]: Reading from /sys/class/net/eth0/device/device (quiet=False)
2019-03-05 12:05:38,971 - util.py[DEBUG]: Reading from /sys/class/net/eth1/operstate (quiet=False)
2019-03-05 12:05:38,971 - util.py[DEBUG]: Read 3 bytes from /sys/class/net/eth1/operstate
2019-03-05 12:05:38,971 - util.py[DEBUG]: Reading from /sys/class/net/lo/operstate (quiet=False)
2019-03-05 12:05:38,971 - util.py[DEBUG]: Read 8 bytes from /sys/class/net/lo/operstate
2019-03-05 12:05:38,971 - util.py[DEBUG]: Reading from /sys/class/net/eth0/operstate (quiet=False)
2019-03-05 12:05:38,971 - util.py[DEBUG]: Read 3 bytes from /sys/class/net/eth0/operstate
2019-03-05 12:05:38,972 - util.py[DEBUG]: Running command ['ip', '-6', 'addr', 'show', 'permanent', 'scope', 'global'] with allowed return codes [0] (shell=False, capture=True)
2019-03-05 12:05:38,975 - util.py[DEBUG]: Running command ['ip', '-4', 'addr', 'show'] with allowed return codes [0] (shell=False, capture=True)
2019-03-05 12:05:38,978 - __init__.py[DEBUG]: no work necessary for renaming of [['06:fc:9a:55:bf:9e', 'eth0', 'vif', None], ['06:99:ac:66:4b:33', 'eth1', 'vif', None]]
2019-03-05 12:05:38,978 - __init__.py[DEBUG]: Datasource DataSourceIBMCloud [OS-Code/Live /dev/xvdh] not updated for events: System boot
2019-03-05 12:05:38,978 - stages.py[DEBUG]: No network config applied. Neither a new instance nor datasource network update on 'System boot' event
2019-03-05 12:05:38,979 - handlers.py[DEBUG]: start: init-network/setup-datasource: setting up datasource
2019-03-05 12:05:38,979 - handlers.py[DEBUG]: finish: init-network/setup-datasource: SUCCESS: setting up datasource
2019-03-05 12:05:38,979 - util.py[DEBUG]: Writing to /var/lib/cloud/instances/c24eca6d-063b-4de4-ab12-dcf37e5c0601/user-data.txt - wb: [600] 496 bytes
2019-03-05 12:05:38,982 - util.py[DEBUG]: Writing to /var/lib/cloud/instances/c24eca6d-063b-4de4-ab12-dcf37e5c0601/user-data.txt.i - wb: [600] 641 bytes
2019-03-05 12:05:38,983 - util.py[DEBUG]: Writing to /var/lib/cloud/instances/c24eca6d-063b-4de4-ab12-dcf37e5c0601/vendor-data.txt - wb: [600] 153 bytes
2019-03-05 12:05:38,984 - util.py[DEBUG]: Writing to /var/lib/cloud/instances/c24eca6d-063b-4de4-ab12-dcf37e5c0601/vendor-data.txt.i - wb: [600] 459 bytes
2019-03-05 12:05:38,985 - util.py[DEBUG]: Reading from /var/lib/cloud/data/set-hostname (quiet=False)
2019-03-05 12:05:38,985 - util.py[DEBUG]: Read 81 bytes from /var/lib/cloud/data/set-hostname
2019-03-05 12:05:38,985 - cc_set_hostname.py[DEBUG]: No hostname changes. Skipping set-hostname
2019-03-05 12:05:38,986 - helpers.py[DEBUG]: consume_data already ran (freq=once-per-instance)
2019-03-05 12:05:38,986 - handlers.py[DEBUG]: start: init-network/consume-user-data: reading and applying user-data
2019-03-05 12:05:38,987 - stages.py[DEBUG]: Added default handler for {'text/cloud-config', 'text/cloud-config-jsonp'} from CloudConfigPartHandler: [['text/cloud-config', 'text/cloud-config-jsonp']]
2019-03-05 12:05:38,987 - stages.py[DEBUG]: Added default handler for {'text/x-shellscript'} from ShellScriptPartHandler: [['text/x-shellscript']]
2019-03-05 12:05:38,987 - stages.py[DEBUG]: Added default handler for {'text/cloud-boothook'} from BootHookPartHandler: [['text/cloud-boothook']]
2019-03-05 12:05:38,988 - stages.py[DEBUG]: Added default handler for {'text/upstart-job'} from UpstartJobPartHandler: [['text/upstart-job']]
2019-03-05 12:05:38,988 - stages.py[DEBUG]: Added default handler for {'text/jinja2'} from JinjaTemplatePartHandler: [['text/jinja2']]
2019-03-05 12:05:38,988 - __init__.py[DEBUG]: Calling handler CloudConfigPartHandler: [['text/cloud-config', 'text/cloud-config-jsonp']] (__begin__, None, 3) with frequency always
2019-03-05 12:05:38,988 - __init__.py[DEBUG]: Calling handler ShellScriptPartHandler: [['text/x-shellscript']] (__begin__, None, 2) with frequency always
2019-03-05 12:05:38,988 - __init__.py[DEBUG]: Calling handler BootHookPartHandler: [['text/cloud-boothook']] (__begin__, None, 2) with frequency always
2019-03-05 12:05:38,988 - __init__.py[DEBUG]: Calling handler JinjaTemplatePartHandler: [['text/jinja2']] (__begin__, None, 3) with frequency always
2019-03-05 12:05:38,988 - __init__.py[DEBUG]: {'Content-Transfer-Encoding': '7bit', 'Mime-Version': '1.0', 'Content-Type': 'text/cloud-config', 'Content-Disposition': 'attachment; filename="part-001"'}
2019-03-05 12:05:38,988 - __init__.py[DEBUG]: Calling handler CloudConfigPartHandler: [['text/cloud-config', 'text/cloud-config-jsonp']] (text/cloud-config, part-001, 3) with frequency always
2019-03-05 12:05:38,988 - util.py[DEBUG]: Attempting to load yaml from string of length 304 with allowed root types (<class 'dict'>,)
2019-03-05 12:05:38,991 - cloud_config.py[DEBUG]: Merging by applying [('dict', ['replace']), ('list', []), ('str', [])]
2019-03-05 12:05:38,991 - __init__.py[DEBUG]: Calling handler CloudConfigPartHandler: [['text/cloud-config', 'text/cloud-config-jsonp']] (__end__, None, 3) with frequency always
2019-03-05 12:05:38,993 - util.py[DEBUG]: Writing to /var/lib/cloud/instances/c24eca6d-063b-4de4-ab12-dcf37e5c0601/cloud-config.txt - wb: [600] 363 bytes
2019-03-05 12:05:38,994 - __init__.py[DEBUG]: Calling handler ShellScriptPartHandler: [['text/x-shellscript']] (__end__, None, 2) with frequency always
2019-03-05 12:05:38,994 - __init__.py[DEBUG]: Calling handler BootHookPartHandler: [['text/cloud-boothook']] (__end__, None, 2) with frequency always
2019-03-05 12:05:38,994 - __init__.py[DEBUG]: Calling handler JinjaTemplatePartHandler: [['text/jinja2']] (__end__, None, 3) with frequency always
2019-03-05 12:05:38,995 - handlers.py[DEBUG]: finish: init-network/consume-user-data: SUCCESS: reading and applying user-data
2019-03-05 12:05:38,995 - handlers.py[DEBUG]: start: init-network/consume-vendor-data: reading and applying vendor-data
2019-03-05 12:05:38,995 - util.py[DEBUG]: Reading from /var/lib/cloud/instance/cloud-config.txt (quiet=False)
2019-03-05 12:05:38,995 - util.py[DEBUG]: Read 363 bytes from /var/lib/cloud/instance/cloud-config.txt
2019-03-05 12:05:38,995 - util.py[DEBUG]: Attempting to load yaml from string of length 363 with allowed root types (<class 'dict'>,)
2019-03-05 12:05:38,998 - stages.py[DEBUG]: vendor data will be consumed. disabled_handlers=None
2019-03-05 12:05:38,999 - stages.py[DEBUG]: Added default handler for {'text/cloud-config', 'text/cloud-config-jsonp'} from CloudConfigPartHandler: [['text/cloud-config', 'text/cloud-config-jsonp']]
2019-03-05 12:05:38,999 - stages.py[DEBUG]: Added default handler for {'text/x-shellscript'} from ShellScriptPartHandler: [['text/x-shellscript']]
2019-03-05 12:05:38,999 - stages.py[DEBUG]: Added default handler for {'text/cloud-boothook'} from BootHookPartHandler: [['text/cloud-boothook']]
2019-03-05 12:05:38,999 - stages.py[DEBUG]: Added default handler for {'text/upstart-job'} from UpstartJobPartHandler: [['text/upstart-job']]
2019-03-05 12:05:38,999 - stages.py[DEBUG]: Added default handler for {'text/jinja2'} from JinjaTemplatePartHandler: [['text/jinja2']]
2019-03-05 12:05:38,999 - __init__.py[DEBUG]: Calling handler CloudConfigPartHandler: [['text/cloud-config', 'text/cloud-config-jsonp']] (__begin__, None, 3) with frequency always
2019-03-05 12:05:38,999 - __init__.py[DEBUG]: Calling handler ShellScriptPartHandler: [['text/x-shellscript']] (__begin__, None, 2) with frequency always
2019-03-05 12:05:38,999 - __init__.py[DEBUG]: Calling handler BootHookPartHandler: [['text/cloud-boothook']] (__begin__, None, 2) with frequency always
2019-03-05 12:05:39,000 - __init__.py[DEBUG]: Calling handler JinjaTemplatePartHandler: [['text/jinja2']] (__begin__, None, 3) with frequency always
2019-03-05 12:05:39,000 - __init__.py[DEBUG]: {'MIME-Version': '1.0', 'Content-Type': 'text/x-shellscript', 'Content-Disposition': 'attachment; filename="part-001"'}
2019-03-05 12:05:39,000 - __init__.py[DEBUG]: Calling handler ShellScriptPartHandler: [['text/x-shellscript']] (text/x-shellscript, part-001, 2) with frequency always
2019-03-05 12:05:39,000 - util.py[DEBUG]: Writing to /var/lib/cloud/instance/scripts/vendor/part-001 - wb: [700] 153 bytes
2019-03-05 12:05:39,001 - __init__.py[DEBUG]: Calling handler CloudConfigPartHandler: [['text/cloud-config', 'text/cloud-config-jsonp']] (__end__, None, 3) with frequency always
2019-03-05 12:05:39,002 - util.py[DEBUG]: Writing to /var/lib/cloud/instances/c24eca6d-063b-4de4-ab12-dcf37e5c0601/vendor-cloud-config.txt - wb: [600] 0 bytes
2019-03-05 12:05:39,002 - __init__.py[DEBUG]: Calling handler ShellScriptPartHandler: [['text/x-shellscript']] (__end__, None, 2) with frequency always
2019-03-05 12:05:39,002 - __init__.py[DEBUG]: Calling handler BootHookPartHandler: [['text/cloud-boothook']] (__end__, None, 2) with frequency always
2019-03-05 12:05:39,002 - __init__.py[DEBUG]: Calling handler JinjaTemplatePartHandler: [['text/jinja2']] (__end__, None, 3) with frequency always
2019-03-05 12:05:39,002 - handlers.py[DEBUG]: finish: init-network/consume-vendor-data: SUCCESS: reading and applying vendor-data
2019-03-05 12:05:39,003 - util.py[DEBUG]: Reading from /etc/cloud/cloud.cfg (quiet=False)
2019-03-05 12:05:39,003 - util.py[DEBUG]: Read 3169 bytes from /etc/cloud/cloud.cfg
2019-03-05 12:05:39,003 - util.py[DEBUG]: Attempting to load yaml from string of length 3169 with allowed root types (<class 'dict'>,)
2019-03-05 12:05:39,017 - util.py[DEBUG]: Reading from /etc/cloud/cloud.cfg.d/99_networklayer_common.cfg (quiet=False)
2019-03-05 12:05:39,017 - util.py[DEBUG]: Read 989 bytes from /etc/cloud/cloud.cfg.d/99_networklayer_common.cfg
2019-03-05 12:05:39,017 - util.py[DEBUG]: Attempting to load yaml from string of length 989 with allowed root types (<class 'dict'>,)
2019-03-05 12:05:39,022 - util.py[DEBUG]: Reading from /etc/cloud/cloud.cfg.d/90_dpkg.cfg (quiet=False)
2019-03-05 12:05:39,022 - util.py[DEBUG]: Read 257 bytes from /etc/cloud/cloud.cfg.d/90_dpkg.cfg
2019-03-05 12:05:39,022 - util.py[DEBUG]: Attempting to load yaml from string of length 257 with allowed root types (<class 'dict'>,)
2019-03-05 12:05:39,024 - util.py[DEBUG]: Reading from /etc/cloud/cloud.cfg.d/05_logging.cfg (quiet=False)
2019-03-05 12:05:39,025 - util.py[DEBUG]: Read 2057 bytes from /etc/cloud/cloud.cfg.d/05_logging.cfg
2019-03-05 12:05:39,025 - util.py[DEBUG]: Attempting to load yaml from string of length 2057 with allowed root types (<class 'dict'>,)
2019-03-05 12:05:39,029 - util.py[DEBUG]: Reading from /run/cloud-init/cloud.cfg (quiet=False)
2019-03-05 12:05:39,029 - util.py[DEBUG]: Read 36 bytes from /run/cloud-init/cloud.cfg
2019-03-05 12:05:39,030 - util.py[DEBUG]: Attempting to load yaml from string of length 36 with allowed root types (<class 'dict'>,)
2019-03-05 12:05:39,030 - util.py[DEBUG]: Attempting to load yaml from string of length 0 with allowed root types (<class 'dict'>,)
2019-03-05 12:05:39,030 - util.py[DEBUG]: loaded blob returned None, returning default.
2019-03-05 12:05:39,031 - util.py[DEBUG]: Reading from /var/lib/cloud/instance/cloud-config.txt (quiet=False)
2019-03-05 12:05:39,031 - util.py[DEBUG]: Read 363 bytes from /var/lib/cloud/instance/cloud-config.txt
2019-03-05 12:05:39,031 - util.py[DEBUG]: Attempting to load yaml from string of length 363 with allowed root types (<class 'dict'>,)
2019-03-05 12:05:39,033 - util.py[DEBUG]: Reading from /var/lib/cloud/instance/vendor-cloud-config.txt (quiet=False)
2019-03-05 12:05:39,034 - util.py[DEBUG]: Read 0 bytes from /var/lib/cloud/instance/vendor-cloud-config.txt
2019-03-05 12:05:39,034 - util.py[DEBUG]: Attempting to load yaml from string of length 0 with allowed root types (<class 'dict'>,)
2019-03-05 12:05:39,034 - util.py[DEBUG]: loaded blob returned None, returning default.
2019-03-05 12:05:39,035 - util.py[DEBUG]: Reading from /var/lib/cloud/instance/cloud-config.txt (quiet=False)
2019-03-05 12:05:39,035 - util.py[DEBUG]: Read 363 bytes from /var/lib/cloud/instance/cloud-config.txt
2019-03-05 12:05:39,035 - util.py[DEBUG]: Attempting to load yaml from string of length 363 with allowed root types (<class 'dict'>,)
2019-03-05 12:05:39,038 - util.py[DEBUG]: Reading from /var/lib/cloud/instance/vendor-cloud-config.txt (quiet=False)
2019-03-05 12:05:39,038 - util.py[DEBUG]: Read 0 bytes from /var/lib/cloud/instance/vendor-cloud-config.txt
2019-03-05 12:05:39,038 - util.py[DEBUG]: Attempting to load yaml from string of length 0 with allowed root types (<class 'dict'>,)
2019-03-05 12:05:39,038 - util.py[DEBUG]: loaded blob returned None, returning default.
2019-03-05 12:05:39,047 - handlers.py[DEBUG]: start: init-network/activate-datasource: activating datasource
2019-03-05 12:05:39,048 - util.py[DEBUG]: Writing to /var/lib/cloud/instance/obj.pkl - wb: [400] 11730 bytes
2019-03-05 12:05:39,049 - handlers.py[DEBUG]: finish: init-network/activate-datasource: SUCCESS: activating datasource
2019-03-05 12:05:39,049 - main.py[DEBUG]: no di_report found in config.
2019-03-05 12:05:39,105 - stages.py[DEBUG]: Using distro class <class 'cloudinit.distros.ubuntu.Distro'>
2019-03-05 12:05:39,106 - stages.py[DEBUG]: Running module migrator (<module 'cloudinit.config.cc_migrator' from '/usr/lib/python3/dist-packages/cloudinit/config/cc_migrator.py'>) with frequency always
2019-03-05 12:05:39,106 - handlers.py[DEBUG]: start: init-network/config-migrator: running config-migrator with frequency always
2019-03-05 12:05:39,106 - helpers.py[DEBUG]: Running config-migrator using lock (<cloudinit.helpers.DummyLock object at 0x7f06b4489710>)
2019-03-05 12:05:39,121 - cc_migrator.py[DEBUG]: Migrated 0 semaphore files to there canonicalized names
2019-03-05 12:05:39,122 - handlers.py[DEBUG]: finish: init-network/config-migrator: SUCCESS: config-migrator ran successfully
2019-03-05 12:05:39,122 - stages.py[DEBUG]: Running module seed_random (<module 'cloudinit.config.cc_seed_random' from '/usr/lib/python3/dist-packages/cloudinit/config/cc_seed_random.py'>) with frequency once-per-instance
2019-03-05 12:05:39,122 - handlers.py[DEBUG]: start: init-network/config-seed_random: running config-seed_random with frequency once-per-instance
2019-03-05 12:05:39,122 - helpers.py[DEBUG]: config-seed_random already ran (freq=once-per-instance)
2019-03-05 12:05:39,122 - handlers.py[DEBUG]: finish: init-network/config-seed_random: SUCCESS: config-seed_random previously ran
2019-03-05 12:05:39,122 - stages.py[DEBUG]: Running module bootcmd (<module 'cloudinit.config.cc_bootcmd' from '/usr/lib/python3/dist-packages/cloudinit/config/cc_bootcmd.py'>) with frequency always
2019-03-05 12:05:39,123 - handlers.py[DEBUG]: start: init-network/config-bootcmd: running config-bootcmd with frequency always
2019-03-05 12:05:39,123 - helpers.py[DEBUG]: Running config-bootcmd using lock (<cloudinit.helpers.DummyLock object at 0x7f06b44895f8>)
2019-03-05 12:05:39,123 - cc_bootcmd.py[DEBUG]: Skipping module named bootcmd, no 'bootcmd' key in configuration
2019-03-05 12:05:39,123 - handlers.py[DEBUG]: finish: init-network/config-bootcmd: SUCCESS: config-bootcmd ran successfully
2019-03-05 12:05:39,123 - stages.py[DEBUG]: Running module write-files (<module 'cloudinit.config.cc_write_files' from '/usr/lib/python3/dist-packages/cloudinit/config/cc_write_files.py'>) with frequency once-per-instance
2019-03-05 12:05:39,123 - handlers.py[DEBUG]: start: init-network/config-write-files: running config-write-files with frequency once-per-instance
2019-03-05 12:05:39,123 - helpers.py[DEBUG]: config-write-files already ran (freq=once-per-instance)
2019-03-05 12:05:39,123 - handlers.py[DEBUG]: finish: init-network/config-write-files: SUCCESS: config-write-files previously ran
2019-03-05 12:05:39,123 - stages.py[DEBUG]: Running module growpart (<module 'cloudinit.config.cc_growpart' from '/usr/lib/python3/dist-packages/cloudinit/config/cc_growpart.py'>) with frequency always
2019-03-05 12:05:39,124 - handlers.py[DEBUG]: start: init-network/config-growpart: running config-growpart with frequency always
2019-03-05 12:05:39,124 - helpers.py[DEBUG]: Running config-growpart using lock (<cloudinit.helpers.DummyLock object at 0x7f06b44a07b8>)
2019-03-05 12:05:39,124 - cc_growpart.py[DEBUG]: No 'growpart' entry in cfg.  Using default: {'mode': 'auto', 'devices': ['/'], 'ignore_growroot_disabled': False}
2019-03-05 12:05:39,124 - util.py[DEBUG]: Running command ['growpart', '--help'] with allowed return codes [0] (shell=False, capture=True)
2019-03-05 12:05:39,136 - util.py[DEBUG]: Reading from /proc/594/mountinfo (quiet=False)
2019-03-05 12:05:39,137 - util.py[DEBUG]: Read 3077 bytes from /proc/594/mountinfo
2019-03-05 12:05:39,137 - util.py[DEBUG]: Running command ['systemd-detect-virt', '--quiet', '--container'] with allowed return codes [0] (shell=False, capture=True)
2019-03-05 12:05:39,146 - util.py[DEBUG]: Running command ['running-in-container'] with allowed return codes [0] (shell=False, capture=True)
2019-03-05 12:05:39,155 - util.py[DEBUG]: Running command ['lxc-is-container'] with allowed return codes [0] (shell=False, capture=True)
2019-03-05 12:05:39,157 - util.py[DEBUG]: Reading from /proc/1/environ (quiet=False)
2019-03-05 12:05:39,157 - util.py[DEBUG]: Read 67 bytes from /proc/1/environ
2019-03-05 12:05:39,158 - util.py[DEBUG]: Reading from /proc/self/status (quiet=False)
2019-03-05 12:05:39,158 - util.py[DEBUG]: Read 1297 bytes from /proc/self/status
2019-03-05 12:05:39,159 - util.py[DEBUG]: Reading from /etc/os-release (quiet=False)
2019-03-05 12:05:39,159 - util.py[DEBUG]: Read 386 bytes from /etc/os-release
2019-03-05 12:05:39,160 - util.py[DEBUG]: Reading from /sys/class/block/xvda2/partition (quiet=False)
2019-03-05 12:05:39,160 - util.py[DEBUG]: Read 2 bytes from /sys/class/block/xvda2/partition
2019-03-05 12:05:39,160 - util.py[DEBUG]: Reading from /sys/devices/vbd-768/block/xvda/dev (quiet=False)
2019-03-05 12:05:39,160 - util.py[DEBUG]: Read 6 bytes from /sys/devices/vbd-768/block/xvda/dev
2019-03-05 12:05:39,160 - util.py[DEBUG]: Running command ['growpart', '--dry-run', '/dev/xvda', '2'] with allowed return codes [0] (shell=False, capture=True)
2019-03-05 12:05:39,247 - util.py[DEBUG]: resize_devices took 0.110 seconds
2019-03-05 12:05:39,247 - cc_growpart.py[DEBUG]: '/' NOCHANGE: no change necessary (/dev/xvda, 2)
2019-03-05 12:05:39,247 - handlers.py[DEBUG]: finish: init-network/config-growpart: SUCCESS: config-growpart ran successfully
2019-03-05 12:05:39,247 - stages.py[DEBUG]: Running module resizefs (<module 'cloudinit.config.cc_resizefs' from '/usr/lib/python3/dist-packages/cloudinit/config/cc_resizefs.py'>) with frequency always
2019-03-05 12:05:39,248 - handlers.py[DEBUG]: start: init-network/config-resizefs: running config-resizefs with frequency always
2019-03-05 12:05:39,248 - helpers.py[DEBUG]: Running config-resizefs using lock (<cloudinit.helpers.DummyLock object at 0x7f06b44a0e80>)
2019-03-05 12:05:39,285 - util.py[DEBUG]: Reading from /proc/594/mountinfo (quiet=False)
2019-03-05 12:05:39,285 - util.py[DEBUG]: Read 3077 bytes from /proc/594/mountinfo
2019-03-05 12:05:39,285 - cc_resizefs.py[DEBUG]: resize_info: dev=/dev/root mnt_point=/ path=/
2019-03-05 12:05:39,285 - util.py[DEBUG]: Running command ['systemd-detect-virt', '--quiet', '--container'] with allowed return codes [0] (shell=False, capture=True)
2019-03-05 12:05:39,297 - util.py[DEBUG]: Running command ['running-in-container'] with allowed return codes [0] (shell=False, capture=True)
2019-03-05 12:05:39,299 - util.py[DEBUG]: Running command ['lxc-is-container'] with allowed return codes [0] (shell=False, capture=True)
2019-03-05 12:05:39,301 - util.py[DEBUG]: Reading from /proc/1/environ (quiet=False)
2019-03-05 12:05:39,301 - util.py[DEBUG]: Read 67 bytes from /proc/1/environ
2019-03-05 12:05:39,301 - util.py[DEBUG]: Reading from /proc/self/status (quiet=False)
2019-03-05 12:05:39,301 - util.py[DEBUG]: Read 1297 bytes from /proc/self/status
2019-03-05 12:05:39,301 - cc_resizefs.py[DEBUG]: Resizing / (ext4) using resize2fs /dev/root
2019-03-05 12:05:39,301 - util.py[DEBUG]: Running command ('resize2fs', '/dev/root') with allowed return codes [0] (shell=False, capture=True)
2019-03-05 12:05:39,318 - util.py[DEBUG]: Resizing took 0.017 seconds
2019-03-05 12:05:39,319 - cc_resizefs.py[DEBUG]: Resized root filesystem (type=ext4, val=True)
2019-03-05 12:05:39,319 - handlers.py[DEBUG]: finish: init-network/config-resizefs: SUCCESS: config-resizefs ran successfully
2019-03-05 12:05:39,319 - stages.py[DEBUG]: Running module disk_setup (<module 'cloudinit.config.cc_disk_setup' from '/usr/lib/python3/dist-packages/cloudinit/config/cc_disk_setup.py'>) with frequency once-per-instance
2019-03-05 12:05:39,319 - handlers.py[DEBUG]: start: init-network/config-disk_setup: running config-disk_setup with frequency once-per-instance
2019-03-05 12:05:39,320 - helpers.py[DEBUG]: config-disk_setup already ran (freq=once-per-instance)
2019-03-05 12:05:39,320 - handlers.py[DEBUG]: finish: init-network/config-disk_setup: SUCCESS: config-disk_setup previously ran
2019-03-05 12:05:39,320 - stages.py[DEBUG]: Running module mounts (<module 'cloudinit.config.cc_mounts' from '/usr/lib/python3/dist-packages/cloudinit/config/cc_mounts.py'>) with frequency once-per-instance
2019-03-05 12:05:39,320 - handlers.py[DEBUG]: start: init-network/config-mounts: running config-mounts with frequency once-per-instance
2019-03-05 12:05:39,320 - helpers.py[DEBUG]: config-mounts already ran (freq=once-per-instance)
2019-03-05 12:05:39,320 - handlers.py[DEBUG]: finish: init-network/config-mounts: SUCCESS: config-mounts previously ran
2019-03-05 12:05:39,320 - stages.py[DEBUG]: Running module set_hostname (<module 'cloudinit.config.cc_set_hostname' from '/usr/lib/python3/dist-packages/cloudinit/config/cc_set_hostname.py'>) with frequency once-per-instance
2019-03-05 12:05:39,321 - handlers.py[DEBUG]: start: init-network/config-set_hostname: running config-set_hostname with frequency once-per-instance
2019-03-05 12:05:39,321 - helpers.py[DEBUG]: config-set_hostname already ran (freq=once-per-instance)
2019-03-05 12:05:39,321 - handlers.py[DEBUG]: finish: init-network/config-set_hostname: SUCCESS: config-set_hostname previously ran
2019-03-05 12:05:39,321 - stages.py[DEBUG]: Running module update_hostname (<module 'cloudinit.config.cc_update_hostname' from '/usr/lib/python3/dist-packages/cloudinit/config/cc_update_hostname.py'>) with frequency always
2019-03-05 12:05:39,321 - handlers.py[DEBUG]: start: init-network/config-update_hostname: running config-update_hostname with frequency always
2019-03-05 12:05:39,321 - helpers.py[DEBUG]: Running config-update_hostname using lock (<cloudinit.helpers.DummyLock object at 0x7f06b441b588>)
2019-03-05 12:05:39,321 - cc_update_hostname.py[DEBUG]: Updating hostname to csc-vm-YOURINITIALS.ibm.cloud (csc-vm-YOURINITIALS)
2019-03-05 12:05:39,321 - util.py[DEBUG]: Reading from /var/lib/cloud/data/previous-hostname (quiet=False)
2019-03-05 12:05:39,329 - util.py[DEBUG]: Read 20 bytes from /var/lib/cloud/data/previous-hostname
2019-03-05 12:05:39,329 - util.py[DEBUG]: Reading from /etc/hostname (quiet=False)
2019-03-05 12:05:39,330 - util.py[DEBUG]: Read 20 bytes from /etc/hostname
2019-03-05 12:05:39,330 - __init__.py[DEBUG]: Attempting to update hostname to csc-vm-YOURINITIALS in 0 files
2019-03-05 12:05:39,330 - handlers.py[DEBUG]: finish: init-network/config-update_hostname: SUCCESS: config-update_hostname ran successfully
2019-03-05 12:05:39,330 - stages.py[DEBUG]: Running module update_etc_hosts (<module 'cloudinit.config.cc_update_etc_hosts' from '/usr/lib/python3/dist-packages/cloudinit/config/cc_update_etc_hosts.py'>) with frequency always
2019-03-05 12:05:39,330 - handlers.py[DEBUG]: start: init-network/config-update_etc_hosts: running config-update_etc_hosts with frequency always
2019-03-05 12:05:39,330 - helpers.py[DEBUG]: Running config-update_etc_hosts using lock (<cloudinit.helpers.DummyLock object at 0x7f06b441b2e8>)
2019-03-05 12:05:39,330 - cc_update_etc_hosts.py[DEBUG]: Managing localhost in /etc/hosts
2019-03-05 12:05:39,330 - util.py[DEBUG]: Reading from /etc/hosts (quiet=False)
2019-03-05 12:05:39,331 - util.py[DEBUG]: Read 282 bytes from /etc/hosts
2019-03-05 12:05:39,331 - handlers.py[DEBUG]: finish: init-network/config-update_etc_hosts: SUCCESS: config-update_etc_hosts ran successfully
2019-03-05 12:05:39,331 - stages.py[DEBUG]: Running module ca-certs (<module 'cloudinit.config.cc_ca_certs' from '/usr/lib/python3/dist-packages/cloudinit/config/cc_ca_certs.py'>) with frequency once-per-instance
2019-03-05 12:05:39,331 - handlers.py[DEBUG]: start: init-network/config-ca-certs: running config-ca-certs with frequency once-per-instance
2019-03-05 12:05:39,331 - helpers.py[DEBUG]: config-ca-certs already ran (freq=once-per-instance)
2019-03-05 12:05:39,331 - handlers.py[DEBUG]: finish: init-network/config-ca-certs: SUCCESS: config-ca-certs previously ran
2019-03-05 12:05:39,331 - stages.py[DEBUG]: Running module rsyslog (<module 'cloudinit.config.cc_rsyslog' from '/usr/lib/python3/dist-packages/cloudinit/config/cc_rsyslog.py'>) with frequency once-per-instance
2019-03-05 12:05:39,332 - handlers.py[DEBUG]: start: init-network/config-rsyslog: running config-rsyslog with frequency once-per-instance
2019-03-05 12:05:39,332 - helpers.py[DEBUG]: config-rsyslog already ran (freq=once-per-instance)
2019-03-05 12:05:39,332 - handlers.py[DEBUG]: finish: init-network/config-rsyslog: SUCCESS: config-rsyslog previously ran
2019-03-05 12:05:39,332 - stages.py[DEBUG]: Running module users-groups (<module 'cloudinit.config.cc_users_groups' from '/usr/lib/python3/dist-packages/cloudinit/config/cc_users_groups.py'>) with frequency once-per-instance
2019-03-05 12:05:39,332 - handlers.py[DEBUG]: start: init-network/config-users-groups: running config-users-groups with frequency once-per-instance
2019-03-05 12:05:39,332 - helpers.py[DEBUG]: config-users-groups already ran (freq=once-per-instance)
2019-03-05 12:05:39,332 - handlers.py[DEBUG]: finish: init-network/config-users-groups: SUCCESS: config-users-groups previously ran
2019-03-05 12:05:39,332 - stages.py[DEBUG]: Running module ssh (<module 'cloudinit.config.cc_ssh' from '/usr/lib/python3/dist-packages/cloudinit/config/cc_ssh.py'>) with frequency once-per-instance
2019-03-05 12:05:39,333 - handlers.py[DEBUG]: start: init-network/config-ssh: running config-ssh with frequency once-per-instance
2019-03-05 12:05:39,333 - helpers.py[DEBUG]: config-ssh already ran (freq=once-per-instance)
2019-03-05 12:05:39,333 - handlers.py[DEBUG]: finish: init-network/config-ssh: SUCCESS: config-ssh previously ran
2019-03-05 12:05:39,333 - main.py[DEBUG]: Ran 15 modules with 0 failures
2019-03-05 12:05:39,334 - util.py[DEBUG]: Reading from /proc/uptime (quiet=False)
2019-03-05 12:05:39,334 - util.py[DEBUG]: Read 11 bytes from /proc/uptime
2019-03-05 12:05:39,334 - util.py[DEBUG]: cloud-init mode 'init' took 0.526 seconds (0.53)
2019-03-05 12:05:39,334 - handlers.py[DEBUG]: finish: init-network: SUCCESS: searching for network datasources
2019-03-05 12:05:41,792 - util.py[DEBUG]: Cloud-init v. 18.4-0ubuntu1~18.04.1 running 'modules:config' at Tue, 05 Mar 2019 12:05:41 +0000. Up 16.32 seconds.
2019-03-05 12:05:41,819 - stages.py[DEBUG]: Using distro class <class 'cloudinit.distros.ubuntu.Distro'>
2019-03-05 12:05:41,820 - stages.py[DEBUG]: Running module emit_upstart (<module 'cloudinit.config.cc_emit_upstart' from '/usr/lib/python3/dist-packages/cloudinit/config/cc_emit_upstart.py'>) with frequency always
2019-03-05 12:05:41,820 - handlers.py[DEBUG]: start: modules-config/config-emit_upstart: running config-emit_upstart with frequency always
2019-03-05 12:05:41,820 - helpers.py[DEBUG]: Running config-emit_upstart using lock (<cloudinit.helpers.DummyLock object at 0x7fea0d8fb240>)
2019-03-05 12:05:41,820 - cc_emit_upstart.py[DEBUG]: no /sbin/initctl located
2019-03-05 12:05:41,820 - cc_emit_upstart.py[DEBUG]: not upstart system, 'emit_upstart' disabled
2019-03-05 12:05:41,820 - handlers.py[DEBUG]: finish: modules-config/config-emit_upstart: SUCCESS: config-emit_upstart ran successfully
2019-03-05 12:05:41,821 - stages.py[DEBUG]: Running module snap (<module 'cloudinit.config.cc_snap' from '/usr/lib/python3/dist-packages/cloudinit/config/cc_snap.py'>) with frequency once-per-instance
2019-03-05 12:05:41,821 - handlers.py[DEBUG]: start: modules-config/config-snap: running config-snap with frequency once-per-instance
2019-03-05 12:05:41,821 - helpers.py[DEBUG]: config-snap already ran (freq=once-per-instance)
2019-03-05 12:05:41,821 - handlers.py[DEBUG]: finish: modules-config/config-snap: SUCCESS: config-snap previously ran
2019-03-05 12:05:41,821 - stages.py[DEBUG]: Running module snap_config (<module 'cloudinit.config.cc_snap_config' from '/usr/lib/python3/dist-packages/cloudinit/config/cc_snap_config.py'>) with frequency once-per-instance
2019-03-05 12:05:41,821 - handlers.py[DEBUG]: start: modules-config/config-snap_config: running config-snap_config with frequency once-per-instance
2019-03-05 12:05:41,822 - helpers.py[DEBUG]: config-snap_config already ran (freq=once-per-instance)
2019-03-05 12:05:41,822 - handlers.py[DEBUG]: finish: modules-config/config-snap_config: SUCCESS: config-snap_config previously ran
2019-03-05 12:05:41,822 - stages.py[DEBUG]: Running module ssh-import-id (<module 'cloudinit.config.cc_ssh_import_id' from '/usr/lib/python3/dist-packages/cloudinit/config/cc_ssh_import_id.py'>) with frequency once-per-instance
2019-03-05 12:05:41,822 - handlers.py[DEBUG]: start: modules-config/config-ssh-import-id: running config-ssh-import-id with frequency once-per-instance
2019-03-05 12:05:41,822 - helpers.py[DEBUG]: config-ssh-import-id already ran (freq=once-per-instance)
2019-03-05 12:05:41,822 - handlers.py[DEBUG]: finish: modules-config/config-ssh-import-id: SUCCESS: config-ssh-import-id previously ran
2019-03-05 12:05:41,822 - stages.py[DEBUG]: Running module locale (<module 'cloudinit.config.cc_locale' from '/usr/lib/python3/dist-packages/cloudinit/config/cc_locale.py'>) with frequency once-per-instance
2019-03-05 12:05:41,823 - handlers.py[DEBUG]: start: modules-config/config-locale: running config-locale with frequency once-per-instance
2019-03-05 12:05:41,823 - helpers.py[DEBUG]: config-locale already ran (freq=once-per-instance)
2019-03-05 12:05:41,823 - handlers.py[DEBUG]: finish: modules-config/config-locale: SUCCESS: config-locale previously ran
2019-03-05 12:05:41,823 - stages.py[DEBUG]: Running module set-passwords (<module 'cloudinit.config.cc_set_passwords' from '/usr/lib/python3/dist-packages/cloudinit/config/cc_set_passwords.py'>) with frequency once-per-instance
2019-03-05 12:05:41,823 - handlers.py[DEBUG]: start: modules-config/config-set-passwords: running config-set-passwords with frequency once-per-instance
2019-03-05 12:05:41,823 - helpers.py[DEBUG]: config-set-passwords already ran (freq=once-per-instance)
2019-03-05 12:05:41,823 - handlers.py[DEBUG]: finish: modules-config/config-set-passwords: SUCCESS: config-set-passwords previously ran
2019-03-05 12:05:41,823 - stages.py[DEBUG]: Running module grub-dpkg (<module 'cloudinit.config.cc_grub_dpkg' from '/usr/lib/python3/dist-packages/cloudinit/config/cc_grub_dpkg.py'>) with frequency once-per-instance
2019-03-05 12:05:41,824 - handlers.py[DEBUG]: start: modules-config/config-grub-dpkg: running config-grub-dpkg with frequency once-per-instance
2019-03-05 12:05:41,824 - helpers.py[DEBUG]: config-grub-dpkg already ran (freq=once-per-instance)
2019-03-05 12:05:41,824 - handlers.py[DEBUG]: finish: modules-config/config-grub-dpkg: SUCCESS: config-grub-dpkg previously ran
2019-03-05 12:05:41,824 - stages.py[DEBUG]: Running module apt-pipelining (<module 'cloudinit.config.cc_apt_pipelining' from '/usr/lib/python3/dist-packages/cloudinit/config/cc_apt_pipelining.py'>) with frequency once-per-instance
2019-03-05 12:05:41,824 - handlers.py[DEBUG]: start: modules-config/config-apt-pipelining: running config-apt-pipelining with frequency once-per-instance
2019-03-05 12:05:41,824 - helpers.py[DEBUG]: config-apt-pipelining already ran (freq=once-per-instance)
2019-03-05 12:05:41,824 - handlers.py[DEBUG]: finish: modules-config/config-apt-pipelining: SUCCESS: config-apt-pipelining previously ran
2019-03-05 12:05:41,824 - stages.py[DEBUG]: Running module apt-configure (<module 'cloudinit.config.cc_apt_configure' from '/usr/lib/python3/dist-packages/cloudinit/config/cc_apt_configure.py'>) with frequency once-per-instance
2019-03-05 12:05:41,825 - handlers.py[DEBUG]: start: modules-config/config-apt-configure: running config-apt-configure with frequency once-per-instance
2019-03-05 12:05:41,825 - helpers.py[DEBUG]: config-apt-configure already ran (freq=once-per-instance)
2019-03-05 12:05:41,825 - handlers.py[DEBUG]: finish: modules-config/config-apt-configure: SUCCESS: config-apt-configure previously ran
2019-03-05 12:05:41,825 - stages.py[DEBUG]: Running module ubuntu-advantage (<module 'cloudinit.config.cc_ubuntu_advantage' from '/usr/lib/python3/dist-packages/cloudinit/config/cc_ubuntu_advantage.py'>) with frequency once-per-instance
2019-03-05 12:05:41,825 - handlers.py[DEBUG]: start: modules-config/config-ubuntu-advantage: running config-ubuntu-advantage with frequency once-per-instance
2019-03-05 12:05:41,825 - helpers.py[DEBUG]: config-ubuntu-advantage already ran (freq=once-per-instance)
2019-03-05 12:05:41,825 - handlers.py[DEBUG]: finish: modules-config/config-ubuntu-advantage: SUCCESS: config-ubuntu-advantage previously ran
2019-03-05 12:05:41,826 - stages.py[DEBUG]: Running module ntp (<module 'cloudinit.config.cc_ntp' from '/usr/lib/python3/dist-packages/cloudinit/config/cc_ntp.py'>) with frequency once-per-instance
2019-03-05 12:05:41,826 - handlers.py[DEBUG]: start: modules-config/config-ntp: running config-ntp with frequency once-per-instance
2019-03-05 12:05:41,826 - helpers.py[DEBUG]: config-ntp already ran (freq=once-per-instance)
2019-03-05 12:05:41,826 - handlers.py[DEBUG]: finish: modules-config/config-ntp: SUCCESS: config-ntp previously ran
2019-03-05 12:05:41,826 - stages.py[DEBUG]: Running module timezone (<module 'cloudinit.config.cc_timezone' from '/usr/lib/python3/dist-packages/cloudinit/config/cc_timezone.py'>) with frequency once-per-instance
2019-03-05 12:05:41,826 - handlers.py[DEBUG]: start: modules-config/config-timezone: running config-timezone with frequency once-per-instance
2019-03-05 12:05:41,827 - helpers.py[DEBUG]: config-timezone already ran (freq=once-per-instance)
2019-03-05 12:05:41,827 - handlers.py[DEBUG]: finish: modules-config/config-timezone: SUCCESS: config-timezone previously ran
2019-03-05 12:05:41,827 - stages.py[DEBUG]: Running module disable-ec2-metadata (<module 'cloudinit.config.cc_disable_ec2_metadata' from '/usr/lib/python3/dist-packages/cloudinit/config/cc_disable_ec2_metadata.py'>) with frequency always
2019-03-05 12:05:41,827 - handlers.py[DEBUG]: start: modules-config/config-disable-ec2-metadata: running config-disable-ec2-metadata with frequency always
2019-03-05 12:05:41,827 - helpers.py[DEBUG]: Running config-disable-ec2-metadata using lock (<cloudinit.helpers.DummyLock object at 0x7fea0d8a5160>)
2019-03-05 12:05:41,827 - cc_disable_ec2_metadata.py[DEBUG]: Skipping module named disable-ec2-metadata, disabling the ec2 route not enabled
2019-03-05 12:05:41,827 - handlers.py[DEBUG]: finish: modules-config/config-disable-ec2-metadata: SUCCESS: config-disable-ec2-metadata ran successfully
2019-03-05 12:05:41,827 - stages.py[DEBUG]: Running module runcmd (<module 'cloudinit.config.cc_runcmd' from '/usr/lib/python3/dist-packages/cloudinit/config/cc_runcmd.py'>) with frequency once-per-instance
2019-03-05 12:05:41,828 - handlers.py[DEBUG]: start: modules-config/config-runcmd: running config-runcmd with frequency once-per-instance
2019-03-05 12:05:41,828 - helpers.py[DEBUG]: config-runcmd already ran (freq=once-per-instance)
2019-03-05 12:05:41,828 - handlers.py[DEBUG]: finish: modules-config/config-runcmd: SUCCESS: config-runcmd previously ran
2019-03-05 12:05:41,828 - stages.py[DEBUG]: Running module byobu (<module 'cloudinit.config.cc_byobu' from '/usr/lib/python3/dist-packages/cloudinit/config/cc_byobu.py'>) with frequency once-per-instance
2019-03-05 12:05:41,828 - handlers.py[DEBUG]: start: modules-config/config-byobu: running config-byobu with frequency once-per-instance
2019-03-05 12:05:41,828 - helpers.py[DEBUG]: config-byobu already ran (freq=once-per-instance)
2019-03-05 12:05:41,828 - handlers.py[DEBUG]: finish: modules-config/config-byobu: SUCCESS: config-byobu previously ran
2019-03-05 12:05:41,828 - main.py[DEBUG]: Ran 15 modules with 0 failures
2019-03-05 12:05:41,829 - util.py[DEBUG]: Reading from /proc/uptime (quiet=False)
2019-03-05 12:05:41,829 - util.py[DEBUG]: Read 11 bytes from /proc/uptime
2019-03-05 12:05:41,830 - util.py[DEBUG]: cloud-init mode 'modules' took 0.151 seconds (0.15)
2019-03-05 12:05:41,830 - handlers.py[DEBUG]: finish: modules-config: SUCCESS: running modules for config
2019-03-05 12:05:42,526 - util.py[DEBUG]: Cloud-init v. 18.4-0ubuntu1~18.04.1 running 'modules:final' at Tue, 05 Mar 2019 12:05:42 +0000. Up 17.07 seconds.
2019-03-05 12:05:42,552 - stages.py[DEBUG]: Using distro class <class 'cloudinit.distros.ubuntu.Distro'>
2019-03-05 12:05:42,553 - stages.py[DEBUG]: Running module snappy (<module 'cloudinit.config.cc_snappy' from '/usr/lib/python3/dist-packages/cloudinit/config/cc_snappy.py'>) with frequency once-per-instance
2019-03-05 12:05:42,553 - handlers.py[DEBUG]: start: modules-final/config-snappy: running config-snappy with frequency once-per-instance
2019-03-05 12:05:42,554 - helpers.py[DEBUG]: config-snappy already ran (freq=once-per-instance)
2019-03-05 12:05:42,554 - handlers.py[DEBUG]: finish: modules-final/config-snappy: SUCCESS: config-snappy previously ran
2019-03-05 12:05:42,554 - stages.py[DEBUG]: Running module package-update-upgrade-install (<module 'cloudinit.config.cc_package_update_upgrade_install' from '/usr/lib/python3/dist-packages/cloudinit/config/cc_package_update_upgrade_install.py'>) with frequency once-per-instance
2019-03-05 12:05:42,554 - handlers.py[DEBUG]: start: modules-final/config-package-update-upgrade-install: running config-package-update-upgrade-install with frequency once-per-instance
2019-03-05 12:05:42,554 - helpers.py[DEBUG]: config-package-update-upgrade-install already ran (freq=once-per-instance)
2019-03-05 12:05:42,554 - handlers.py[DEBUG]: finish: modules-final/config-package-update-upgrade-install: SUCCESS: config-package-update-upgrade-install previously ran
2019-03-05 12:05:42,554 - stages.py[DEBUG]: Running module fan (<module 'cloudinit.config.cc_fan' from '/usr/lib/python3/dist-packages/cloudinit/config/cc_fan.py'>) with frequency once-per-instance
2019-03-05 12:05:42,555 - handlers.py[DEBUG]: start: modules-final/config-fan: running config-fan with frequency once-per-instance
2019-03-05 12:05:42,555 - helpers.py[DEBUG]: config-fan already ran (freq=once-per-instance)
2019-03-05 12:05:42,555 - handlers.py[DEBUG]: finish: modules-final/config-fan: SUCCESS: config-fan previously ran
2019-03-05 12:05:42,555 - stages.py[DEBUG]: Running module landscape (<module 'cloudinit.config.cc_landscape' from '/usr/lib/python3/dist-packages/cloudinit/config/cc_landscape.py'>) with frequency once-per-instance
2019-03-05 12:05:42,555 - handlers.py[DEBUG]: start: modules-final/config-landscape: running config-landscape with frequency once-per-instance
2019-03-05 12:05:42,555 - helpers.py[DEBUG]: config-landscape already ran (freq=once-per-instance)
2019-03-05 12:05:42,555 - handlers.py[DEBUG]: finish: modules-final/config-landscape: SUCCESS: config-landscape previously ran
2019-03-05 12:05:42,555 - stages.py[DEBUG]: Running module lxd (<module 'cloudinit.config.cc_lxd' from '/usr/lib/python3/dist-packages/cloudinit/config/cc_lxd.py'>) with frequency once-per-instance
2019-03-05 12:05:42,556 - handlers.py[DEBUG]: start: modules-final/config-lxd: running config-lxd with frequency once-per-instance
2019-03-05 12:05:42,556 - helpers.py[DEBUG]: config-lxd already ran (freq=once-per-instance)
2019-03-05 12:05:42,556 - handlers.py[DEBUG]: finish: modules-final/config-lxd: SUCCESS: config-lxd previously ran
2019-03-05 12:05:42,556 - stages.py[DEBUG]: Running module puppet (<module 'cloudinit.config.cc_puppet' from '/usr/lib/python3/dist-packages/cloudinit/config/cc_puppet.py'>) with frequency once-per-instance
2019-03-05 12:05:42,556 - handlers.py[DEBUG]: start: modules-final/config-puppet: running config-puppet with frequency once-per-instance
2019-03-05 12:05:42,556 - helpers.py[DEBUG]: config-puppet already ran (freq=once-per-instance)
2019-03-05 12:05:42,556 - handlers.py[DEBUG]: finish: modules-final/config-puppet: SUCCESS: config-puppet previously ran
2019-03-05 12:05:42,556 - stages.py[DEBUG]: Running module chef (<module 'cloudinit.config.cc_chef' from '/usr/lib/python3/dist-packages/cloudinit/config/cc_chef.py'>) with frequency once-per-instance
2019-03-05 12:05:42,557 - handlers.py[DEBUG]: start: modules-final/config-chef: running config-chef with frequency once-per-instance
2019-03-05 12:05:42,557 - helpers.py[DEBUG]: config-chef already ran (freq=once-per-instance)
2019-03-05 12:05:42,557 - handlers.py[DEBUG]: finish: modules-final/config-chef: SUCCESS: config-chef previously ran
2019-03-05 12:05:42,557 - stages.py[DEBUG]: Running module mcollective (<module 'cloudinit.config.cc_mcollective' from '/usr/lib/python3/dist-packages/cloudinit/config/cc_mcollective.py'>) with frequency once-per-instance
2019-03-05 12:05:42,557 - handlers.py[DEBUG]: start: modules-final/config-mcollective: running config-mcollective with frequency once-per-instance
2019-03-05 12:05:42,557 - helpers.py[DEBUG]: config-mcollective already ran (freq=once-per-instance)
2019-03-05 12:05:42,557 - handlers.py[DEBUG]: finish: modules-final/config-mcollective: SUCCESS: config-mcollective previously ran
2019-03-05 12:05:42,557 - stages.py[DEBUG]: Running module salt-minion (<module 'cloudinit.config.cc_salt_minion' from '/usr/lib/python3/dist-packages/cloudinit/config/cc_salt_minion.py'>) with frequency once-per-instance
2019-03-05 12:05:42,558 - handlers.py[DEBUG]: start: modules-final/config-salt-minion: running config-salt-minion with frequency once-per-instance
2019-03-05 12:05:42,558 - helpers.py[DEBUG]: config-salt-minion already ran (freq=once-per-instance)
2019-03-05 12:05:42,558 - handlers.py[DEBUG]: finish: modules-final/config-salt-minion: SUCCESS: config-salt-minion previously ran
2019-03-05 12:05:42,558 - stages.py[DEBUG]: Running module rightscale_userdata (<module 'cloudinit.config.cc_rightscale_userdata' from '/usr/lib/python3/dist-packages/cloudinit/config/cc_rightscale_userdata.py'>) with frequency once-per-instance
2019-03-05 12:05:42,558 - handlers.py[DEBUG]: start: modules-final/config-rightscale_userdata: running config-rightscale_userdata with frequency once-per-instance
2019-03-05 12:05:42,558 - helpers.py[DEBUG]: config-rightscale_userdata already ran (freq=once-per-instance)
2019-03-05 12:05:42,558 - handlers.py[DEBUG]: finish: modules-final/config-rightscale_userdata: SUCCESS: config-rightscale_userdata previously ran
2019-03-05 12:05:42,558 - stages.py[DEBUG]: Running module scripts-vendor (<module 'cloudinit.config.cc_scripts_vendor' from '/usr/lib/python3/dist-packages/cloudinit/config/cc_scripts_vendor.py'>) with frequency once-per-instance
2019-03-05 12:05:42,559 - handlers.py[DEBUG]: start: modules-final/config-scripts-vendor: running config-scripts-vendor with frequency once-per-instance
2019-03-05 12:05:42,559 - helpers.py[DEBUG]: config-scripts-vendor already ran (freq=once-per-instance)
2019-03-05 12:05:42,559 - handlers.py[DEBUG]: finish: modules-final/config-scripts-vendor: SUCCESS: config-scripts-vendor previously ran
2019-03-05 12:05:42,559 - stages.py[DEBUG]: Running module scripts-per-once (<module 'cloudinit.config.cc_scripts_per_once' from '/usr/lib/python3/dist-packages/cloudinit/config/cc_scripts_per_once.py'>) with frequency once
2019-03-05 12:05:42,559 - handlers.py[DEBUG]: start: modules-final/config-scripts-per-once: running config-scripts-per-once with frequency once
2019-03-05 12:05:42,559 - helpers.py[DEBUG]: config-scripts-per-once already ran (freq=once)
2019-03-05 12:05:42,559 - handlers.py[DEBUG]: finish: modules-final/config-scripts-per-once: SUCCESS: config-scripts-per-once previously ran
2019-03-05 12:05:42,559 - stages.py[DEBUG]: Running module scripts-per-boot (<module 'cloudinit.config.cc_scripts_per_boot' from '/usr/lib/python3/dist-packages/cloudinit/config/cc_scripts_per_boot.py'>) with frequency always
2019-03-05 12:05:42,560 - handlers.py[DEBUG]: start: modules-final/config-scripts-per-boot: running config-scripts-per-boot with frequency always
2019-03-05 12:05:42,560 - helpers.py[DEBUG]: Running config-scripts-per-boot using lock (<cloudinit.helpers.DummyLock object at 0x7f402b8dc2b0>)
2019-03-05 12:05:42,561 - handlers.py[DEBUG]: finish: modules-final/config-scripts-per-boot: SUCCESS: config-scripts-per-boot ran successfully
2019-03-05 12:05:42,561 - stages.py[DEBUG]: Running module scripts-per-instance (<module 'cloudinit.config.cc_scripts_per_instance' from '/usr/lib/python3/dist-packages/cloudinit/config/cc_scripts_per_instance.py'>) with frequency once-per-instance
2019-03-05 12:05:42,561 - handlers.py[DEBUG]: start: modules-final/config-scripts-per-instance: running config-scripts-per-instance with frequency once-per-instance
2019-03-05 12:05:42,561 - helpers.py[DEBUG]: config-scripts-per-instance already ran (freq=once-per-instance)
2019-03-05 12:05:42,561 - handlers.py[DEBUG]: finish: modules-final/config-scripts-per-instance: SUCCESS: config-scripts-per-instance previously ran
2019-03-05 12:05:42,561 - stages.py[DEBUG]: Running module scripts-user (<module 'cloudinit.config.cc_scripts_user' from '/usr/lib/python3/dist-packages/cloudinit/config/cc_scripts_user.py'>) with frequency once-per-instance
2019-03-05 12:05:42,561 - handlers.py[DEBUG]: start: modules-final/config-scripts-user: running config-scripts-user with frequency once-per-instance
2019-03-05 12:05:42,562 - helpers.py[DEBUG]: config-scripts-user already ran (freq=once-per-instance)
2019-03-05 12:05:42,562 - handlers.py[DEBUG]: finish: modules-final/config-scripts-user: SUCCESS: config-scripts-user previously ran
2019-03-05 12:05:42,562 - stages.py[DEBUG]: Running module ssh-authkey-fingerprints (<module 'cloudinit.config.cc_ssh_authkey_fingerprints' from '/usr/lib/python3/dist-packages/cloudinit/config/cc_ssh_authkey_fingerprints.py'>) with frequency once-per-instance
2019-03-05 12:05:42,562 - handlers.py[DEBUG]: start: modules-final/config-ssh-authkey-fingerprints: running config-ssh-authkey-fingerprints with frequency once-per-instance
2019-03-05 12:05:42,562 - helpers.py[DEBUG]: config-ssh-authkey-fingerprints already ran (freq=once-per-instance)
2019-03-05 12:05:42,562 - handlers.py[DEBUG]: finish: modules-final/config-ssh-authkey-fingerprints: SUCCESS: config-ssh-authkey-fingerprints previously ran
2019-03-05 12:05:42,562 - stages.py[DEBUG]: Running module keys-to-console (<module 'cloudinit.config.cc_keys_to_console' from '/usr/lib/python3/dist-packages/cloudinit/config/cc_keys_to_console.py'>) with frequency once-per-instance
2019-03-05 12:05:42,563 - handlers.py[DEBUG]: start: modules-final/config-keys-to-console: running config-keys-to-console with frequency once-per-instance
2019-03-05 12:05:42,563 - helpers.py[DEBUG]: config-keys-to-console already ran (freq=once-per-instance)
2019-03-05 12:05:42,563 - handlers.py[DEBUG]: finish: modules-final/config-keys-to-console: SUCCESS: config-keys-to-console previously ran
2019-03-05 12:05:42,563 - stages.py[DEBUG]: Running module phone-home (<module 'cloudinit.config.cc_phone_home' from '/usr/lib/python3/dist-packages/cloudinit/config/cc_phone_home.py'>) with frequency once-per-instance
2019-03-05 12:05:42,563 - handlers.py[DEBUG]: start: modules-final/config-phone-home: running config-phone-home with frequency once-per-instance
2019-03-05 12:05:42,563 - helpers.py[DEBUG]: config-phone-home already ran (freq=once-per-instance)
2019-03-05 12:05:42,563 - handlers.py[DEBUG]: finish: modules-final/config-phone-home: SUCCESS: config-phone-home previously ran
2019-03-05 12:05:42,563 - stages.py[DEBUG]: Running module final-message (<module 'cloudinit.config.cc_final_message' from '/usr/lib/python3/dist-packages/cloudinit/config/cc_final_message.py'>) with frequency always
2019-03-05 12:05:42,564 - handlers.py[DEBUG]: start: modules-final/config-final-message: running config-final-message with frequency always
2019-03-05 12:05:42,564 - helpers.py[DEBUG]: Running config-final-message using lock (<cloudinit.helpers.DummyLock object at 0x7f402b90a240>)
2019-03-05 12:05:42,564 - util.py[DEBUG]: Reading from /proc/uptime (quiet=False)
2019-03-05 12:05:42,564 - util.py[DEBUG]: Read 11 bytes from /proc/uptime
2019-03-05 12:05:42,564 - util.py[DEBUG]: The system is finally up, after 17.21 seconds
2019-03-05 12:05:42,564 - util.py[DEBUG]: Writing to /var/lib/cloud/instance/boot-finished - wb: [644] 67 bytes
2019-03-05 12:05:42,565 - handlers.py[DEBUG]: finish: modules-final/config-final-message: SUCCESS: config-final-message ran successfully
2019-03-05 12:05:42,565 - stages.py[DEBUG]: Running module power-state-change (<module 'cloudinit.config.cc_power_state_change' from '/usr/lib/python3/dist-packages/cloudinit/config/cc_power_state_change.py'>) with frequency once-per-instance
2019-03-05 12:05:42,565 - handlers.py[DEBUG]: start: modules-final/config-power-state-change: running config-power-state-change with frequency once-per-instance
2019-03-05 12:05:42,565 - helpers.py[DEBUG]: config-power-state-change already ran (freq=once-per-instance)
2019-03-05 12:05:42,565 - handlers.py[DEBUG]: finish: modules-final/config-power-state-change: SUCCESS: config-power-state-change previously ran
2019-03-05 12:05:42,565 - main.py[DEBUG]: Ran 20 modules with 0 failures
2019-03-05 12:05:42,566 - util.py[DEBUG]: Creating symbolic link from '/run/cloud-init/result.json' => '../../var/lib/cloud/data/result.json'
2019-03-05 12:05:42,566 - util.py[DEBUG]: Reading from /proc/uptime (quiet=False)
2019-03-05 12:05:42,567 - util.py[DEBUG]: Read 11 bytes from /proc/uptime
2019-03-05 12:05:42,567 - util.py[DEBUG]: cloud-init mode 'modules' took 0.144 seconds (0.15)
2019-03-05 12:05:42,567 - handlers.py[DEBUG]: finish: modules-final: SUCCESS: running modules for final
